Workbook

Sheet Database Geral
A1: País | B1: Gastos P&D (%) | C1: Taxa Crescimento (%) | D1: PIB per capita (US$ constantes de 2005) | E1: Razão de Dependência de Jovens (%) | F1: Gastos com educação (%)
A2: Argentina | B2: 0.61745 | C2: 9.4515783 | D2: 7293.6582 | E2: 38.566712 | F2: 15.57046
A3: Armenia | B3: 0.24139 | C3: 2.2 | D3: 1997.0523 | E3: 29.758869 | F3: 12.40051
A4: Australia | B4: 2.3856201 | C4: 1.9623661 | D4: 36175.113 | E4: 28.019033 | F4: 14.3276
A5: Austria | B5: 2.79846 | C5: 1.8801177 | D5: 40099.966 | E5: 21.881818 | F5: 10.85817
A6: Azerbaijan | B6: 0.21848001 | C6: 4.8543393 | D6: 3126.724 | E6: 31.79129 | F6: 8.77911
A7: Belarus | B7: 0.69349998 | C7: 7.7407812 | D7: 4524.1582 | E7: 20.852179 | F7: 12.86463
A8: Belgium | B8: 2.10478 | C8: 2.5010546 | D8: 37745.502 | E8: 25.395926 | F8: 12.22374
A9: Brazil | B9: 1.1604199 | C9: 7.5720672 | D9: 5678.286 | E9: 37.709678 | F9: 14.55989
A10: Bulgaria | B10: 0.59794003 | C10: 0.65532511 | D10: 4559.6954 | E10: 19.485786 | F10: 11.16342
A11: Burundi | B11: 0.13755 | C11: 3.7859025 | D11: 150.74275 | E11: 82.053945 | F11: 16.5881
A12: Canada | B12: 1.86008 | C12: 3.3742486 | D12: 36465.711 | E12: 23.744055 | F12: 12.38789
A13: Chile | B13: 0.41722 | C13: 5.7537089 | D13: 8609.2679 | E13: 32.237808 | F13: 17.51402
... A65: United States | B65: 2.73827 | C65: 2.5319204 | D65: 43961.169 | E65: 29.568269 | F65: 13.03757

Sheet Cruzamento
A1: RA | B1: Variável Y | C1: Variável X
A2: 102180010 | B2: Taxa Crescimento (%) | C2: Gastos P&D (%)
A3: 101190016 | B3: Taxa Crescimento (%) | C3: PIB per capita (US$ constantes de 2005)
A4: 101200457 | B4: Gastos P&D (%) | C4: PIB per capita (US$ constantes de 2005)
A5: 102180021 | B5: PIB per capita (US$ constantes de 2005) | C5: Taxa Crescimento (%)
A6: 101170214 | B6: Gastos com educação (%) | C6: Taxa Crescimento (%)
A7: 101180193 | B7: Gastos com educação (%) | C7: Razão de Dependência de Jovens (%)
A8: 101190475 | B8: PIB per capita (US$ constantes de 2005) | C8: Gastos P&D (%)
A9: 102180054 | B9: Gastos P&D (%) | C9: Gastos com educação (%)
A10: 102180027 | B10: PIB per capita (US$ constantes de 2005) | C10: Razão de Dependência de Jovens (%)
A11: 101190516 | B11: Taxa Crescimento (%) | C11: PIB per capita (US$ constantes de 2005)
A12: 101190648 | B12: Gastos com educação (%) | C12: PIB per capita (US$ constantes de 2005)
A13: 101180325 | B13: PIB per capita (US$ constantes de 2005) | C13: Gastos P&D (%)
... A31: 101170502 | B31: Gastos P&D (%) | C31: PIB per capita (US$ constantes de 2005)

Sheet Base de Dados P1
A1: País | C1: Variável Y | D1: Variável X | F1: Insira seu RA abaixo | H1: Escola Superior de Administração, Marketing e Comunicação (ESAMC) 10175/A - Econometria - 1º Sem. de 2021 - Prof. Pier Francesco De Maria
C2: =IFERROR(VLOOKUP(F2,Cruzamento!$A$2:$C$31,2,FALSE),"") -> Gastos com educação (%) | D2: =IFERROR(VLOOKUP(F2,Cruzamento!$A$2:$C$31,3,FALSE),"") -> PIB per capita (US$ constantes de 2005) | F2: 101190648
A3: 2 | B3: Argentina | C3: =IFERROR(IF(HLOOKUP(C$2,'Database Geral'!$B$1:$F$65,'Base de Dados P1'!$A3,FALSE)=0,,HLOOKUP(C$2,'Database Geral'!$B$1:$F$65,'Base de Dados P1'!$A3,FALSE)),"") -> 15.57046 | D3: =IFERROR(IF(HLOOKUP(D$2,'Database Geral'!$B$1:$F$65,'Base de Dados P1'!$A3,FALSE)=0,,HLOOKUP(D$2,'Database Geral'!$B$1:$F$65,'Base de Dados P1'!$A3,FALSE)),"") -> 7293.6582
A4: 3 | B4: Armenia | C4: =IFERROR(IF(HLOOKUP(C$2,'Database Geral'!$B$1:$F$65,'Base de Dados P1'!$A4,FALSE)=0,,HLOOKUP(C$2,'Database Geral'!$B$1:$F$65,'Base de Dados P1'!$A4,FALSE)),"") -> 12.40051 | D4: =IFERROR(IF(HLOOKUP(D$2,'Database Geral'!$B$1:$F$65,'Base de Dados P1'!$A4,FALSE)=0,,HLOOKUP(D$2,'Database Geral'!$B$1:$F$65,'Base de Dados P1'!$A4,FALSE)),"") -> 1997.0523 | H4: Prova 1 / Parte A (Modelo de Regressão Linear Simples)
A5: 4 | B5: Australia | C5: =IFERROR(IF(HLOOKUP(C$2,'Database Geral'!$B$1:$F$65,'Base de Dados P1'!$A5,FALSE)=0,,HLOOKUP(C$2,'Database Geral'!$B$1:$F$65,'Base de Dados P1'!$A5,FALSE)),"") -> 14.3276 | D5: =IFERROR(IF(HLOOKUP(D$2,'Database Geral'!$B$1:$F$65,'Base de Dados P1'!$A5,FALSE)=0,,HLOOKUP(D$2,'Database Geral'!$B$1:$F$65,'Base de Dados P1'!$A5,FALSE)),"") -> 36175.113 | F5: A pontuação máxima desta prova é 5.0 (cinco) pontos. À nota desta prova será somada a nota da Parte 2, compondo a nota da P1. Você recebeu as duas variáveis ao lado para criar um modelo de regressão linear simples (RLS). Faça o que é pedido, na ordem indicada, por meio de fórmulas. NÃO use o método rápido ("Análise de Dados") para apresentar as respostas, pois estas não serão consideradas para avaliação. Use a aba "Planilha Suporte" para fazer as contas necessárias (você não tem como adicionar/eliminar abas). Deixe todas as fórmulas! Você terá 24h para fazer esta prova: das 21h00 de 19/03 até as 20h59 de 20/03. Ao terminar a sua prova, SALVE O ARQUIVO E ENVIE PARA O E-MAIL pier.francesco@esamc.br!
A6: 5 | B6: Austria | C6: =IFERROR(IF(HLOOKUP(C$2,'Database Geral'!$B$1:$F$65,'Base de Dados P1'!$A6,FALSE)=0,,HLOOKUP(C$2,'Database Geral'!$B$1:$F$65,'Base de Dados P1'!$A6,FALSE)),"") -> 10.85817 | D6: =IFERROR(IF(HLOOKUP(D$2,'Database Geral'!$B$1:$F$65,'Base de Dados P1'!$A6,FALSE)=0,,HLOOKUP(D$2,'Database Geral'!$B$1:$F$65,'Base de Dados P1'!$A6,FALSE)),"") -> 40099.966
A7: 6 | B7: Azerbaijan | C7: =IFERROR(IF(HLOOKUP(C$2,'Database Geral'!$B$1:$F$65,'Base de Dados P1'!$A7,FALSE)=0,,HLOOKUP(C$2,'Database Geral'!$B$1:$F$65,'Base de Dados P1'!$A7,FALSE)),"") -> 8.77911 | D7: =IFERROR(IF(HLOOKUP(D$2,'Database Geral'!$B$1:$F$65,'Base de Dados P1'!$A7,FALSE)=0,,HLOOKUP(D$2,'Database Geral'!$B$1:$F$65,'Base de Dados P1'!$A7,FALSE)),"") -> 3126.724
A8: 7 | B8: Belarus | C8: =IFERROR(IF(HLOOKUP(C$2,'Database Geral'!$B$1:$F$65,'Base de Dados P1'!$A8,FALSE)=0,,HLOOKUP(C$2,'Database Geral'!$B$1:$F$65,'Base de Dados P1'!$A8,FALSE)),"") -> 12.86463 | D8: =IFERROR(IF(HLOOKUP(D$2,'Database Geral'!$B$1:$F$65,'Base de Dados P1'!$A8,FALSE)=0,,HLOOKUP(D$2,'Database Geral'!$B$1:$F$65,'Base de Dados P1'!$A8,FALSE)),"") -> 4524.1582
A9: 8 | B9: Belgium | C9: =IFERROR(IF(HLOOKUP(C$2,'Database Geral'!$B$1:$F$65,'Base de Dados P1'!$A9,FALSE)=0,,HLOOKUP(C$2,'Database Geral'!$B$1:$F$65,'Base de Dados P1'!$A9,FALSE)),"") -> 12.22374 | D9: =IFERROR(IF(HLOOKUP(D$2,'Database Geral'!$B$1:$F$65,'Base de Dados P1'!$A9,FALSE)=0,,HLOOKUP(D$2,'Database Geral'!$B$1:$F$65,'Base de Dados P1'!$A9,FALSE)),"") -> 37745.502
A10: 9 | B10: Brazil | C10: =IFERROR(IF(HLOOKUP(C$2,'Database Geral'!$B$1:$F$65,'Base de Dados P1'!$A10,FALSE)=0,,HLOOKUP(C$2,'Database Geral'!$B$1:$F$65,'Base de Dados P1'!$A10,FALSE)),"") -> 14.55989 | D10: =IFERROR(IF(HLOOKUP(D$2,'Database Geral'!$B$1:$F$65,'Base de Dados P1'!$A10,FALSE)=0,,HLOOKUP(D$2,'Database Geral'!$B$1:$F$65,'Base de Dados P1'!$A10,FALSE)),"") -> 5678.286
A11: 10 | B11: Bulgaria | C11: =IFERROR(IF(HLOOKUP(C$2,'Database Geral'!$B$1:$F$65,'Base de Dados P1'!$A11,FALSE)=0,,HLOOKUP(C$2,'Database Geral'!$B$1:$F$65,'Base de Dados P1'!$A11,FALSE)),"") -> 11.16342 | D11: =IFERROR(IF(HLOOKUP(D$2,'Database Geral'!$B$1:$F$65,'Base de Dados P1'!$A11,FALSE)=0,,HLOOKUP(D$2,'Database Geral'!$B$1:$F$65,'Base de Dados P1'!$A11,FALSE)),"") -> 4559.6954
A12: 11 | B12: Burundi | C12: =IFERROR(IF(HLOOKUP(C$2,'Database Geral'!$B$1:$F$65,'Base de Dados P1'!$A12,FALSE)=0,,HLOOKUP(C$2,'Database Geral'!$B$1:$F$65,'Base de Dados P1'!$A12,FALSE)),"") -> 16.5881 | D12: =IFERROR(IF(HLOOKUP(D$2,'Database Geral'!$B$1:$F$65,'Base de Dados P1'!$A12,FALSE)=0,,HLOOKUP(D$2,'Database Geral'!$B$1:$F$65,'Base de Dados P1'!$A12,FALSE)),"") -> 150.74275
A13: 12 | B13: Canada | C13: =IFERROR(IF(HLOOKUP(C$2,'Database Geral'!$B$1:$F$65,'Base de Dados P1'!$A13,FALSE)=0,,HLOOKUP(C$2,'Database Geral'!$B$1:$F$65,'Base de Dados P1'!$A13,FALSE)),"") -> 12.38789 | D13: =IFERROR(IF(HLOOKUP(D$2,'Database Geral'!$B$1:$F$65,'Base de Dados P1'!$A13,FALSE)=0,,HLOOKUP(D$2,'Database Geral'!$B$1:$F$65,'Base de Dados P1'!$A13,FALSE)),"") -> 36465.711
A14: 13 | B14: Chile | C14: =IFERROR(IF(HLOOKUP(C$2,'Database Geral'!$B$1:$F$65,'Base de Dados P1'!$A14,FALSE)=0,,HLOOKUP(C$2,'Database Geral'!$B$1:$F$65,'Base de Dados P1'!$A14,FALSE)),"") -> 17.51402 | D14: =IFERROR(IF(HLOOKUP(D$2,'Database Geral'!$B$1:$F$65,'Base de Dados P1'!$A14,FALSE)=0,,HLOOKUP(D$2,'Database Geral'!$B$1:$F$65,'Base de Dados P1'!$A14,FALSE)),"") -> 8609.2679 | F14: Exercícios
A15: 14 | B15: Colombia | C15: =IFERROR(IF(HLOOKUP(C$2,'Database Geral'!$B$1:$F$65,'Base de Dados P1'!$A15,FALSE)=0,,HLOOKUP(C$2,'Database Geral'!$B$1:$F$65,'Base de Dados P1'!$A15,FALSE)),"") -> 16.41858 | D15: =IFERROR(IF(HLOOKUP(D$2,'Database Geral'!$B$1:$F$65,'Base de Dados P1'!$A15,FALSE)=0,,HLOOKUP(D$2,'Database Geral'!$B$1:$F$65,'Base de Dados P1'!$A15,FALSE)),"") -> 3939.107 | F15: 1) (0.25 pontos) Plote um gráfico de dispersão. Atente-se para qual delas ficará em cada eixo! Interprete o gráfico
A16: 15 | B16: Croatia | C16: =IFERROR(IF(HLOOKUP(C$2,'Database Geral'!$B$1:$F$65,'Base de Dados P1'!$A16,FALSE)=0,,HLOOKUP(C$2,'Database Geral'!$B$1:$F$65,'Base de Dados P1'!$A16,FALSE)),"") -> 9.08259 | D16: =IFERROR(IF(HLOOKUP(D$2,'Database Geral'!$B$1:$F$65,'Base de Dados P1'!$A16,FALSE)=0,,HLOOKUP(D$2,'Database Geral'!$B$1:$F$65,'Base de Dados P1'!$A16,FALSE)),"") -> 10523.915 | F16: 2) (0.25 pontos) Construa um boxplot para cada variável. O que você observa para cada uma das variáveis? Descreva
A17: 16 | B17: Cyprus | C17: =IFERROR(IF(HLOOKUP(C$2,'Database Geral'!$B$1:$F$65,'Base de Dados P1'!$A17,FALSE)=0,,HLOOKUP(C$2,'Database Geral'!$B$1:$F$65,'Base de Dados P1'!$A17,FALSE)),"") -> 15.68234 | D17: =IFERROR(IF(HLOOKUP(D$2,'Database Geral'!$B$1:$F$65,'Base de Dados P1'!$A17,FALSE)=0,,HLOOKUP(D$2,'Database Geral'!$B$1:$F$65,'Base de Dados P1'!$A17,FALSE)),"") -> 24852.374 | F17: 3) (0.75 pontos) Complete a tabela com as variáveis de suporte (exceto as últimas 3 colunas)
A18: 17 | B18: Czech Republic | C18: =IFERROR(IF(HLOOKUP(C$2,'Database Geral'!$B$1:$F$65,'Base de Dados P1'!$A18,FALSE)=0,,HLOOKUP(C$2,'Database Geral'!$B$1:$F$65,'Base de Dados P1'!$A18,FALSE)),"") -> 9.7125 | D18: =IFERROR(IF(HLOOKUP(D$2,'Database Geral'!$B$1:$F$65,'Base de Dados P1'!$A18,FALSE)=0,,HLOOKUP(D$2,'Database Geral'!$B$1:$F$65,'Base de Dados P1'!$A18,FALSE)),"") -> 14640.343 | F18: 4) (1.00 pontos) Estime os coeficientes do modelo de regressão Ŷ = α + βX . Interprete o modelo de regressão obtido
A19: 18 | B19: Denmark | C19: =IFERROR(IF(HLOOKUP(C$2,'Database Geral'!$B$1:$F$65,'Base de Dados P1'!$A19,FALSE)=0,,HLOOKUP(C$2,'Database Geral'!$B$1:$F$65,'Base de Dados P1'!$A19,FALSE)),"") -> 15.10334 | D19: =IFERROR(IF(HLOOKUP(D$2,'Database Geral'!$B$1:$F$65,'Base de Dados P1'!$A19,FALSE)=0,,HLOOKUP(D$2,'Database Geral'!$B$1:$F$65,'Base de Dados P1'!$A19,FALSE)),"") -> 47791.92 | F19: 5) (0.50 pontos) Complete as últimas 3 colunas da tabela
A20: 19 | B20: El Salvador | C20: =IFERROR(IF(HLOOKUP(C$2,'Database Geral'!$B$1:$F$65,'Base de Dados P1'!$A20,FALSE)=0,,HLOOKUP(C$2,'Database Geral'!$B$1:$F$65,'Base de Dados P1'!$A20,FALSE)),"") -> 16.16422 | D20: =IFERROR(IF(HLOOKUP(D$2,'Database Geral'!$B$1:$F$65,'Base de Dados P1'!$A20,FALSE)=0,,HLOOKUP(D$2,'Database Geral'!$B$1:$F$65,'Base de Dados P1'!$A20,FALSE)),"") -> 2949.6137 | F20: 6) (0.75 pontos) Avalie se os coeficientes obtidos são estatisticamente significativos (ou seja, diferentes de 0)
A21: 20 | B21: Estonia | C21: =IFERROR(IF(HLOOKUP(C$2,'Database Geral'!$B$1:$F$65,'Base de Dados P1'!$A21,FALSE)=0,,HLOOKUP(C$2,'Database Geral'!$B$1:$F$65,'Base de Dados P1'!$A21,FALSE)),"") -> 13.6818 | D21: =IFERROR(IF(HLOOKUP(D$2,'Database Geral'!$B$1:$F$65,'Base de Dados P1'!$A21,FALSE)=0,,HLOOKUP(D$2,'Database Geral'!$B$1:$F$65,'Base de Dados P1'!$A21,FALSE)),"") -> 10364.464 | F21: 7) (0.50 pontos) Obtenha o intervalo de confiança para os estimadores α e β
A22: 21 | B22: Ethiopia | C22: =IFERROR(IF(HLOOKUP(C$2,'Database Geral'!$B$1:$F$65,'Base de Dados P1'!$A22,FALSE)=0,,HLOOKUP(C$2,'Database Geral'!$B$1:$F$65,'Base de Dados P1'!$A22,FALSE)),"") -> 22.03582 | D22: =IFERROR(IF(HLOOKUP(D$2,'Database Geral'!$B$1:$F$65,'Base de Dados P1'!$A22,FALSE)=0,,HLOOKUP(D$2,'Database Geral'!$B$1:$F$65,'Base de Dados P1'!$A22,FALSE)),"") -> 238.63182 | F22: 8) (0.50 pontos) Calcule as somas de quadrados e obtenha o coeficiente de determinação. Interprete este valor
A23: 22 | B23: Finland | C23: =IFERROR(IF(HLOOKUP(C$2,'Database Geral'!$B$1:$F$65,'Base de Dados P1'!$A23,FALSE)=0,,HLOOKUP(C$2,'Database Geral'!$B$1:$F$65,'Base de Dados P1'!$A23,FALSE)),"") -> 11.95611 | D23: =IFERROR(IF(HLOOKUP(D$2,'Database Geral'!$B$1:$F$65,'Base de Dados P1'!$A23,FALSE)=0,,HLOOKUP(D$2,'Database Geral'!$B$1:$F$65,'Base de Dados P1'!$A23,FALSE)),"") -> 39698.805 | F23: 9) (0.50 pontos) Monte a tabela ANOVA e identifique se o modelo é estatisticamente válido
A24: 23 | B24: France | C24: =IFERROR(IF(HLOOKUP(C$2,'Database Geral'!$B$1:$F$65,'Base de Dados P1'!$A24,FALSE)=0,,HLOOKUP(C$2,'Database Geral'!$B$1:$F$65,'Base de Dados P1'!$A24,FALSE)),"") -> 10.06913 | D24: =IFERROR(IF(HLOOKUP(D$2,'Database Geral'!$B$1:$F$65,'Base de Dados P1'!$A24,FALSE)=0,,HLOOKUP(D$2,'Database Geral'!$B$1:$F$65,'Base de Dados P1'!$A24,FALSE)),"") -> 35216.5
A25: 24 | B25: Germany | C25: =IFERROR(IF(HLOOKUP(C$2,'Database Geral'!$B$1:$F$65,'Base de Dados P1'!$A25,FALSE)=0,,HLOOKUP(C$2,'Database Geral'!$B$1:$F$65,'Base de Dados P1'!$A25,FALSE)),"") -> 10.61658 | D25: =IFERROR(IF(HLOOKUP(D$2,'Database Geral'!$B$1:$F$65,'Base de Dados P1'!$A25,FALSE)=0,,HLOOKUP(D$2,'Database Geral'!$B$1:$F$65,'Base de Dados P1'!$A25,FALSE)),"") -> 37147.022
A26: 25 | B26: Ghana | C26: =IFERROR(IF(HLOOKUP(C$2,'Database Geral'!$B$1:$F$65,'Base de Dados P1'!$A26,FALSE)=0,,HLOOKUP(C$2,'Database Geral'!$B$1:$F$65,'Base de Dados P1'!$A26,FALSE)),"") -> 21.24422 | D26: =IFERROR(IF(HLOOKUP(D$2,'Database Geral'!$B$1:$F$65,'Base de Dados P1'!$A26,FALSE)=0,,HLOOKUP(D$2,'Database Geral'!$B$1:$F$65,'Base de Dados P1'!$A26,FALSE)),"") -> 606.38422
A27: 26 | B27: Guatemala | C27: =IFERROR(IF(HLOOKUP(C$2,'Database Geral'!$B$1:$F$65,'Base de Dados P1'!$A27,FALSE)=0,,HLOOKUP(C$2,'Database Geral'!$B$1:$F$65,'Base de Dados P1'!$A27,FALSE)),"") -> 19.29692 | D27: =IFERROR(IF(HLOOKUP(D$2,'Database Geral'!$B$1:$F$65,'Base de Dados P1'!$A27,FALSE)=0,,HLOOKUP(D$2,'Database Geral'!$B$1:$F$65,'Base de Dados P1'!$A27,FALSE)),"") -> 2270.0983
A28: 27 | B28: Hong Kong | C28: =IFERROR(IF(HLOOKUP(C$2,'Database Geral'!$B$1:$F$65,'Base de Dados P1'!$A28,FALSE)=0,,HLOOKUP(C$2,'Database Geral'!$B$1:$F$65,'Base de Dados P1'!$A28,FALSE)),"") -> 19.90955 | D28: =IFERROR(IF(HLOOKUP(D$2,'Database Geral'!$B$1:$F$65,'Base de Dados P1'!$A28,FALSE)=0,,HLOOKUP(D$2,'Database Geral'!$B$1:$F$65,'Base de Dados P1'!$A28,FALSE)),"") -> 31328.375
A29: 28 | B29: Hungary | C29: =IFERROR(IF(HLOOKUP(C$2,'Database Geral'!$B$1:$F$65,'Base de Dados P1'!$A29,FALSE)=0,,HLOOKUP(C$2,'Database Geral'!$B$1:$F$65,'Base de Dados P1'!$A29,FALSE)),"") -> 9.68498 | D29: =IFERROR(IF(HLOOKUP(D$2,'Database Geral'!$B$1:$F$65,'Base de Dados P1'!$A29,FALSE)=0,,HLOOKUP(D$2,'Database Geral'!$B$1:$F$65,'Base de Dados P1'!$A29,FALSE)),"") -> 11108.9
A30: 29 | B30: India | C30: =IFERROR(IF(HLOOKUP(C$2,'Database Geral'!$B$1:$F$65,'Base de Dados P1'!$A30,FALSE)=0,,HLOOKUP(C$2,'Database Geral'!$B$1:$F$65,'Base de Dados P1'!$A30,FALSE)),"") -> 11.74278 | D30: =IFERROR(IF(HLOOKUP(D$2,'Database Geral'!$B$1:$F$65,'Base de Dados P1'!$A30,FALSE)=0,,HLOOKUP(D$2,'Database Geral'!$B$1:$F$65,'Base de Dados P1'!$A30,FALSE)),"") -> 1031.5611
A31: 30 | B31: Ireland | C31: =IFERROR(IF(HLOOKUP(C$2,'Database Geral'!$B$1:$F$65,'Base de Dados P1'!$A31,FALSE)=0,,HLOOKUP(C$2,'Database Geral'!$B$1:$F$65,'Base de Dados P1'!$A31,FALSE)),"") -> 9.29551 | D31: =IFERROR(IF(HLOOKUP(D$2,'Database Geral'!$B$1:$F$65,'Base de Dados P1'!$A31,FALSE)=0,,HLOOKUP(D$2,'Database Geral'!$B$1:$F$65,'Base de Dados P1'!$A31,FALSE)),"") -> 46425.614
A32: 31 | B32: Israel | C32: =IFERROR(IF(HLOOKUP(C$2,'Database Geral'!$B$1:$F$65,'Base de Dados P1'!$A32,FALSE)=0,,HLOOKUP(C$2,'Database Geral'!$B$1:$F$65,'Base de Dados P1'!$A32,FALSE)),"") -> 13.25932 | D32: =IFERROR(IF(HLOOKUP(D$2,'Database Geral'!$B$1:$F$65,'Base de Dados P1'!$A32,FALSE)=0,,HLOOKUP(D$2,'Database Geral'!$B$1:$F$65,'Base de Dados P1'!$A32,FALSE)),"") -> 23225.416
A33: 32 | B33: Italy | C33: =IFERROR(IF(HLOOKUP(C$2,'Database Geral'!$B$1:$F$65,'Base de Dados P1'!$A33,FALSE)=0,,HLOOKUP(C$2,'Database Geral'!$B$1:$F$65,'Base de Dados P1'!$A33,FALSE)),"") -> 8.72395 | D33: =IFERROR(IF(HLOOKUP(D$2,'Database Geral'!$B$1:$F$65,'Base de Dados P1'!$A33,FALSE)=0,,HLOOKUP(D$2,'Database Geral'!$B$1:$F$65,'Base de Dados P1'!$A33,FALSE)),"") -> 30788.539
A34: 33 | B34: Japan | C34: =IFERROR(IF(HLOOKUP(C$2,'Database Geral'!$B$1:$F$65,'Base de Dados P1'!$A34,FALSE)=0,,HLOOKUP(C$2,'Database Geral'!$B$1:$F$65,'Base de Dados P1'!$A34,FALSE)),"") -> 9.45758 | D34: =IFERROR(IF(HLOOKUP(D$2,'Database Geral'!$B$1:$F$65,'Base de Dados P1'!$A34,FALSE)=0,,HLOOKUP(D$2,'Database Geral'!$B$1:$F$65,'Base de Dados P1'!$A34,FALSE)),"") -> 36296.315
A35: 34 | B35: Kenya | C35: =IFERROR(IF(HLOOKUP(C$2,'Database Geral'!$B$1:$F$65,'Base de Dados P1'!$A35,FALSE)=0,,HLOOKUP(C$2,'Database Geral'!$B$1:$F$65,'Base de Dados P1'!$A35,FALSE)),"") -> 20.55599 | D35: =IFERROR(IF(HLOOKUP(D$2,'Database Geral'!$B$1:$F$65,'Base de Dados P1'!$A35,FALSE)=0,,HLOOKUP(D$2,'Database Geral'!$B$1:$F$65,'Base de Dados P1'!$A35,FALSE)),"") -> 584.91173
... A66: 65 | B66: United States | C66: =IFERROR(IF(HLOOKUP(C$2,'Database Geral'!$B$1:$F$65,'Base de Dados P1'!$A66,FALSE)=0,,HLOOKUP(C$2,'Database Geral'!$B$1:$F$65,'Base de Dados P1'!$A66,FALSE)),"") -> 13.03757 | D66: =IFERROR(IF(HLOOKUP(D$2,'Database Geral'!$B$1:$F$65,'Base de Dados P1'!$A66,FALSE)=0,,HLOOKUP(D$2,'Database Geral'!$B$1:$F$65,'Base de Dados P1'!$A66,FALSE)),"") -> 43961.169

Sheet Planilha Suporte
A1: País | B1: Variável Y | C1: Variável X | D1: Variáveis de suporte | X1: Não mexer nisso | Y1: Y | Z1: X
B2: ='Base de Dados P1'!C2 -> Gastos com educação (%) | C2: ='Base de Dados P1'!D2 -> PIB per capita (US$ constantes de 2005) | D2: y | E2: x | F2: x*y | G2: x² | H2: y² | I2: Ŷ | J2: ê | K2: Ŷ - Ȳ | M2: Média de Y | N2: =AVERAGE(B3:B66) -> 14.348792 | U2: Boxplot Y | V2: Boxplot X | X2: LI | Y2: =U3 -> 8.12264 | Z2: =V3 -> 150.74275
A3: Argentina | B3: ='Base de Dados P1'!C3 -> 15.57046 | C3: ='Base de Dados P1'!D3 -> 7293.6582 | D3: =B3-$N$2 -> 1.221668 | E3: =C3-$N$3 -> -9342.7735 | F3: =E3*D3 -> -11413.767 | G3: =E3^2 -> 87287417 | H3: =D3^2 -> 1.4924726 | I3: =$N$4+$N$5*C3 -> 15.11745 | J3: =B3-I3 -> 0.45300983 | K3: =I3-$N$2 -> 0.76865814 | M3: Média de X | N3: =AVERAGE(C3:C66) -> 16636.432 | T3: Mínimo | U3: =MIN(B3:B66) -> 8.12264 | V3: =MIN(C3:C66) -> 150.74275 | X3: A | Y3: =0 -> 0 | Z3: =0 -> 0
A4: Armenia | B4: ='Base de Dados P1'!C4 -> 12.40051 | C4: ='Base de Dados P1'!D4 -> 1997.0523 | D4: =B4-$N$2 -> -1.948282 | E4: =C4-$N$3 -> -14639.379 | F4: =E4*D4 -> 28521.64 | G4: =E4^2 -> 2.1431143e+08 | H4: =D4^2 -> 3.7958029 | I4: =$N$4+$N$5*C4 -> 15.553218 | J4: =B4-I4 -> -3.1527079 | K4: =I4-$N$2 -> 1.2044259 | M4: Alfa | N4: =N2-N3*N5 -> 15.717521 | T4: 1º Quartil | U4: =_xlfn.QUARTILE.EXC(B3:B66,1) -> 10.676977 | V4: =_xlfn.QUARTILE.EXC(C3:C66,1) -> 1706.8501 | X4: B-A | Y4: =U4-U3 -> 2.5543375 | Z4: =V4-V3 -> 1556.1074
A5: Australia | B5: ='Base de Dados P1'!C5 -> 14.3276 | C5: ='Base de Dados P1'!D5 -> 36175.113 | D5: =B5-$N$2 -> -0.021192031 | E5: =C5-$N$3 -> 19538.681 | F5: =E5*D5 -> -414.06433 | G5: =E5^2 -> 3.8176005e+08 | H5: =D5^2 -> 0.00044910219 | I5: =$N$4+$N$5*C5 -> 12.741286 | J5: =B5-I5 -> 1.5863141 | K5: =I5-$N$2 -> -1.6075062 | M5: Beta | N5: =SUM(F3:F66)/SUM(G3:G66) -> -8.2273014e-05 | T5: Mediana | U5: =MEDIAN(B3:B66) -> 13.599685 | V5: =MEDIAN(C3:C66) -> 8346.9485 | X5: C-B | Y5: =U5-U4 -> 2.9227075 | Z5: =V5-V4 -> 6640.0984
A6: Austria | B6: ='Base de Dados P1'!C6 -> 10.85817 | C6: ='Base de Dados P1'!D6 -> 40099.966 | D6: =B6-$N$2 -> -3.490622 | E6: =C6-$N$3 -> 23463.534 | F6: =E6*D6 -> -81902.33 | G6: =E6^2 -> 5.5053745e+08 | H6: =D6^2 -> 12.184442 | I6: =$N$4+$N$5*C6 -> 12.418376 | J6: =B6-I6 -> -1.5602063 | K6: =I6-$N$2 -> -1.9304157 | M6: Sigma^ | N6: =SUMSQ(J3:J66)/(COUNT(J3:J66)-2) -> 15.713425 | T6: 3º Quartil | U6: =_xlfn.QUARTILE.EXC(B3:B66,3) -> 16.580223 | V6: =_xlfn.QUARTILE.EXC(C3:C66,3) -> 35101.976 | X6: D-C | Y6: =U6-U5 -> 2.9805375 | Z6: =V6-V5 -> 26755.027
A7: Azerbaijan | B7: ='Base de Dados P1'!C7 -> 8.77911 | C7: ='Base de Dados P1'!D7 -> 3126.724 | D7: =B7-$N$2 -> -5.569682 | E7: =C7-$N$3 -> -13509.708 | F7: =E7*D7 -> 75244.776 | G7: =E7^2 -> 1.825122e+08 | H7: =D7^2 -> 31.021358 | I7: =$N$4+$N$5*C7 -> 15.460276 | J7: =B7-I7 -> -6.6811664 | K7: =I7-$N$2 -> 1.1114844 | M7: S² (Alfa) | N7: =((1/COUNT(J3:J66))+N3^2/SUM(G3:G66))*N6 -> 0.47968058 | T7: Máximo | U7: =MAX(B3:B66) -> 26.19325 | V7: =MAX(C3:C66) -> 66117.007 | X7: E-D | Y7: =U7-U6 -> 9.6130275 | Z7: =V7-V6 -> 31015.031
A8: Belarus | B8: ='Base de Dados P1'!C8 -> 12.86463 | C8: ='Base de Dados P1'!D8 -> 4524.1582 | D8: =B8-$N$2 -> -1.484162 | E8: =C8-$N$3 -> -12112.274 | F8: =E8*D8 -> 17976.577 | G8: =E8^2 -> 1.4670717e+08 | H8: =D8^2 -> 2.2027369 | I8: =$N$4+$N$5*C8 -> 15.345305 | J8: =B8-I8 -> -2.4806753 | K8: =I8-$N$2 -> 0.99651325 | M8: S² (Beta) | N8: =N6/SUM(G3:G66) -> 8.4603671e-10 | T8: Média | U8: =AVERAGE(B3:B66) -> 14.348792 | V8: =AVERAGE(C3:C66) -> 16636.432 | X8: LS | Y8: =0 -> 0 | Z8: =0 -> 0
A9: Belgium | B9: ='Base de Dados P1'!C9 -> 12.22374 | C9: ='Base de Dados P1'!D9 -> 37745.502 | D9: =B9-$N$2 -> -2.125052 | E9: =C9-$N$3 -> 21109.07 | F9: =E9*D9 -> -44857.872 | G9: =E9^2 -> 4.4559284e+08 | H9: =D9^2 -> 4.5158461 | I9: =$N$4+$N$5*C9 -> 12.612085 | J9: =B9-I9 -> -0.38834522 | K9: =I9-$N$2 -> -1.7367068 | M9: t(alfa) | N9: =N4/SQRT(N7) -> 22.69384
A10: Brazil | B10: ='Base de Dados P1'!C10 -> 14.55989 | C10: ='Base de Dados P1'!D10 -> 5678.286 | D10: =B10-$N$2 -> 0.21109797 | E10: =C10-$N$3 -> -10958.146 | F10: =E10*D10 -> -2313.2423 | G10: =E10^2 -> 1.2008096e+08 | H10: =D10^2 -> 0.044562352 | I10: =$N$4+$N$5*C10 -> 15.250352 | J10: =B10-I10 -> -0.6904617 | K10: =I10-$N$2 -> 0.90155967 | M10: t(beta) | N10: =N5/SQRT(N8) -> -2.8285431
A11: Bulgaria | B11: ='Base de Dados P1'!C11 -> 11.16342 | C11: ='Base de Dados P1'!D11 -> 4559.6954 | D11: =B11-$N$2 -> -3.185372 | E11: =C11-$N$3 -> -12076.736 | F11: =E11*D11 -> 38468.898 | G11: =E11^2 -> 1.4584756e+08 | H11: =D11^2 -> 10.146595 | I11: =$N$4+$N$5*C11 -> 15.342382 | J11: =B11-I11 -> -4.1789615 | K11: =I11-$N$2 -> 0.99358949 | M11: t(crítico) | N11: =_xlfn.T.INV(5%,(COUNT(D3:D66)-2)) -> -1.6698042
A12: Burundi | B12: ='Base de Dados P1'!C12 -> 16.5881 | C12: ='Base de Dados P1'!D12 -> 150.74275 | D12: =B12-$N$2 -> 2.239308 | E12: =C12-$N$3 -> -16485.689 | F12: =E12*D12 -> -36916.535 | G12: =E12^2 -> 2.7177794e+08 | H12: =D12^2 -> 5.0145002 | I12: =$N$4+$N$5*C12 -> 15.705119 | J12: =B12-I12 -> 0.88298065 | K12: =I12-$N$2 -> 1.3563273 | M12: SQT | N12: =SUMSQ(D3:D66) -> 1099.9501
A13: Canada | B13: ='Base de Dados P1'!C13 -> 12.38789 | C13: ='Base de Dados P1'!D13 -> 36465.711 | D13: =B13-$N$2 -> -1.960902 | E13: =C13-$N$3 -> 19829.279 | F13: =E13*D13 -> -38883.274 | G13: =E13^2 -> 3.9320031e+08 | H13: =D13^2 -> 3.8451368 | I13: =$N$4+$N$5*C13 -> 12.717377 | J13: =B13-I13 -> -0.32948747 | K13: =I13-$N$2 -> -1.6314146 | M13: SQReg | N13: =SUMSQ(K3:K66) -> 125.71771
A14: Chile | B14: ='Base de Dados P1'!C14 -> 17.51402 | C14: ='Base de Dados P1'!D14 -> 8609.2679 | D14: =B14-$N$2 -> 3.165228 | E14: =C14-$N$3 -> -8027.1638 | F14: =E14*D14 -> -25407.803 | G14: =E14^2 -> 64435359 | H14: =D14^2 -> 10.018668 | I14: =$N$4+$N$5*C14 -> 15.009211 | J14: =B14-I14 -> 2.504809 | K14: =I14-$N$2 -> 0.66041896 | M14: SQRes | N14: =SUMSQ(J3:J66) -> 974.23235
A15: Colombia | B15: ='Base de Dados P1'!C15 -> 16.41858 | C15: ='Base de Dados P1'!D15 -> 3939.107 | D15: =B15-$N$2 -> 2.069788 | E15: =C15-$N$3 -> -12697.325 | F15: =E15*D15 -> -26280.77 | G15: =E15^2 -> 1.6122206e+08 | H15: =D15^2 -> 4.2840222 | I15: =$N$4+$N$5*C15 -> 15.393439 | J15: =B15-I15 -> 1.0251408 | K15: =I15-$N$2 -> 1.0446472 | M15: Prova real SQT | N15: =N13+N14 -> 1099.9501
A16: Croatia | B16: ='Base de Dados P1'!C16 -> 9.08259 | C16: ='Base de Dados P1'!D16 -> 10523.915 | D16: =B16-$N$2 -> -5.266202 | E16: =C16-$N$3 -> -6112.5163 | F16: =E16*D16 -> 32189.746 | G16: =E16^2 -> 37362856 | H16: =D16^2 -> 27.732884 | I16: =$N$4+$N$5*C16 -> 14.851687 | J16: =B16-I16 -> -5.7690972 | K16: =I16-$N$2 -> 0.50289514 | M16: R² | N16: =N13/N12 -> 0.11429402
A17: Cyprus | B17: ='Base de Dados P1'!C17 -> 15.68234 | C17: ='Base de Dados P1'!D17 -> 24852.374 | D17: =B17-$N$2 -> 1.333548 | E17: =C17-$N$3 -> 8215.942 | F17: =E17*D17 -> 10956.353 | G17: =E17^2 -> 67501702 | H17: =D17^2 -> 1.7783502 | I17: =$N$4+$N$5*C17 -> 13.672842 | J17: =B17-I17 -> 2.0094983 | K17: =I17-$N$2 -> -0.67595031
A18: Czech Republic | B18: ='Base de Dados P1'!C18 -> 9.7125 | C18: ='Base de Dados P1'!D18 -> 14640.343 | D18: =B18-$N$2 -> -4.636292 | E18: =C18-$N$3 -> -1996.0886 | F18: =E18*D18 -> 9254.4495 | G18: =E18^2 -> 3984369.5 | H18: =D18^2 -> 21.495204 | I18: =$N$4+$N$5*C18 -> 14.513016 | J18: =B18-I18 -> -4.8005163 | K18: =I18-$N$2 -> 0.16422422 | M18: Tabela ANOVA (analysis of variance)
A19: Denmark | B19: ='Base de Dados P1'!C19 -> 15.10334 | C19: ='Base de Dados P1'!D19 -> 47791.92 | D19: =B19-$N$2 -> 0.75454797 | E19: =C19-$N$3 -> 31155.488 | F19: =E19*D19 -> 23508.31 | G19: =E19^2 -> 9.7066442e+08 | H19: =D19^2 -> 0.56934264 | I19: =$N$4+$N$5*C19 -> 11.785536 | J19: =B19-I19 -> 3.3178039 | K19: =I19-$N$2 -> -2.5632559 | M19: FONTE | N19: GL | O19: SQ | P19: QM | Q19: F | R19: F (crit)
A20: El Salvador | B20: ='Base de Dados P1'!C20 -> 16.16422 | C20: ='Base de Dados P1'!D20 -> 2949.6137 | D20: =B20-$N$2 -> 1.815428 | E20: =C20-$N$3 -> -13686.818 | F20: =E20*D20 -> -24847.432 | G20: =E20^2 -> 1.8732899e+08 | H20: =D20^2 -> 3.2957787 | I20: =$N$4+$N$5*C20 -> 15.474848 | J20: =B20-I20 -> 0.6893722 | K20: =I20-$N$2 -> 1.1260558 | M20: Regressão | N20: 1 | O20: =N13 -> 125.71771 | P20: =O20/N20 -> 125.71771 | Q20: =P20/P21 -> 8.0006561 | R20: =FINV(5%,N20,N21) -> 3.9958871
A21: Estonia | B21: ='Base de Dados P1'!C21 -> 13.6818 | C21: ='Base de Dados P1'!D21 -> 10364.464 | D21: =B21-$N$2 -> -0.66699203 | E21: =C21-$N$3 -> -6271.9676 | F21: =E21*D21 -> 4183.3524 | G21: =E21^2 -> 39337578 | H21: =D21^2 -> 0.44487837 | I21: =$N$4+$N$5*C21 -> 14.864806 | J21: =B21-I21 -> -1.1830057 | K21: =I21-$N$2 -> 0.51601368 | M21: Resíduos | N21: =COUNT(D3:D66)-2 -> 62 | O21: =N14 -> 974.23235 | P21: =O21/N21 -> 15.713425
A22: Ethiopia | B22: ='Base de Dados P1'!C22 -> 22.03582 | C22: ='Base de Dados P1'!D22 -> 238.63182 | D22: =B22-$N$2 -> 7.687028 | E22: =C22-$N$3 -> -16397.8 | F22: =E22*D22 -> -126050.35 | G22: =E22^2 -> 2.6888784e+08 | H22: =D22^2 -> 59.090399 | I22: =$N$4+$N$5*C22 -> 15.697888 | J22: =B22-I22 -> 6.3379315 | K22: =I22-$N$2 -> 1.3490964 | M22: Total | N22: =SUM(N20:N21) -> 63 | O22: =N12 -> 1099.9501
A23: Finland | B23: ='Base de Dados P1'!C23 -> 11.95611 | C23: ='Base de Dados P1'!D23 -> 39698.805 | D23: =B23-$N$2 -> -2.392682 | E23: =C23-$N$3 -> 23062.374 | F23: =E23*D23 -> -55180.927 | G23: =E23^2 -> 5.3187308e+08 | H23: =D23^2 -> 5.7249273 | I23: =$N$4+$N$5*C23 -> 12.451381 | J23: =B23-I23 -> -0.49527105 | K23: =I23-$N$2 -> -1.897411
A24: France | B24: ='Base de Dados P1'!C24 -> 10.06913 | C24: ='Base de Dados P1'!D24 -> 35216.5 | D24: =B24-$N$2 -> -4.279662 | E24: =C24-$N$3 -> 18580.068 | F24: =E24*D24 -> -79516.411 | G24: =E24^2 -> 3.4521892e+08 | H24: =D24^2 -> 18.315507 | I24: =$N$4+$N$5*C24 -> 12.820154 | J24: =B24-I24 -> -2.7510239 | K24: =I24-$N$2 -> -1.5286382
A25: Germany | B25: ='Base de Dados P1'!C25 -> 10.61658 | C25: ='Base de Dados P1'!D25 -> 37147.022 | D25: =B25-$N$2 -> -3.732212 | E25: =C25-$N$3 -> 20510.59 | F25: =E25*D25 -> -76549.872 | G25: =E25^2 -> 4.2068432e+08 | H25: =D25^2 -> 13.929407 | I25: =$N$4+$N$5*C25 -> 12.661324 | J25: =B25-I25 -> -2.0447439 | K25: =I25-$N$2 -> -1.6874681
A26: Ghana | B26: ='Base de Dados P1'!C26 -> 21.24422 | C26: ='Base de Dados P1'!D26 -> 606.38422 | D26: =B26-$N$2 -> 6.895428 | E26: =C26-$N$3 -> -16030.048 | F26: =E26*D26 -> -110534.04 | G26: =E26^2 -> 2.5696242e+08 | H26: =D26^2 -> 47.546927 | I26: =$N$4+$N$5*C26 -> 15.667632 | J26: =B26-I26 -> 5.5765876 | K26: =I26-$N$2 -> 1.3188403
A27: Guatemala | B27: ='Base de Dados P1'!C27 -> 19.29692 | C27: ='Base de Dados P1'!D27 -> 2270.0983 | D27: =B27-$N$2 -> 4.948128 | E27: =C27-$N$3 -> -14366.333 | F27: =E27*D27 -> -71086.456 | G27: =E27^2 -> 2.0639154e+08 | H27: =D27^2 -> 24.48397 | I27: =$N$4+$N$5*C27 -> 15.530754 | J27: =B27-I27 -> 3.7661664 | K27: =I27-$N$2 -> 1.1819616
A28: Hong Kong | B28: ='Base de Dados P1'!C28 -> 19.90955 | C28: ='Base de Dados P1'!D28 -> 31328.375 | D28: =B28-$N$2 -> 5.560758 | E28: =C28-$N$3 -> 14691.943 | F28: =E28*D28 -> 81698.342 | G28: =E28^2 -> 2.158532e+08 | H28: =D28^2 -> 30.922029 | I28: =$N$4+$N$5*C28 -> 13.140042 | J28: =B28-I28 -> 6.7695084 | K28: =I28-$N$2 -> -1.2087505
A29: Hungary | B29: ='Base de Dados P1'!C29 -> 9.68498 | C29: ='Base de Dados P1'!D29 -> 11108.9 | D29: =B29-$N$2 -> -4.663812 | E29: =C29-$N$3 -> -5527.5319 | F29: =E29*D29 -> 25779.37 | G29: =E29^2 -> 30553609 | H29: =D29^2 -> 21.751143 | I29: =$N$4+$N$5*C29 -> 14.803559 | J29: =B29-I29 -> -5.1185787 | K29: =I29-$N$2 -> 0.45476671
A30: India | B30: ='Base de Dados P1'!C30 -> 11.74278 | C30: ='Base de Dados P1'!D30 -> 1031.5611 | D30: =B30-$N$2 -> -2.606012 | E30: =C30-$N$3 -> -15604.871 | F30: =E30*D30 -> 40666.481 | G30: =E30^2 -> 2.4351199e+08 | H30: =D30^2 -> 6.7912987 | I30: =$N$4+$N$5*C30 -> 15.632652 | J30: =B30-I30 -> -3.8898718 | K30: =I30-$N$2 -> 1.2838597
A31: Ireland | B31: ='Base de Dados P1'!C31 -> 9.29551 | C31: ='Base de Dados P1'!D31 -> 46425.614 | D31: =B31-$N$2 -> -5.053282 | E31: =C31-$N$3 -> 29789.182 | F31: =E31*D31 -> -150533.14 | G31: =E31^2 -> 8.8739539e+08 | H31: =D31^2 -> 25.535659 | I31: =$N$4+$N$5*C31 -> 11.897946 | J31: =B31-I31 -> -2.6024362 | K31: =I31-$N$2 -> -2.4508458
A32: Israel | B32: ='Base de Dados P1'!C32 -> 13.25932 | C32: ='Base de Dados P1'!D32 -> 23225.416 | D32: =B32-$N$2 -> -1.089472 | E32: =C32-$N$3 -> 6588.9839 | F32: =E32*D32 -> -7178.5136 | G32: =E32^2 -> 43414708 | H32: =D32^2 -> 1.1869493 | I32: =$N$4+$N$5*C32 -> 13.806696 | J32: =B32-I32 -> -0.54737647 | K32: =I32-$N$2 -> -0.54209556
A33: Italy | B33: ='Base de Dados P1'!C33 -> 8.72395 | C33: ='Base de Dados P1'!D33 -> 30788.539 | D33: =B33-$N$2 -> -5.624842 | E33: =C33-$N$3 -> 14152.107 | F33: =E33*D33 -> -79603.366 | G33: =E33^2 -> 2.0028213e+08 | H33: =D33^2 -> 31.638848 | I33: =$N$4+$N$5*C33 -> 13.184456 | J33: =B33-I33 -> -4.4605055 | K33: =I33-$N$2 -> -1.1643365
A34: Japan | B34: ='Base de Dados P1'!C34 -> 9.45758 | C34: ='Base de Dados P1'!D34 -> 36296.315 | D34: =B34-$N$2 -> -4.891212 | E34: =C34-$N$3 -> 19659.884 | F34: =E34*D34 -> -96160.66 | G34: =E34^2 -> 3.8651103e+08 | H34: =D34^2 -> 23.923955 | I34: =$N$4+$N$5*C34 -> 12.731314 | J34: =B34-I34 -> -3.2737341 | K34: =I34-$N$2 -> -1.6174779
... A36: Kyrgyz Republic | B36: ='Base de Dados P1'!C36 -> 15.68476 | C36: ='Base de Dados P1'!D36 -> 560.99914 | D36: =B36-$N$2 -> 1.335968 | E36: =C36-$N$3 -> -16075.433 | F36: =E36*D36 -> -21476.263 | G36: =E36^2 -> 2.5841953e+08 | H36: =D36^2 -> 1.7848104 | I36: =$N$4+$N$5*C36 -> 15.671366 | J36: =B36-I36 -> 0.013393679 | K36: =I36-$N$2 -> 1.3225743
A37: Latvia | B37: ='Base de Dados P1'!C37 -> 8.12264 | C37: ='Base de Dados P1'!D37 -> 8058.7935 | D37: =B37-$N$2 -> -6.226152 | E37: =C37-$N$3 -> -8577.6382 | F37: =E37*D37 -> 53405.679 | G37: =E37^2 -> 73575877 | H37: =D37^2 -> 38.764969 | I37: =$N$4+$N$5*C37 -> 15.0545 | J37: =B37-I37 -> -6.9318602 | K37: =I37-$N$2 -> 0.70570815 | T37: Resposta 1ª questão : | X37: Correlação | Y37: =CORREL(C3:C66,B3:B66) -> -0.33807398
A38: Macao | B38: ='Base de Dados P1'!C38 -> 15.67268 | C38: ='Base de Dados P1'!D38 -> 38689.017 | D38: =B38-$N$2 -> 1.323888 | E38: =C38-$N$3 -> 22052.585 | F38: =E38*D38 -> 29195.153 | G38: =E38^2 -> 4.8631653e+08 | H38: =D38^2 -> 1.7526794 | I38: =$N$4+$N$5*C38 -> 12.534459 | J38: =B38-I38 -> 3.1382206 | K38: =I38-$N$2 -> -1.8143327 | T38: Podemos concluir de acordo com o gráfico que a variável X segue a linha de teendência em relação à variável Y, ou seja, existe uma correlação entre essas duas variáveis. Quanto maior gastos em educação, maior valor do pip per capita do país analisado.
A39: Malaysia | B39: ='Base de Dados P1'!C39 -> 18.40623 | C39: ='Base de Dados P1'!D39 -> 6319.0036 | D39: =B39-$N$2 -> 4.057438 | E39: =C39-$N$3 -> -10317.428 | F39: =E39*D39 -> -41862.324 | G39: =E39^2 -> 1.0644932e+08 | H39: =D39^2 -> 16.462803 | I39: =$N$4+$N$5*C39 -> 15.197638 | J39: =B39-I39 -> 3.2085921 | K39: =I39-$N$2 -> 0.8488459
A40: Mali | B40: ='Base de Dados P1'!C40 -> 16.50391 | C40: ='Base de Dados P1'!D40 -> 498.47515 | D40: =B40-$N$2 -> 2.155118 | E40: =C40-$N$3 -> -16137.957 | F40: =E40*D40 -> -34779.2 | G40: =E40^2 -> 2.6043364e+08 | H40: =D40^2 -> 4.6445335 | I40: =$N$4+$N$5*C40 -> 15.67651 | J40: =B40-I40 -> 0.82739964 | K40: =I40-$N$2 -> 1.3277183
A41: Malta | B41: ='Base de Dados P1'!C41 -> 15.73082 | C41: ='Base de Dados P1'!D41 -> 16227.712 | D41: =B41-$N$2 -> 1.382028 | E41: =C41-$N$3 -> -408.71961 | F41: =E41*D41 -> -564.86194 | G41: =E41^2 -> 167051.72 | H41: =D41^2 -> 1.9100013 | I41: =$N$4+$N$5*C41 -> 14.382419 | J41: =B41-I41 -> 1.3484014 | K41: =I41-$N$2 -> 0.033626594
...
