Workbook

Sheet Database Geral
A1: País | B1: Gastos P&D (%) | C1: Taxa Crescimento (%) | D1: PIB per capita (US$ constantes de 2005) | E1: Razão de Dependência de Jovens (%) | F1: Gastos com educação (%) | G1: População
A2: Argentina | B2: 0.61745 | C2: 9.4515783 | D2: 7293.6582 | E2: 38.566712 | F2: 15.57046 | G2: 45195774
A3: Armenia | B3: 0.24139 | C3: 2.2 | D3: 1997.0523 | E3: 29.758869 | F3: 12.40051 | G3: 2963243
A4: Australia | B4: 2.3856201 | C4: 1.9623661 | D4: 36175.113 | E4: 28.019033 | F4: 14.3276 | G4: 25499884
A5: Austria | B5: 2.79846 | C5: 1.8801177 | D5: 40099.966 | E5: 21.881818 | F5: 10.85817 | G5: 9006398
A6: Azerbaijan | B6: 0.21848001 | C6: 4.8543393 | D6: 3126.724 | E6: 31.79129 | F6: 8.77911 | G6: 10139177
A7: Belarus | B7: 0.69349998 | C7: 7.7407812 | D7: 4524.1582 | E7: 20.852179 | F7: 12.86463 | G7: 9449323
A8: Belgium | B8: 2.10478 | C8: 2.5010546 | D8: 37745.502 | E8: 25.395926 | F8: 12.22374 | G8: 11589623
A9: Brazil | B9: 1.1604199 | C9: 7.5720672 | D9: 5678.286 | E9: 37.709678 | F9: 14.55989 | G9: 212559417
A10: Bulgaria | B10: 0.59794003 | C10: 0.65532511 | D10: 4559.6954 | E10: 19.485786 | F10: 11.16342 | G10: 6948445
A11: Burundi | B11: 0.13755 | C11: 3.7859025 | D11: 150.74275 | E11: 82.053945 | F11: 16.5881 | G11: 11890784
A12: Canada | B12: 1.86008 | C12: 3.3742486 | D12: 36465.711 | E12: 23.744055 | F12: 12.38789 | G12: 37742154
A13: Chile | B13: 0.41722 | C13: 5.7537089 | D13: 8609.2679 | E13: 32.237808 | F13: 17.51402 | G13: 19116201
... A65: United States | B65: 2.73827 | C65: 2.5319204 | D65: 43961.169 | E65: 29.568269 | F65: 13.03757 | G65: 331002651

Sheet Cruzamento
A1: RA | B1: Variável Y | C1: Variável X1 | D1: Variável X2 | E1: Variável X3
A2: 102180010 | B2: Gastos P&D (%) | C2: Taxa Crescimento (%) | D2: PIB per capita (US$ constantes de 2005) | E2: Razão de Dependência de Jovens (%)
A3: 101190016 | B3: Taxa Crescimento (%) | C3: PIB per capita (US$ constantes de 2005) | D3: Razão de Dependência de Jovens (%) | E3: Gastos com educação (%)
A4: 101200457 | B4: PIB per capita (US$ constantes de 2005) | C4: Razão de Dependência de Jovens (%) | D4: Gastos com educação (%) | E4: Gastos P&D (%)
A5: 102180021 | B5: Razão de Dependência de Jovens (%) | C5: Gastos com educação (%) | D5: Gastos P&D (%) | E5: Taxa Crescimento (%)
A6: 101170214 | B6: Gastos com educação (%) | C6: Gastos P&D (%) | D6: Taxa Crescimento (%) | E6: PIB per capita (US$ constantes de 2005)
A7: 101180193 | B7: Gastos P&D (%) | C7: PIB per capita (US$ constantes de 2005) | D7: Razão de Dependência de Jovens (%) | E7: Gastos com educação (%)
A8: 101190475 | B8: Taxa Crescimento (%) | C8: Razão de Dependência de Jovens (%) | D8: Gastos com educação (%) | E8: Gastos P&D (%)
A9: 102180054 | B9: PIB per capita (US$ constantes de 2005) | C9: Gastos com educação (%) | D9: Gastos P&D (%) | E9: Taxa Crescimento (%)
A10: 102180027 | B10: Razão de Dependência de Jovens (%) | C10: Gastos P&D (%) | D10: Taxa Crescimento (%) | E10: PIB per capita (US$ constantes de 2005)
A11: 101190516 | B11: Gastos com educação (%) | C11: Taxa Crescimento (%) | D11: PIB per capita (US$ constantes de 2005) | E11: Razão de Dependência de Jovens (%)
A12: 101190648 | B12: Gastos P&D (%) | C12: Razão de Dependência de Jovens (%) | D12: Gastos com educação (%) | E12: Taxa Crescimento (%)
A13: 101180325 | B13: Taxa Crescimento (%) | C13: Gastos com educação (%) | D13: Gastos P&D (%) | E13: PIB per capita (US$ constantes de 2005)
... A31: 101170502 | B31: Gastos com educação (%) | C31: Razão de Dependência de Jovens (%) | D31: Taxa Crescimento (%) | E31: PIB per capita (US$ constantes de 2005)

Sheet Base de Dados P1
B1: País | C1: Variável Y | D1: Variável X1 | E1: Variável X2 | F1: Variável X3 | H1: População (só use essa variável no item 8, SE ESTE FOR O SEU CASO) | J1: Insira seu RA abaixo | L1: Escola Superior de Administração, Marketing e Comunicação (ESAMC) 10175/A - Econometria - 1º Sem. de 2021 - Prof. Pier Francesco De Maria
C2: =IFERROR(VLOOKUP('Base de Dados P1'!J2,Cruzamento!$A$2:$E$31,2,FALSE),"") -> Gastos P&D (%) | D2: =IFERROR(VLOOKUP('Base de Dados P1'!J2,Cruzamento!$A$2:$E$31,3,FALSE),"") -> Razão de Dependência de Jovens (%) | E2: =IFERROR(VLOOKUP('Base de Dados P1'!J2,Cruzamento!$A$2:$E$31,4,FALSE),"") -> Gastos com educação (%) | F2: =IFERROR(VLOOKUP('Base de Dados P1'!J2,Cruzamento!$A$2:$E$31,5,FALSE),"") -> Taxa Crescimento (%) | J2: 101190648
A3: 2 | B3: Argentina | C3: =IFERROR(IF(HLOOKUP(C$2,'Database Geral'!$B$1:$F$65,'Base de Dados P1'!$A3,FALSE)=0,,HLOOKUP(C$2,'Database Geral'!$B$1:$F$65,'Base de Dados P1'!$A3,FALSE)),"") -> 0.61745 | D3: =IFERROR(IF(HLOOKUP(D$2,'Database Geral'!$B$1:$F$65,'Base de Dados P1'!$A3,FALSE)=0,,HLOOKUP(D$2,'Database Geral'!$B$1:$F$65,'Base de Dados P1'!$A3,FALSE)),"") -> 38.566712 | E3: =IFERROR(IF(HLOOKUP(E$2,'Database Geral'!$B$1:$F$65,'Base de Dados P1'!$A3,FALSE)=0,,HLOOKUP(E$2,'Database Geral'!$B$1:$F$65,'Base de Dados P1'!$A3,FALSE)),"") -> 15.57046 | F3: =IFERROR(IF(HLOOKUP(F$2,'Database Geral'!$B$1:$F$65,'Base de Dados P1'!$A3,FALSE)=0,,HLOOKUP(F$2,'Database Geral'!$B$1:$F$65,'Base de Dados P1'!$A3,FALSE)),"") -> 9.4515783 | H3: ='Database Geral'!G2 -> 45195774
A4: 3 | B4: Armenia | C4: =IFERROR(IF(HLOOKUP(C$2,'Database Geral'!$B$1:$F$65,'Base de Dados P1'!$A4,FALSE)=0,,HLOOKUP(C$2,'Database Geral'!$B$1:$F$65,'Base de Dados P1'!$A4,FALSE)),"") -> 0.24139 | D4: =IFERROR(IF(HLOOKUP(D$2,'Database Geral'!$B$1:$F$65,'Base de Dados P1'!$A4,FALSE)=0,,HLOOKUP(D$2,'Database Geral'!$B$1:$F$65,'Base de Dados P1'!$A4,FALSE)),"") -> 29.758869 | E4: =IFERROR(IF(HLOOKUP(E$2,'Database Geral'!$B$1:$F$65,'Base de Dados P1'!$A4,FALSE)=0,,HLOOKUP(E$2,'Database Geral'!$B$1:$F$65,'Base de Dados P1'!$A4,FALSE)),"") -> 12.40051 | F4: =IFERROR(IF(HLOOKUP(F$2,'Database Geral'!$B$1:$F$65,'Base de Dados P1'!$A4,FALSE)=0,,HLOOKUP(F$2,'Database Geral'!$B$1:$F$65,'Base de Dados P1'!$A4,FALSE)),"") -> 2.2 | H4: ='Database Geral'!G3 -> 2963243 | L4: Prova 1 / Parte B (Modelo de Regressão Linear Múltipla)
A5: 4 | B5: Australia | C5: =IFERROR(IF(HLOOKUP(C$2,'Database Geral'!$B$1:$F$65,'Base de Dados P1'!$A5,FALSE)=0,,HLOOKUP(C$2,'Database Geral'!$B$1:$F$65,'Base de Dados P1'!$A5,FALSE)),"") -> 2.3856201 | D5: =IFERROR(IF(HLOOKUP(D$2,'Database Geral'!$B$1:$F$65,'Base de Dados P1'!$A5,FALSE)=0,,HLOOKUP(D$2,'Database Geral'!$B$1:$F$65,'Base de Dados P1'!$A5,FALSE)),"") -> 28.019033 | E5: =IFERROR(IF(HLOOKUP(E$2,'Database Geral'!$B$1:$F$65,'Base de Dados P1'!$A5,FALSE)=0,,HLOOKUP(E$2,'Database Geral'!$B$1:$F$65,'Base de Dados P1'!$A5,FALSE)),"") -> 14.3276 | F5: =IFERROR(IF(HLOOKUP(F$2,'Database Geral'!$B$1:$F$65,'Base de Dados P1'!$A5,FALSE)=0,,HLOOKUP(F$2,'Database Geral'!$B$1:$F$65,'Base de Dados P1'!$A5,FALSE)),"") -> 1.9623661 | H5: ='Database Geral'!G4 -> 25499884 | J5: A pontuação máxima desta prova é 5.0 (cinco) pontos. À nota desta prova será somada a nota da Parte 1, compondo a nota da P1. Você recebeu as variáveis ao lado (uma Y e três X) para criar um modelo de regressão linear múltipla (RLM). Faça o que é pedido, na ordem indicada, por meio de fórmulas matriciais. NÃO use o método rápido ("Análise de Dados") para apresentar as respostas, pois estas não serão consideradas para avaliação. Use a aba "Folha de Respostas" para fazer as contas necessárias (você não tem como adicionar/eliminar abas). Deixe todas as fórmulas! Você terá até 26/04 (23h59) para fazer e entregar esta prova. Ao terminar a sua prova, SALVE O ARQUIVO E ENVIE PARA O E-MAIL pier.francesco@esamc.br!
A6: 5 | B6: Austria | C6: =IFERROR(IF(HLOOKUP(C$2,'Database Geral'!$B$1:$F$65,'Base de Dados P1'!$A6,FALSE)=0,,HLOOKUP(C$2,'Database Geral'!$B$1:$F$65,'Base de Dados P1'!$A6,FALSE)),"") -> 2.79846 | D6: =IFERROR(IF(HLOOKUP(D$2,'Database Geral'!$B$1:$F$65,'Base de Dados P1'!$A6,FALSE)=0,,HLOOKUP(D$2,'Database Geral'!$B$1:$F$65,'Base de Dados P1'!$A6,FALSE)),"") -> 21.881818 | E6: =IFERROR(IF(HLOOKUP(E$2,'Database Geral'!$B$1:$F$65,'Base de Dados P1'!$A6,FALSE)=0,,HLOOKUP(E$2,'Database Geral'!$B$1:$F$65,'Base de Dados P1'!$A6,FALSE)),"") -> 10.85817 | F6: =IFERROR(IF(HLOOKUP(F$2,'Database Geral'!$B$1:$F$65,'Base de Dados P1'!$A6,FALSE)=0,,HLOOKUP(F$2,'Database Geral'!$B$1:$F$65,'Base de Dados P1'!$A6,FALSE)),"") -> 1.8801177 | H6: ='Database Geral'!G5 -> 9006398
A7: 6 | B7: Azerbaijan | C7: =IFERROR(IF(HLOOKUP(C$2,'Database Geral'!$B$1:$F$65,'Base de Dados P1'!$A7,FALSE)=0,,HLOOKUP(C$2,'Database Geral'!$B$1:$F$65,'Base de Dados P1'!$A7,FALSE)),"") -> 0.21848001 | D7: =IFERROR(IF(HLOOKUP(D$2,'Database Geral'!$B$1:$F$65,'Base de Dados P1'!$A7,FALSE)=0,,HLOOKUP(D$2,'Database Geral'!$B$1:$F$65,'Base de Dados P1'!$A7,FALSE)),"") -> 31.79129 | E7: =IFERROR(IF(HLOOKUP(E$2,'Database Geral'!$B$1:$F$65,'Base de Dados P1'!$A7,FALSE)=0,,HLOOKUP(E$2,'Database Geral'!$B$1:$F$65,'Base de Dados P1'!$A7,FALSE)),"") -> 8.77911 | F7: =IFERROR(IF(HLOOKUP(F$2,'Database Geral'!$B$1:$F$65,'Base de Dados P1'!$A7,FALSE)=0,,HLOOKUP(F$2,'Database Geral'!$B$1:$F$65,'Base de Dados P1'!$A7,FALSE)),"") -> 4.8543393 | H7: ='Database Geral'!G6 -> 10139177
A8: 7 | B8: Belarus | C8: =IFERROR(IF(HLOOKUP(C$2,'Database Geral'!$B$1:$F$65,'Base de Dados P1'!$A8,FALSE)=0,,HLOOKUP(C$2,'Database Geral'!$B$1:$F$65,'Base de Dados P1'!$A8,FALSE)),"") -> 0.69349998 | D8: =IFERROR(IF(HLOOKUP(D$2,'Database Geral'!$B$1:$F$65,'Base de Dados P1'!$A8,FALSE)=0,,HLOOKUP(D$2,'Database Geral'!$B$1:$F$65,'Base de Dados P1'!$A8,FALSE)),"") -> 20.852179 | E8: =IFERROR(IF(HLOOKUP(E$2,'Database Geral'!$B$1:$F$65,'Base de Dados P1'!$A8,FALSE)=0,,HLOOKUP(E$2,'Database Geral'!$B$1:$F$65,'Base de Dados P1'!$A8,FALSE)),"") -> 12.86463 | F8: =IFERROR(IF(HLOOKUP(F$2,'Database Geral'!$B$1:$F$65,'Base de Dados P1'!$A8,FALSE)=0,,HLOOKUP(F$2,'Database Geral'!$B$1:$F$65,'Base de Dados P1'!$A8,FALSE)),"") -> 7.7407812 | H8: ='Database Geral'!G7 -> 9449323
A9: 8 | B9: Belgium | C9: =IFERROR(IF(HLOOKUP(C$2,'Database Geral'!$B$1:$F$65,'Base de Dados P1'!$A9,FALSE)=0,,HLOOKUP(C$2,'Database Geral'!$B$1:$F$65,'Base de Dados P1'!$A9,FALSE)),"") -> 2.10478 | D9: =IFERROR(IF(HLOOKUP(D$2,'Database Geral'!$B$1:$F$65,'Base de Dados P1'!$A9,FALSE)=0,,HLOOKUP(D$2,'Database Geral'!$B$1:$F$65,'Base de Dados P1'!$A9,FALSE)),"") -> 25.395926 | E9: =IFERROR(IF(HLOOKUP(E$2,'Database Geral'!$B$1:$F$65,'Base de Dados P1'!$A9,FALSE)=0,,HLOOKUP(E$2,'Database Geral'!$B$1:$F$65,'Base de Dados P1'!$A9,FALSE)),"") -> 12.22374 | F9: =IFERROR(IF(HLOOKUP(F$2,'Database Geral'!$B$1:$F$65,'Base de Dados P1'!$A9,FALSE)=0,,HLOOKUP(F$2,'Database Geral'!$B$1:$F$65,'Base de Dados P1'!$A9,FALSE)),"") -> 2.5010546 | H9: ='Database Geral'!G8 -> 11589623
A10: 9 | B10: Brazil | C10: =IFERROR(IF(HLOOKUP(C$2,'Database Geral'!$B$1:$F$65,'Base de Dados P1'!$A10,FALSE)=0,,HLOOKUP(C$2,'Database Geral'!$B$1:$F$65,'Base de Dados P1'!$A10,FALSE)),"") -> 1.1604199 | D10: =IFERROR(IF(HLOOKUP(D$2,'Database Geral'!$B$1:$F$65,'Base de Dados P1'!$A10,FALSE)=0,,HLOOKUP(D$2,'Database Geral'!$B$1:$F$65,'Base de Dados P1'!$A10,FALSE)),"") -> 37.709678 | E10: =IFERROR(IF(HLOOKUP(E$2,'Database Geral'!$B$1:$F$65,'Base de Dados P1'!$A10,FALSE)=0,,HLOOKUP(E$2,'Database Geral'!$B$1:$F$65,'Base de Dados P1'!$A10,FALSE)),"") -> 14.55989 | F10: =IFERROR(IF(HLOOKUP(F$2,'Database Geral'!$B$1:$F$65,'Base de Dados P1'!$A10,FALSE)=0,,HLOOKUP(F$2,'Database Geral'!$B$1:$F$65,'Base de Dados P1'!$A10,FALSE)),"") -> 7.5720672 | H10: ='Database Geral'!G9 -> 212559417
A11: 10 | B11: Bulgaria | C11: =IFERROR(IF(HLOOKUP(C$2,'Database Geral'!$B$1:$F$65,'Base de Dados P1'!$A11,FALSE)=0,,HLOOKUP(C$2,'Database Geral'!$B$1:$F$65,'Base de Dados P1'!$A11,FALSE)),"") -> 0.59794003 | D11: =IFERROR(IF(HLOOKUP(D$2,'Database Geral'!$B$1:$F$65,'Base de Dados P1'!$A11,FALSE)=0,,HLOOKUP(D$2,'Database Geral'!$B$1:$F$65,'Base de Dados P1'!$A11,FALSE)),"") -> 19.485786 | E11: =IFERROR(IF(HLOOKUP(E$2,'Database Geral'!$B$1:$F$65,'Base de Dados P1'!$A11,FALSE)=0,,HLOOKUP(E$2,'Database Geral'!$B$1:$F$65,'Base de Dados P1'!$A11,FALSE)),"") -> 11.16342 | F11: =IFERROR(IF(HLOOKUP(F$2,'Database Geral'!$B$1:$F$65,'Base de Dados P1'!$A11,FALSE)=0,,HLOOKUP(F$2,'Database Geral'!$B$1:$F$65,'Base de Dados P1'!$A11,FALSE)),"") -> 0.65532511 | H11: ='Database Geral'!G10 -> 6948445
A12: 11 | B12: Burundi | C12: =IFERROR(IF(HLOOKUP(C$2,'Database Geral'!$B$1:$F$65,'Base de Dados P1'!$A12,FALSE)=0,,HLOOKUP(C$2,'Database Geral'!$B$1:$F$65,'Base de Dados P1'!$A12,FALSE)),"") -> 0.13755 | D12: =IFERROR(IF(HLOOKUP(D$2,'Database Geral'!$B$1:$F$65,'Base de Dados P1'!$A12,FALSE)=0,,HLOOKUP(D$2,'Database Geral'!$B$1:$F$65,'Base de Dados P1'!$A12,FALSE)),"") -> 82.053945 | E12: =IFERROR(IF(HLOOKUP(E$2,'Database Geral'!$B$1:$F$65,'Base de Dados P1'!$A12,FALSE)=0,,HLOOKUP(E$2,'Database Geral'!$B$1:$F$65,'Base de Dados P1'!$A12,FALSE)),"") -> 16.5881 | F12: =IFERROR(IF(HLOOKUP(F$2,'Database Geral'!$B$1:$F$65,'Base de Dados P1'!$A12,FALSE)=0,,HLOOKUP(F$2,'Database Geral'!$B$1:$F$65,'Base de Dados P1'!$A12,FALSE)),"") -> 3.7859025 | H12: ='Database Geral'!G11 -> 11890784
A13: 12 | B13: Canada | C13: =IFERROR(IF(HLOOKUP(C$2,'Database Geral'!$B$1:$F$65,'Base de Dados P1'!$A13,FALSE)=0,,HLOOKUP(C$2,'Database Geral'!$B$1:$F$65,'Base de Dados P1'!$A13,FALSE)),"") -> 1.86008 | D13: =IFERROR(IF(HLOOKUP(D$2,'Database Geral'!$B$1:$F$65,'Base de Dados P1'!$A13,FALSE)=0,,HLOOKUP(D$2,'Database Geral'!$B$1:$F$65,'Base de Dados P1'!$A13,FALSE)),"") -> 23.744055 | E13: =IFERROR(IF(HLOOKUP(E$2,'Database Geral'!$B$1:$F$65,'Base de Dados P1'!$A13,FALSE)=0,,HLOOKUP(E$2,'Database Geral'!$B$1:$F$65,'Base de Dados P1'!$A13,FALSE)),"") -> 12.38789 | F13: =IFERROR(IF(HLOOKUP(F$2,'Database Geral'!$B$1:$F$65,'Base de Dados P1'!$A13,FALSE)=0,,HLOOKUP(F$2,'Database Geral'!$B$1:$F$65,'Base de Dados P1'!$A13,FALSE)),"") -> 3.3742486 | H13: ='Database Geral'!G12 -> 37742154
A14: 13 | B14: Chile | C14: =IFERROR(IF(HLOOKUP(C$2,'Database Geral'!$B$1:$F$65,'Base de Dados P1'!$A14,FALSE)=0,,HLOOKUP(C$2,'Database Geral'!$B$1:$F$65,'Base de Dados P1'!$A14,FALSE)),"") -> 0.41722 | D14: =IFERROR(IF(HLOOKUP(D$2,'Database Geral'!$B$1:$F$65,'Base de Dados P1'!$A14,FALSE)=0,,HLOOKUP(D$2,'Database Geral'!$B$1:$F$65,'Base de Dados P1'!$A14,FALSE)),"") -> 32.237808 | E14: =IFERROR(IF(HLOOKUP(E$2,'Database Geral'!$B$1:$F$65,'Base de Dados P1'!$A14,FALSE)=0,,HLOOKUP(E$2,'Database Geral'!$B$1:$F$65,'Base de Dados P1'!$A14,FALSE)),"") -> 17.51402 | F14: =IFERROR(IF(HLOOKUP(F$2,'Database Geral'!$B$1:$F$65,'Base de Dados P1'!$A14,FALSE)=0,,HLOOKUP(F$2,'Database Geral'!$B$1:$F$65,'Base de Dados P1'!$A14,FALSE)),"") -> 5.7537089 | H14: ='Database Geral'!G13 -> 19116201 | J14: Exercícios
A15: 14 | B15: Colombia | C15: =IFERROR(IF(HLOOKUP(C$2,'Database Geral'!$B$1:$F$65,'Base de Dados P1'!$A15,FALSE)=0,,HLOOKUP(C$2,'Database Geral'!$B$1:$F$65,'Base de Dados P1'!$A15,FALSE)),"") -> 0.18054 | D15: =IFERROR(IF(HLOOKUP(D$2,'Database Geral'!$B$1:$F$65,'Base de Dados P1'!$A15,FALSE)=0,,HLOOKUP(D$2,'Database Geral'!$B$1:$F$65,'Base de Dados P1'!$A15,FALSE)),"") -> 43.827462 | E15: =IFERROR(IF(HLOOKUP(E$2,'Database Geral'!$B$1:$F$65,'Base de Dados P1'!$A15,FALSE)=0,,HLOOKUP(E$2,'Database Geral'!$B$1:$F$65,'Base de Dados P1'!$A15,FALSE)),"") -> 16.41858 | F15: =IFERROR(IF(HLOOKUP(F$2,'Database Geral'!$B$1:$F$65,'Base de Dados P1'!$A15,FALSE)=0,,HLOOKUP(F$2,'Database Geral'!$B$1:$F$65,'Base de Dados P1'!$A15,FALSE)),"") -> 3.9718007 | H15: ='Database Geral'!G14 -> 50882891 | J15: 1) (0.75 pontos) Construa as matrizes necessárias para calcular adequadamente o modelo de regressão.
A16: 15 | B16: Croatia | C16: =IFERROR(IF(HLOOKUP(C$2,'Database Geral'!$B$1:$F$65,'Base de Dados P1'!$A16,FALSE)=0,,HLOOKUP(C$2,'Database Geral'!$B$1:$F$65,'Base de Dados P1'!$A16,FALSE)),"") -> 0.75443 | D16: =IFERROR(IF(HLOOKUP(D$2,'Database Geral'!$B$1:$F$65,'Base de Dados P1'!$A16,FALSE)=0,,HLOOKUP(D$2,'Database Geral'!$B$1:$F$65,'Base de Dados P1'!$A16,FALSE)),"") -> 22.775894 | E16: =IFERROR(IF(HLOOKUP(E$2,'Database Geral'!$B$1:$F$65,'Base de Dados P1'!$A16,FALSE)=0,,HLOOKUP(E$2,'Database Geral'!$B$1:$F$65,'Base de Dados P1'!$A16,FALSE)),"") -> 9.08259 | F16: =IFERROR(IF(HLOOKUP(F$2,'Database Geral'!$B$1:$F$65,'Base de Dados P1'!$A16,FALSE)=0,,HLOOKUP(F$2,'Database Geral'!$B$1:$F$65,'Base de Dados P1'!$A16,FALSE)),"") -> -1.7011369 | H16: ='Database Geral'!G15 -> 4105267 | J16: 2) (1.00 pontos) Estime os coeficientes do modelo de regressão Ŷ = α + β1X1 + β2X2 + β3X3 . Interprete o modelo obtido.
A17: 16 | B17: Cyprus | C17: =IFERROR(IF(HLOOKUP(C$2,'Database Geral'!$B$1:$F$65,'Base de Dados P1'!$A17,FALSE)=0,,HLOOKUP(C$2,'Database Geral'!$B$1:$F$65,'Base de Dados P1'!$A17,FALSE)),"") -> 0.49355 | D17: =IFERROR(IF(HLOOKUP(D$2,'Database Geral'!$B$1:$F$65,'Base de Dados P1'!$A17,FALSE)=0,,HLOOKUP(D$2,'Database Geral'!$B$1:$F$65,'Base de Dados P1'!$A17,FALSE)),"") -> 25.145563 | E17: =IFERROR(IF(HLOOKUP(E$2,'Database Geral'!$B$1:$F$65,'Base de Dados P1'!$A17,FALSE)=0,,HLOOKUP(E$2,'Database Geral'!$B$1:$F$65,'Base de Dados P1'!$A17,FALSE)),"") -> 15.68234 | F17: =IFERROR(IF(HLOOKUP(F$2,'Database Geral'!$B$1:$F$65,'Base de Dados P1'!$A17,FALSE)=0,,HLOOKUP(F$2,'Database Geral'!$B$1:$F$65,'Base de Dados P1'!$A17,FALSE)),"") -> 1.3906441 | H17: ='Database Geral'!G16 -> 1207359 | J17: 3) (0.75 pontos) Avalie, individualmente, se os coeficientes obtidos são estatisticamente significativos.
A18: 17 | B18: Czech Republic | C18: =IFERROR(IF(HLOOKUP(C$2,'Database Geral'!$B$1:$F$65,'Base de Dados P1'!$A18,FALSE)=0,,HLOOKUP(C$2,'Database Geral'!$B$1:$F$65,'Base de Dados P1'!$A18,FALSE)),"") -> 1.3974 | D18: =IFERROR(IF(HLOOKUP(D$2,'Database Geral'!$B$1:$F$65,'Base de Dados P1'!$A18,FALSE)=0,,HLOOKUP(D$2,'Database Geral'!$B$1:$F$65,'Base de Dados P1'!$A18,FALSE)),"") -> 20.151364 | E18: =IFERROR(IF(HLOOKUP(E$2,'Database Geral'!$B$1:$F$65,'Base de Dados P1'!$A18,FALSE)=0,,HLOOKUP(E$2,'Database Geral'!$B$1:$F$65,'Base de Dados P1'!$A18,FALSE)),"") -> 9.7125 | F18: =IFERROR(IF(HLOOKUP(F$2,'Database Geral'!$B$1:$F$65,'Base de Dados P1'!$A18,FALSE)=0,,HLOOKUP(F$2,'Database Geral'!$B$1:$F$65,'Base de Dados P1'!$A18,FALSE)),"") -> 2.2950891 | H18: ='Database Geral'!G17 -> 10708981 | J18: 4) (0.50 pontos) Obtenha o R² e o R² ajustado. Interprete o segundo valor.
A19: 18 | B19: Denmark | C19: =IFERROR(IF(HLOOKUP(C$2,'Database Geral'!$B$1:$F$65,'Base de Dados P1'!$A19,FALSE)=0,,HLOOKUP(C$2,'Database Geral'!$B$1:$F$65,'Base de Dados P1'!$A19,FALSE)),"") -> 3.00138 | D19: =IFERROR(IF(HLOOKUP(D$2,'Database Geral'!$B$1:$F$65,'Base de Dados P1'!$A19,FALSE)=0,,HLOOKUP(D$2,'Database Geral'!$B$1:$F$65,'Base de Dados P1'!$A19,FALSE)),"") -> 27.475773 | E19: =IFERROR(IF(HLOOKUP(E$2,'Database Geral'!$B$1:$F$65,'Base de Dados P1'!$A19,FALSE)=0,,HLOOKUP(E$2,'Database Geral'!$B$1:$F$65,'Base de Dados P1'!$A19,FALSE)),"") -> 15.10334 | F19: =IFERROR(IF(HLOOKUP(F$2,'Database Geral'!$B$1:$F$65,'Base de Dados P1'!$A19,FALSE)=0,,HLOOKUP(F$2,'Database Geral'!$B$1:$F$65,'Base de Dados P1'!$A19,FALSE)),"") -> 1.6251359 | H19: ='Database Geral'!G18 -> 5792202 | J19: 5) (0.50 pontos) Monte a tabela ANOVA e identifique se o modelo é estatisticamente válido.
A20: 19 | B20: El Salvador | C20: =IFERROR(IF(HLOOKUP(C$2,'Database Geral'!$B$1:$F$65,'Base de Dados P1'!$A20,FALSE)=0,,HLOOKUP(C$2,'Database Geral'!$B$1:$F$65,'Base de Dados P1'!$A20,FALSE)),"") -> 0.067230001 | D20: =IFERROR(IF(HLOOKUP(D$2,'Database Geral'!$B$1:$F$65,'Base de Dados P1'!$A20,FALSE)=0,,HLOOKUP(D$2,'Database Geral'!$B$1:$F$65,'Base de Dados P1'!$A20,FALSE)),"") -> 52.564166 | E20: =IFERROR(IF(HLOOKUP(E$2,'Database Geral'!$B$1:$F$65,'Base de Dados P1'!$A20,FALSE)=0,,HLOOKUP(E$2,'Database Geral'!$B$1:$F$65,'Base de Dados P1'!$A20,FALSE)),"") -> 16.16422 | F20: =IFERROR(IF(HLOOKUP(F$2,'Database Geral'!$B$1:$F$65,'Base de Dados P1'!$A20,FALSE)=0,,HLOOKUP(F$2,'Database Geral'!$B$1:$F$65,'Base de Dados P1'!$A20,FALSE)),"") -> 1.3647837 | H20: ='Database Geral'!G19 -> 6486205 | J20: 6) (0.50 pontos) Obtenha o intervalo de confiança para os estimadores α e β.
A21: 20 | B21: Estonia | C21: =IFERROR(IF(HLOOKUP(C$2,'Database Geral'!$B$1:$F$65,'Base de Dados P1'!$A21,FALSE)=0,,HLOOKUP(C$2,'Database Geral'!$B$1:$F$65,'Base de Dados P1'!$A21,FALSE)),"") -> 1.61964 | D21: =IFERROR(IF(HLOOKUP(D$2,'Database Geral'!$B$1:$F$65,'Base de Dados P1'!$A21,FALSE)=0,,HLOOKUP(D$2,'Database Geral'!$B$1:$F$65,'Base de Dados P1'!$A21,FALSE)),"") -> 22.944788 | E21: =IFERROR(IF(HLOOKUP(E$2,'Database Geral'!$B$1:$F$65,'Base de Dados P1'!$A21,FALSE)=0,,HLOOKUP(E$2,'Database Geral'!$B$1:$F$65,'Base de Dados P1'!$A21,FALSE)),"") -> 13.6818 | F21: =IFERROR(IF(HLOOKUP(F$2,'Database Geral'!$B$1:$F$65,'Base de Dados P1'!$A21,FALSE)=0,,HLOOKUP(F$2,'Database Geral'!$B$1:$F$65,'Base de Dados P1'!$A21,FALSE)),"") -> 2.4758739 | H21: ='Database Geral'!G20 -> 1326535 | J21: 7) (0.50 pontos) Faça e interprete o teste de contribuição marginal tirando a variável indicada. → | S21: =CONCATENATE("Tire a variável: ",VLOOKUP('Base de Dados P1'!J2,Cruzamento!$A$2:$E$31,5,FALSE)) -> Tire a variável: Taxa Crescimento (%)
A22: 21 | B22: Ethiopia | C22: =IFERROR(IF(HLOOKUP(C$2,'Database Geral'!$B$1:$F$65,'Base de Dados P1'!$A22,FALSE)=0,,HLOOKUP(C$2,'Database Geral'!$B$1:$F$65,'Base de Dados P1'!$A22,FALSE)),"") -> 0.24566001 | D22: =IFERROR(IF(HLOOKUP(D$2,'Database Geral'!$B$1:$F$65,'Base de Dados P1'!$A22,FALSE)=0,,HLOOKUP(D$2,'Database Geral'!$B$1:$F$65,'Base de Dados P1'!$A22,FALSE)),"") -> 85.004237 | E22: =IFERROR(IF(HLOOKUP(E$2,'Database Geral'!$B$1:$F$65,'Base de Dados P1'!$A22,FALSE)=0,,HLOOKUP(E$2,'Database Geral'!$B$1:$F$65,'Base de Dados P1'!$A22,FALSE)),"") -> 22.03582 | F22: =IFERROR(IF(HLOOKUP(F$2,'Database Geral'!$B$1:$F$65,'Base de Dados P1'!$A22,FALSE)=0,,HLOOKUP(F$2,'Database Geral'!$B$1:$F$65,'Base de Dados P1'!$A22,FALSE)),"") -> 12.550538 | H22: ='Database Geral'!G21 -> 114963588
A23: 22 | B23: Finland | C23: =IFERROR(IF(HLOOKUP(C$2,'Database Geral'!$B$1:$F$65,'Base de Dados P1'!$A23,FALSE)=0,,HLOOKUP(C$2,'Database Geral'!$B$1:$F$65,'Base de Dados P1'!$A23,FALSE)),"") -> 3.9006 | D23: =IFERROR(IF(HLOOKUP(D$2,'Database Geral'!$B$1:$F$65,'Base de Dados P1'!$A23,FALSE)=0,,HLOOKUP(D$2,'Database Geral'!$B$1:$F$65,'Base de Dados P1'!$A23,FALSE)),"") -> 24.874029 | E23: =IFERROR(IF(HLOOKUP(E$2,'Database Geral'!$B$1:$F$65,'Base de Dados P1'!$A23,FALSE)=0,,HLOOKUP(E$2,'Database Geral'!$B$1:$F$65,'Base de Dados P1'!$A23,FALSE)),"") -> 11.95611 | F23: =IFERROR(IF(HLOOKUP(F$2,'Database Geral'!$B$1:$F$65,'Base de Dados P1'!$A23,FALSE)=0,,HLOOKUP(F$2,'Database Geral'!$B$1:$F$65,'Base de Dados P1'!$A23,FALSE)),"") -> 2.9923553 | H23: ='Database Geral'!G22 -> 5540720 | J23: 8) (0.50 pontos) Realize uma anamorfose do modelo loriginal, transformando a única variável não percentual do seu modelo em logaritmo. Se o seu modelo não tiver variável não-percentual, faça o que for indicado abaixo:
A24: 23 | B24: France | C24: =IFERROR(IF(HLOOKUP(C$2,'Database Geral'!$B$1:$F$65,'Base de Dados P1'!$A24,FALSE)=0,,HLOOKUP(C$2,'Database Geral'!$B$1:$F$65,'Base de Dados P1'!$A24,FALSE)),"") -> 2.2444601 | D24: =IFERROR(IF(HLOOKUP(D$2,'Database Geral'!$B$1:$F$65,'Base de Dados P1'!$A24,FALSE)=0,,HLOOKUP(D$2,'Database Geral'!$B$1:$F$65,'Base de Dados P1'!$A24,FALSE)),"") -> 28.303837 | E24: =IFERROR(IF(HLOOKUP(E$2,'Database Geral'!$B$1:$F$65,'Base de Dados P1'!$A24,FALSE)=0,,HLOOKUP(E$2,'Database Geral'!$B$1:$F$65,'Base de Dados P1'!$A24,FALSE)),"") -> 10.06913 | F24: =IFERROR(IF(HLOOKUP(F$2,'Database Geral'!$B$1:$F$65,'Base de Dados P1'!$A24,FALSE)=0,,HLOOKUP(F$2,'Database Geral'!$B$1:$F$65,'Base de Dados P1'!$A24,FALSE)),"") -> 1.9656578 | H24: ='Database Geral'!G23 -> 65273511
A25: 24 | B25: Germany | C25: =IFERROR(IF(HLOOKUP(C$2,'Database Geral'!$B$1:$F$65,'Base de Dados P1'!$A25,FALSE)=0,,HLOOKUP(C$2,'Database Geral'!$B$1:$F$65,'Base de Dados P1'!$A25,FALSE)),"") -> 2.80352 | D25: =IFERROR(IF(HLOOKUP(D$2,'Database Geral'!$B$1:$F$65,'Base de Dados P1'!$A25,FALSE)=0,,HLOOKUP(D$2,'Database Geral'!$B$1:$F$65,'Base de Dados P1'!$A25,FALSE)),"") -> 20.386593 | E25: =IFERROR(IF(HLOOKUP(E$2,'Database Geral'!$B$1:$F$65,'Base de Dados P1'!$A25,FALSE)=0,,HLOOKUP(E$2,'Database Geral'!$B$1:$F$65,'Base de Dados P1'!$A25,FALSE)),"") -> 10.61658 | F25: =IFERROR(IF(HLOOKUP(F$2,'Database Geral'!$B$1:$F$65,'Base de Dados P1'!$A25,FALSE)=0,,HLOOKUP(F$2,'Database Geral'!$B$1:$F$65,'Base de Dados P1'!$A25,FALSE)),"") -> 4.0907695 | H25: ='Database Geral'!G24 -> 83783942 | J25: → Pegue a variável "Razão de Dependência de Jovens" e multiplique pelos valores que estão na coluna H (população)
A26: 25 | B26: Ghana | C26: =IFERROR(IF(HLOOKUP(C$2,'Database Geral'!$B$1:$F$65,'Base de Dados P1'!$A26,FALSE)=0,,HLOOKUP(C$2,'Database Geral'!$B$1:$F$65,'Base de Dados P1'!$A26,FALSE)),"") -> 0.37654999 | D26: =IFERROR(IF(HLOOKUP(D$2,'Database Geral'!$B$1:$F$65,'Base de Dados P1'!$A26,FALSE)=0,,HLOOKUP(D$2,'Database Geral'!$B$1:$F$65,'Base de Dados P1'!$A26,FALSE)),"") -> 67.75072 | E26: =IFERROR(IF(HLOOKUP(E$2,'Database Geral'!$B$1:$F$65,'Base de Dados P1'!$A26,FALSE)=0,,HLOOKUP(E$2,'Database Geral'!$B$1:$F$65,'Base de Dados P1'!$A26,FALSE)),"") -> 21.24422 | F26: =IFERROR(IF(HLOOKUP(F$2,'Database Geral'!$B$1:$F$65,'Base de Dados P1'!$A26,FALSE)=0,,HLOOKUP(F$2,'Database Geral'!$B$1:$F$65,'Base de Dados P1'!$A26,FALSE)),"") -> 7.8997403 | H26: ='Database Geral'!G25 -> 31072940 | J26: → Use estes resultados, que são a variável "Número de Jovens", no lugar da variável anterior
A27: 26 | B27: Guatemala | C27: =IFERROR(IF(HLOOKUP(C$2,'Database Geral'!$B$1:$F$65,'Base de Dados P1'!$A27,FALSE)=0,,HLOOKUP(C$2,'Database Geral'!$B$1:$F$65,'Base de Dados P1'!$A27,FALSE)),"") -> 0.043499999 | D27: =IFERROR(IF(HLOOKUP(D$2,'Database Geral'!$B$1:$F$65,'Base de Dados P1'!$A27,FALSE)=0,,HLOOKUP(D$2,'Database Geral'!$B$1:$F$65,'Base de Dados P1'!$A27,FALSE)),"") -> 76.8074 | E27: =IFERROR(IF(HLOOKUP(E$2,'Database Geral'!$B$1:$F$65,'Base de Dados P1'!$A27,FALSE)=0,,HLOOKUP(E$2,'Database Geral'!$B$1:$F$65,'Base de Dados P1'!$A27,FALSE)),"") -> 19.29692 | F27: =IFERROR(IF(HLOOKUP(F$2,'Database Geral'!$B$1:$F$65,'Base de Dados P1'!$A27,FALSE)=0,,HLOOKUP(F$2,'Database Geral'!$B$1:$F$65,'Base de Dados P1'!$A27,FALSE)),"") -> 2.8693724 | H27: ='Database Geral'!G26 -> 17915568 | J27: → Faça o seu modelo com anamorfose, realizando troca da forma funcional na variável "Número de Jovens"
A28: 27 | B28: Hong Kong | C28: =IFERROR(IF(HLOOKUP(C$2,'Database Geral'!$B$1:$F$65,'Base de Dados P1'!$A28,FALSE)=0,,HLOOKUP(C$2,'Database Geral'!$B$1:$F$65,'Base de Dados P1'!$A28,FALSE)),"") -> 0.74927002 | D28: =IFERROR(IF(HLOOKUP(D$2,'Database Geral'!$B$1:$F$65,'Base de Dados P1'!$A28,FALSE)=0,,HLOOKUP(D$2,'Database Geral'!$B$1:$F$65,'Base de Dados P1'!$A28,FALSE)),"") -> 16.200772 | E28: =IFERROR(IF(HLOOKUP(E$2,'Database Geral'!$B$1:$F$65,'Base de Dados P1'!$A28,FALSE)=0,,HLOOKUP(E$2,'Database Geral'!$B$1:$F$65,'Base de Dados P1'!$A28,FALSE)),"") -> 19.90955 | F28: =IFERROR(IF(HLOOKUP(F$2,'Database Geral'!$B$1:$F$65,'Base de Dados P1'!$A28,FALSE)=0,,HLOOKUP(F$2,'Database Geral'!$B$1:$F$65,'Base de Dados P1'!$A28,FALSE)),"") -> 6.7676106 | H28: ='Database Geral'!G27 -> 7496981 | J28: A coluna H foi replicada na outra aba!
A29: 28 | B29: Hungary | C29: =IFERROR(IF(HLOOKUP(C$2,'Database Geral'!$B$1:$F$65,'Base de Dados P1'!$A29,FALSE)=0,,HLOOKUP(C$2,'Database Geral'!$B$1:$F$65,'Base de Dados P1'!$A29,FALSE)),"") -> 1.17003 | D29: =IFERROR(IF(HLOOKUP(D$2,'Database Geral'!$B$1:$F$65,'Base de Dados P1'!$A29,FALSE)=0,,HLOOKUP(D$2,'Database Geral'!$B$1:$F$65,'Base de Dados P1'!$A29,FALSE)),"") -> 21.336267 | E29: =IFERROR(IF(HLOOKUP(E$2,'Database Geral'!$B$1:$F$65,'Base de Dados P1'!$A29,FALSE)=0,,HLOOKUP(E$2,'Database Geral'!$B$1:$F$65,'Base de Dados P1'!$A29,FALSE)),"") -> 9.68498 | F29: =IFERROR(IF(HLOOKUP(F$2,'Database Geral'!$B$1:$F$65,'Base de Dados P1'!$A29,FALSE)=0,,HLOOKUP(F$2,'Database Geral'!$B$1:$F$65,'Base de Dados P1'!$A29,FALSE)),"") -> 0.78911688 | H29: ='Database Geral'!G28 -> 9660351
A30: 29 | B30: India | C30: =IFERROR(IF(HLOOKUP(C$2,'Database Geral'!$B$1:$F$65,'Base de Dados P1'!$A30,FALSE)=0,,HLOOKUP(C$2,'Database Geral'!$B$1:$F$65,'Base de Dados P1'!$A30,FALSE)),"") -> 0.79718 | D30: =IFERROR(IF(HLOOKUP(D$2,'Database Geral'!$B$1:$F$65,'Base de Dados P1'!$A30,FALSE)=0,,HLOOKUP(D$2,'Database Geral'!$B$1:$F$65,'Base de Dados P1'!$A30,FALSE)),"") -> 46.591042 | E30: =IFERROR(IF(HLOOKUP(E$2,'Database Geral'!$B$1:$F$65,'Base de Dados P1'!$A30,FALSE)=0,,HLOOKUP(E$2,'Database Geral'!$B$1:$F$65,'Base de Dados P1'!$A30,FALSE)),"") -> 11.74278 | F30: =IFERROR(IF(HLOOKUP(F$2,'Database Geral'!$B$1:$F$65,'Base de Dados P1'!$A30,FALSE)=0,,HLOOKUP(F$2,'Database Geral'!$B$1:$F$65,'Base de Dados P1'!$A30,FALSE)),"") -> 10.259963 | H30: ='Database Geral'!G29 -> 1380004385
A31: 30 | B31: Ireland | C31: =IFERROR(IF(HLOOKUP(C$2,'Database Geral'!$B$1:$F$65,'Base de Dados P1'!$A31,FALSE)=0,,HLOOKUP(C$2,'Database Geral'!$B$1:$F$65,'Base de Dados P1'!$A31,FALSE)),"") -> 1.68853 | D31: =IFERROR(IF(HLOOKUP(D$2,'Database Geral'!$B$1:$F$65,'Base de Dados P1'!$A31,FALSE)=0,,HLOOKUP(D$2,'Database Geral'!$B$1:$F$65,'Base de Dados P1'!$A31,FALSE)),"") -> 31.700322 | E31: =IFERROR(IF(HLOOKUP(E$2,'Database Geral'!$B$1:$F$65,'Base de Dados P1'!$A31,FALSE)=0,,HLOOKUP(E$2,'Database Geral'!$B$1:$F$65,'Base de Dados P1'!$A31,FALSE)),"") -> 9.29551 | F31: =IFERROR(IF(HLOOKUP(F$2,'Database Geral'!$B$1:$F$65,'Base de Dados P1'!$A31,FALSE)=0,,HLOOKUP(F$2,'Database Geral'!$B$1:$F$65,'Base de Dados P1'!$A31,FALSE)),"") -> -0.27550501 | H31: ='Database Geral'!G30 -> 4937786
A32: 31 | B32: Israel | C32: =IFERROR(IF(HLOOKUP(C$2,'Database Geral'!$B$1:$F$65,'Base de Dados P1'!$A32,FALSE)=0,,HLOOKUP(C$2,'Database Geral'!$B$1:$F$65,'Base de Dados P1'!$A32,FALSE)),"") -> 3.9650099 | D32: =IFERROR(IF(HLOOKUP(D$2,'Database Geral'!$B$1:$F$65,'Base de Dados P1'!$A32,FALSE)=0,,HLOOKUP(D$2,'Database Geral'!$B$1:$F$65,'Base de Dados P1'!$A32,FALSE)),"") -> 43.702014 | E32: =IFERROR(IF(HLOOKUP(E$2,'Database Geral'!$B$1:$F$65,'Base de Dados P1'!$A32,FALSE)=0,,HLOOKUP(E$2,'Database Geral'!$B$1:$F$65,'Base de Dados P1'!$A32,FALSE)),"") -> 13.25932 | F32: =IFERROR(IF(HLOOKUP(F$2,'Database Geral'!$B$1:$F$65,'Base de Dados P1'!$A32,FALSE)=0,,HLOOKUP(F$2,'Database Geral'!$B$1:$F$65,'Base de Dados P1'!$A32,FALSE)),"") -> 5.7505322 | H32: ='Database Geral'!G31 -> 8655535
A33: 32 | B33: Italy | C33: =IFERROR(IF(HLOOKUP(C$2,'Database Geral'!$B$1:$F$65,'Base de Dados P1'!$A33,FALSE)=0,,HLOOKUP(C$2,'Database Geral'!$B$1:$F$65,'Base de Dados P1'!$A33,FALSE)),"") -> 1.26458 | D33: =IFERROR(IF(HLOOKUP(D$2,'Database Geral'!$B$1:$F$65,'Base de Dados P1'!$A33,FALSE)=0,,HLOOKUP(D$2,'Database Geral'!$B$1:$F$65,'Base de Dados P1'!$A33,FALSE)),"") -> 21.380459 | E33: =IFERROR(IF(HLOOKUP(E$2,'Database Geral'!$B$1:$F$65,'Base de Dados P1'!$A33,FALSE)=0,,HLOOKUP(E$2,'Database Geral'!$B$1:$F$65,'Base de Dados P1'!$A33,FALSE)),"") -> 8.72395 | F33: =IFERROR(IF(HLOOKUP(F$2,'Database Geral'!$B$1:$F$65,'Base de Dados P1'!$A33,FALSE)=0,,HLOOKUP(F$2,'Database Geral'!$B$1:$F$65,'Base de Dados P1'!$A33,FALSE)),"") -> 1.7105824 | H33: ='Database Geral'!G32 -> 60461826
A34: 33 | B34: Japan | C34: =IFERROR(IF(HLOOKUP(C$2,'Database Geral'!$B$1:$F$65,'Base de Dados P1'!$A34,FALSE)=0,,HLOOKUP(C$2,'Database Geral'!$B$1:$F$65,'Base de Dados P1'!$A34,FALSE)),"") -> 3.2539401 | D34: =IFERROR(IF(HLOOKUP(D$2,'Database Geral'!$B$1:$F$65,'Base de Dados P1'!$A34,FALSE)=0,,HLOOKUP(D$2,'Database Geral'!$B$1:$F$65,'Base de Dados P1'!$A34,FALSE)),"") -> 20.841027 | E34: =IFERROR(IF(HLOOKUP(E$2,'Database Geral'!$B$1:$F$65,'Base de Dados P1'!$A34,FALSE)=0,,HLOOKUP(E$2,'Database Geral'!$B$1:$F$65,'Base de Dados P1'!$A34,FALSE)),"") -> 9.45758 | F34: =IFERROR(IF(HLOOKUP(F$2,'Database Geral'!$B$1:$F$65,'Base de Dados P1'!$A34,FALSE)=0,,HLOOKUP(F$2,'Database Geral'!$B$1:$F$65,'Base de Dados P1'!$A34,FALSE)),"") -> 4.6520301 | H34: ='Database Geral'!G33 -> 126476461
A35: 34 | B35: Kenya | C35: =IFERROR(IF(HLOOKUP(C$2,'Database Geral'!$B$1:$F$65,'Base de Dados P1'!$A35,FALSE)=0,,HLOOKUP(C$2,'Database Geral'!$B$1:$F$65,'Base de Dados P1'!$A35,FALSE)),"") -> 0.97617 | D35: =IFERROR(IF(HLOOKUP(D$2,'Database Geral'!$B$1:$F$65,'Base de Dados P1'!$A35,FALSE)=0,,HLOOKUP(D$2,'Database Geral'!$B$1:$F$65,'Base de Dados P1'!$A35,FALSE)),"") -> 77.647766 | E35: =IFERROR(IF(HLOOKUP(E$2,'Database Geral'!$B$1:$F$65,'Base de Dados P1'!$A35,FALSE)=0,,HLOOKUP(E$2,'Database Geral'!$B$1:$F$65,'Base de Dados P1'!$A35,FALSE)),"") -> 20.55599 | F35: =IFERROR(IF(HLOOKUP(F$2,'Database Geral'!$B$1:$F$65,'Base de Dados P1'!$A35,FALSE)=0,,HLOOKUP(F$2,'Database Geral'!$B$1:$F$65,'Base de Dados P1'!$A35,FALSE)),"") -> 8.4022771 | H35: ='Database Geral'!G34 -> 53771296
A36: 35 | B36: Kyrgyz Republic | C36: =IFERROR(IF(HLOOKUP(C$2,'Database Geral'!$B$1:$F$65,'Base de Dados P1'!$A36,FALSE)=0,,HLOOKUP(C$2,'Database Geral'!$B$1:$F$65,'Base de Dados P1'!$A36,FALSE)),"") -> 0.15547 | D36: =IFERROR(IF(HLOOKUP(D$2,'Database Geral'!$B$1:$F$65,'Base de Dados P1'!$A36,FALSE)=0,,HLOOKUP(D$2,'Database Geral'!$B$1:$F$65,'Base de Dados P1'!$A36,FALSE)),"") -> 45.85531 | E36: =IFERROR(IF(HLOOKUP(E$2,'Database Geral'!$B$1:$F$65,'Base de Dados P1'!$A36,FALSE)=0,,HLOOKUP(E$2,'Database Geral'!$B$1:$F$65,'Base de Dados P1'!$A36,FALSE)),"") -> 15.68476 | F36: =IFERROR(IF(HLOOKUP(F$2,'Database Geral'!$B$1:$F$65,'Base de Dados P1'!$A36,FALSE)=0,,HLOOKUP(F$2,'Database Geral'!$B$1:$F$65,'Base de Dados P1'!$A36,FALSE)),"") -> -0.47156685 | H36: ='Database Geral'!G35 -> 6524195
A37: 36 | B37: Latvia | C37: =IFERROR(IF(HLOOKUP(C$2,'Database Geral'!$B$1:$F$65,'Base de Dados P1'!$A37,FALSE)=0,,HLOOKUP(C$2,'Database Geral'!$B$1:$F$65,'Base de Dados P1'!$A37,FALSE)),"") -> 0.60459 | D37: =IFERROR(IF(HLOOKUP(D$2,'Database Geral'!$B$1:$F$65,'Base de Dados P1'!$A37,FALSE)=0,,HLOOKUP(D$2,'Database Geral'!$B$1:$F$65,'Base de Dados P1'!$A37,FALSE)),"") -> 20.978531 | E37: =IFERROR(IF(HLOOKUP(E$2,'Database Geral'!$B$1:$F$65,'Base de Dados P1'!$A37,FALSE)=0,,HLOOKUP(E$2,'Database Geral'!$B$1:$F$65,'Base de Dados P1'!$A37,FALSE)),"") -> 8.12264 | F37: =IFERROR(IF(HLOOKUP(F$2,'Database Geral'!$B$1:$F$65,'Base de Dados P1'!$A37,FALSE)=0,,HLOOKUP(F$2,'Database Geral'!$B$1:$F$65,'Base de Dados P1'!$A37,FALSE)),"") -> -2.8736097 | H37: ='Database Geral'!G36 -> 1886198
A38: 37 | B38: Macao | C38: =IFERROR(IF(HLOOKUP(C$2,'Database Geral'!$B$1:$F$65,'Base de Dados P1'!$A38,FALSE)=0,,HLOOKUP(C$2,'Database Geral'!$B$1:$F$65,'Base de Dados P1'!$A38,FALSE)),"") -> 0.051720001 | D38: =IFERROR(IF(HLOOKUP(D$2,'Database Geral'!$B$1:$F$65,'Base de Dados P1'!$A38,FALSE)=0,,HLOOKUP(D$2,'Database Geral'!$B$1:$F$65,'Base de Dados P1'!$A38,FALSE)),"") -> 15.888047 | E38: =IFERROR(IF(HLOOKUP(E$2,'Database Geral'!$B$1:$F$65,'Base de Dados P1'!$A38,FALSE)=0,,HLOOKUP(E$2,'Database Geral'!$B$1:$F$65,'Base de Dados P1'!$A38,FALSE)),"") -> 15.67268 | F38: =IFERROR(IF(HLOOKUP(F$2,'Database Geral'!$B$1:$F$65,'Base de Dados P1'!$A38,FALSE)=0,,HLOOKUP(F$2,'Database Geral'!$B$1:$F$65,'Base de Dados P1'!$A38,FALSE)),"") -> 27.498964 | H38: ='Database Geral'!G37 -> 649335
A39: 38 | B39: Malaysia | C39: =IFERROR(IF(HLOOKUP(C$2,'Database Geral'!$B$1:$F$65,'Base de Dados P1'!$A39,FALSE)=0,,HLOOKUP(C$2,'Database Geral'!$B$1:$F$65,'Base de Dados P1'!$A39,FALSE)),"") -> 1.0674 | D39: =IFERROR(IF(HLOOKUP(D$2,'Database Geral'!$B$1:$F$65,'Base de Dados P1'!$A39,FALSE)=0,,HLOOKUP(D$2,'Database Geral'!$B$1:$F$65,'Base de Dados P1'!$A39,FALSE)),"") -> 41.026654 | E39: =IFERROR(IF(HLOOKUP(E$2,'Database Geral'!$B$1:$F$65,'Base de Dados P1'!$A39,FALSE)=0,,HLOOKUP(E$2,'Database Geral'!$B$1:$F$65,'Base de Dados P1'!$A39,FALSE)),"") -> 18.40623 | F39: =IFERROR(IF(HLOOKUP(F$2,'Database Geral'!$B$1:$F$65,'Base de Dados P1'!$A39,FALSE)=0,,HLOOKUP(F$2,'Database Geral'!$B$1:$F$65,'Base de Dados P1'!$A39,FALSE)),"") -> 7.4259705 | H39: ='Database Geral'!G38 -> 32365999
A40: 39 | B40: Mali | C40: =IFERROR(IF(HLOOKUP(C$2,'Database Geral'!$B$1:$F$65,'Base de Dados P1'!$A40,FALSE)=0,,HLOOKUP(C$2,'Database Geral'!$B$1:$F$65,'Base de Dados P1'!$A40,FALSE)),"") -> 0.66141999 | D40: =IFERROR(IF(HLOOKUP(D$2,'Database Geral'!$B$1:$F$65,'Base de Dados P1'!$A40,FALSE)=0,,HLOOKUP(D$2,'Database Geral'!$B$1:$F$65,'Base de Dados P1'!$A40,FALSE)),"") -> 93.034395 | E40: =IFERROR(IF(HLOOKUP(E$2,'Database Geral'!$B$1:$F$65,'Base de Dados P1'!$A40,FALSE)=0,,HLOOKUP(E$2,'Database Geral'!$B$1:$F$65,'Base de Dados P1'!$A40,FALSE)),"") -> 16.50391 | F40: =IFERROR(IF(HLOOKUP(F$2,'Database Geral'!$B$1:$F$65,'Base de Dados P1'!$A40,FALSE)=0,,HLOOKUP(F$2,'Database Geral'!$B$1:$F$65,'Base de Dados P1'!$A40,FALSE)),"") -> 5.8193148 | H40: ='Database Geral'!G39 -> 20250833
...

Sheet Folha de Respostas
A1: País | B1: Variável Y | D1: Variável X1 | E1: Variável X2 | F1: Variável X3 | G1: Variável X4 | J1: ='Base de Dados P1'!H1 -> População (só use essa variável no item 8, SE ESTE FOR O SEU CASO)
B2: ='Base de Dados P1'!C2 -> Gastos P&D (%) | D2: ='Base de Dados P1'!D2 -> Razão de Dependência de Jovens (%) | E2: ='Base de Dados P1'!E2 -> Gastos com educação (%) | F2: ='Base de Dados P1'!F2 -> Taxa Crescimento (%) | G2: Taxa de crescimento por população | H2: y^ | I2: ê | L2: Inversão da matriz X para obter a MATRIZ XT
A3: Argentina | B3: ='Base de Dados P1'!C3 -> 0.61745 | C3: 1 | D3: ='Base de Dados P1'!D3 -> 38.566712 | E3: ='Base de Dados P1'!E3 -> 15.57046 | F3: ='Base de Dados P1'!F3 -> 9.4515783 | G3: =F3*J3/100 -> 4271714 | H3: =$M$15+SUMPRODUCT(D3:F3,$N$40:$P$40) -> 1.0163245 | I3: =B3-H3 -> -0.39887448 | J3: ='Base de Dados P1'!H3 -> 45195774 | L3: 1 | M3: 1 | N3: 1 | O3: 1 | P3: 1 | Q3: 1 | R3: 1 | S3: 1 | T3: 1 | U3: 1 | V3: 1 | W3: 1 | X3: 1 | Y3: 1 | Z3: 1 | AA3: 1 | AB3: 1 | AC3: 1 | AD3: 1 | AE3: 1 | AF3: 1 | AG3: 1 | AH3: 1 | AI3: 1 | AJ3: 1 | AK3: 1 | AL3: 1 | AM3: 1 | AN3: 1 | AO3: 1 | AP3: 1 | AQ3: 1 | AR3: 1 | AS3: 1 | AT3: 1 | AU3: 1 | AV3: 1 | AW3: 1 | AX3: 1 | AY3: 1 | AZ3: 1 | BA3: 1 | BB3: 1 | BC3: 1 | BD3: 1 | BE3: 1 | BF3: 1 | BG3: 1 | BH3: 1 | BI3: 1 | BJ3: 1 | BK3: 1 | BL3: 1 | BM3: 1 | BN3: 1 | BO3: 1 | BP3: 1 | BQ3: 1 | BR3: 1 | BS3: 1 | BT3: 1 | BU3: 1 | BV3: 1 | BW3: 1
A4: Armenia | B4: ='Base de Dados P1'!C4 -> 0.24139 | C4: 1 | D4: ='Base de Dados P1'!D4 -> 29.758869 | E4: ='Base de Dados P1'!E4 -> 12.40051 | F4: ='Base de Dados P1'!F4 -> 2.2 | G4: =F4*J4/100 -> 65191.346 | H4: =$M$15+SUMPRODUCT(D4:F4,$N$40:$P$40) -> 1.3716336 | I4: =B4-H4 -> -1.1302436 | J4: ='Base de Dados P1'!H4 -> 2963243 | L4: 38.566712 | M4: 29.758869 | N4: 28.019033 | O4: 21.881818 | P4: 31.79129 | Q4: 20.852179 | R4: 25.395926 | S4: 37.709678 | T4: 19.485786 | U4: 82.053945 | V4: 23.744055 | W4: 32.237808 | X4: 43.827462 | Y4: 22.775894 | Z4: 25.145563 | AA4: 20.151364 | AB4: 27.475773 | AC4: 52.564166 | AD4: 22.944788 | AE4: 85.004237 | AF4: 24.874029 | AG4: 28.303837 | AH4: 20.386593 | AI4: 67.75072 | AJ4: 76.8074 | AK4: 16.200772 | AL4: 21.336267 | AM4: 46.591042 | AN4: 31.700322 | AO4: 43.702014 | AP4: 21.380459 | AQ4: 20.841027 | AR4: 77.647766 | AS4: 45.85531 | AT4: 20.978531 | AU4: 15.888047 | AV4: 41.026654 | AW4: 93.034395 | AX4: 22.355622 | AY4: 46.964943 | AZ4: 23.09797 | BA4: 38.931399 | BB4: 64.003761 | BC4: 64.012022 | BD4: 26.101343 | BE4: 28.409666 | BF4: 21.002492 | BG4: 22.665676 | BH4: 21.402773 | BI4: 81.910321 | BJ4: 24.311684 | BK4: 23.548008 | BL4: 20.846008 | BM4: 20.21325 | BN4: 45.665131 | BO4: 21.961482 | BP4: 37.433781 | BQ4: 25.283075 | BR4: 59.08497 | BS4: 86.154026 | BT4: 76.2288 | BU4: 100.3384 | BV4: 26.666562 | BW4: 29.568269
A5: Australia | B5: ='Base de Dados P1'!C5 -> 2.3856201 | C5: 1 | D5: ='Base de Dados P1'!D5 -> 28.019033 | E5: ='Base de Dados P1'!E5 -> 14.3276 | F5: ='Base de Dados P1'!F5 -> 1.9623661 | G5: =F5*J5/100 -> 500401.08 | H5: =$M$15+SUMPRODUCT(D5:F5,$N$40:$P$40) -> 1.319345 | I5: =B5-H5 -> 1.0662751 | J5: ='Base de Dados P1'!H5 -> 25499884 | L5: 15.57046 | M5: 12.40051 | N5: 14.3276 | O5: 10.85817 | P5: 8.77911 | Q5: 12.86463 | R5: 12.22374 | S5: 14.55989 | T5: 11.16342 | U5: 16.5881 | V5: 12.38789 | W5: 17.51402 | X5: 16.41858 | Y5: 9.08259 | Z5: 15.68234 | AA5: 9.7125 | AB5: 15.10334 | AC5: 16.16422 | AD5: 13.6818 | AE5: 22.03582 | AF5: 11.95611 | AG5: 10.06913 | AH5: 10.61658 | AI5: 21.24422 | AJ5: 19.29692 | AK5: 19.90955 | AL5: 9.68498 | AM5: 11.74278 | AN5: 9.29551 | AO5: 13.25932 | AP5: 8.72395 | AQ5: 9.45758 | AR5: 20.55599 | AS5: 15.68476 | AT5: 8.12264 | AU5: 15.67268 | AV5: 18.40623 | AW5: 16.50391 | AX5: 15.73082 | AY5: 19.31998 | AZ5: 22.3361 | BA5: 14.71114 | BB5: 26.19325 | BC5: 20.81352 | BD5: 11.52436 | BE5: 15.30602 | BF5: 11.10892 | BG5: 10.42656 | BH5: 9.12913 | BI5: 20.72318 | BJ5: 10.51355 | BK5: 16.55659 | BL5: 9.85753 | BM5: 12.08019 | BN5: 18.04437 | BO5: 10.56398 | BP5: 8.60566 | BQ5: 13.34554 | BR5: 15.33145 | BS5: 19.64801 | BT5: 19.61576 | BU5: 13.51757 | BV5: 12.96037 | BW5: 13.03757
A6: Austria | B6: ='Base de Dados P1'!C6 -> 2.79846 | C6: 1 | D6: ='Base de Dados P1'!D6 -> 21.881818 | E6: ='Base de Dados P1'!E6 -> 10.85817 | F6: ='Base de Dados P1'!F6 -> 1.8801177 | G6: =F6*J6/100 -> 169330.88 | H6: =$M$15+SUMPRODUCT(D6:F6,$N$40:$P$40) -> 1.5441921 | I6: =B6-H6 -> 1.2542679 | J6: ='Base de Dados P1'!H6 -> 9006398 | L6: 9.4515783 | M6: 2.2 | N6: 1.9623661 | O6: 1.8801177 | P6: 4.8543393 | Q6: 7.7407812 | R6: 2.5010546 | S6: 7.5720672 | T6: 0.65532511 | U6: 3.7859025 | V6: 3.3742486 | W6: 5.7537089 | X6: 3.9718007 | Y6: -1.7011369 | Z6: 1.3906441 | AA6: 2.2950891 | AB6: 1.6251359 | AC6: 1.3647837 | AD6: 2.4758739 | AE6: 12.550538 | AF6: 2.9923553 | AG6: 1.9656578 | AH6: 4.0907695 | AI6: 7.8997403 | AJ6: 2.8693724 | AK6: 6.7676106 | AL6: 0.78911688 | AM6: 10.259963 | AN6: -0.27550501 | AO6: 5.7505322 | AP6: 1.7105824 | AQ6: 4.6520301 | AR6: 8.4022771 | AS6: -0.47156685 | AT6: -2.8736097 | AU6: 27.498964 | AV6: 7.4259705 | AW6: 5.8193148 | AX6: 4.3 | AY6: 5.1101987 | AZ6: 7.0940718 | BA6: 6.3651617 | BB6: 5.9637802 | BC6: 4.8164147 | BD6: 1.0705038 | BE6: 0.60193444 | BF6: 3.7098104 | BG6: 1.898675 | BH6: -0.93965598 | BI6: 4.2662476 | BJ6: 0.58447809 | BK6: 15.240377 | BL6: 4.827314 | BM6: 1.2218192 | BN6: 3.0397471 | BO6: 0.013804783 | BP6: 8.0159594 | BQ6: 5.9889271 | BR6: 6.5 | BS6: 6.3588861 | BT6: 3.9956788 | BU6: 5.170343 | BV6: 1.9113777 | BW6: 2.5319204
A7: Azerbaijan | B7: ='Base de Dados P1'!C7 -> 0.21848001 | C7: 1 | D7: ='Base de Dados P1'!D7 -> 31.79129 | E7: ='Base de Dados P1'!E7 -> 8.77911 | F7: ='Base de Dados P1'!F7 -> 4.8543393 | G7: =F7*J7/100 -> 492190.06 | H7: =$M$15+SUMPRODUCT(D7:F7,$N$40:$P$40) -> 1.4532866 | I7: =B7-H7 -> -1.2348066 | J7: ='Base de Dados P1'!H7 -> 10139177
A8: Belarus | B8: ='Base de Dados P1'!C8 -> 0.69349998 | C8: 1 | D8: ='Base de Dados P1'!D8 -> 20.852179 | E8: ='Base de Dados P1'!E8 -> 12.86463 | F8: ='Base de Dados P1'!F8 -> 7.7407812 | G8: =F8*J8/100 -> 731451.42 | H8: =$M$15+SUMPRODUCT(D8:F8,$N$40:$P$40) -> 1.3879766 | I8: =B8-H8 -> -0.69447663 | J8: ='Base de Dados P1'!H8 -> 9449323 | L8: Multiplicação das matrizes e obter a MATRIZ XTX | Q8: Inversão da matriz XTX | V8: Multiplicação da matriz XT pela matriz y
A9: Belgium | B9: ='Base de Dados P1'!C9 -> 2.10478 | C9: 1 | D9: ='Base de Dados P1'!D9 -> 25.395926 | E9: ='Base de Dados P1'!E9 -> 12.22374 | F9: ='Base de Dados P1'!F9 -> 2.5010546 | G9: =F9*J9/100 -> 289862.8 | H9: =$M$15+SUMPRODUCT(D9:F9,$N$40:$P$40) -> 1.4323003 | I9: =B9-H9 -> 0.67247965 | J9: ='Base de Dados P1'!H9 -> 11589623 | L9: {=MMULT(L3:BW6,C3:F66)} -> 64 | M9: 2463.853 | N9: 918.32269 | O9: 280.63557 | Q9: {=MINVERSE(L9:O12)} -> 0.20931999 | R9: 0.0004556747 | S9: -0.015236088 | T9: 0.0016835006 | V9: {=MMULT(L3:BW6,B3:B66)} -> 73.15822
A10: Brazil | B10: ='Base de Dados P1'!C10 -> 1.1604199 | C10: 1 | D10: ='Base de Dados P1'!D10 -> 37.709678 | E10: ='Base de Dados P1'!E10 -> 14.55989 | F10: ='Base de Dados P1'!F10 -> 7.5720672 | G10: =F10*J10/100 -> 16095142 | H10: =$M$15+SUMPRODUCT(D10:F10,$N$40:$P$40) -> 1.097225 | I10: =B10-H10 -> 0.063194937 | J10: ='Base de Dados P1'!H10 -> 212559417 | L10: 2463.853 | M10: 126329.31 | N10: 38947.312 | O10: 11942.918 | Q10: 0.0004556747 | R10: 5.0994872e-05 | S10: -0.00017392975 | T10: 1.7519496e-05 | V10: 2234.2123
A11: Bulgaria | B11: ='Base de Dados P1'!C11 -> 0.59794003 | C11: 1 | D11: ='Base de Dados P1'!D11 -> 19.485786 | E11: ='Base de Dados P1'!E11 -> 11.16342 | F11: ='Base de Dados P1'!F11 -> 0.65532511 | G11: =F11*J11/100 -> 45534.905 | H11: =$M$15+SUMPRODUCT(D11:F11,$N$40:$P$40) -> 1.5818268 | I11: =B11-H11 -> -0.98388678 | J11: ='Base de Dados P1'!H11 -> 6948445 | L11: 918.32269 | M11: 38947.312 | N11: 14276.771 | O11: 4485.6167 | Q11: -0.015236088 | R11: -0.00017392975 | S11: 0.0016683654 | T11: -0.00045771414 | V11: 950.08638
A12: Burundi | B12: ='Base de Dados P1'!C12 -> 0.13755 | C12: 1 | D12: ='Base de Dados P1'!D12 -> 82.053945 | E12: ='Base de Dados P1'!E12 -> 16.5881 | F12: ='Base de Dados P1'!F12 -> 3.7859025 | G12: =F12*J12/100 -> 450173.49 | H12: =$M$15+SUMPRODUCT(D12:F12,$N$40:$P$40) -> 0.48200009 | I12: =B12-H12 -> -0.3444501 | J12: ='Base de Dados P1'!H12 -> 11890784 | L12: 280.63557 | M12: 11942.918 | N12: 4485.6167 | O12: 2470.1681 | Q12: 0.0016835006 | R12: 1.7519496e-05 | S12: -0.00045771414 | T12: 0.00096003432 | V12: 268.32511
A13: Canada | B13: ='Base de Dados P1'!C13 -> 1.86008 | C13: 1 | D13: ='Base de Dados P1'!D13 -> 23.744055 | E13: ='Base de Dados P1'!E13 -> 12.38789 | F13: ='Base de Dados P1'!F13 -> 3.3742486 | G13: =F13*J13/100 -> 1273514.1 | H13: =$M$15+SUMPRODUCT(D13:F13,$N$40:$P$40) -> 1.4344436 | I13: =B13-H13 -> 0.42563645 | J13: ='Base de Dados P1'!H13 -> 37742154
A14: Chile | B14: ='Base de Dados P1'!C14 -> 0.41722 | C14: 1 | D14: ='Base de Dados P1'!D14 -> 32.237808 | E14: ='Base de Dados P1'!E14 -> 17.51402 | F14: ='Base de Dados P1'!F14 -> 5.7537089 | G14: =F14*J14/100 -> 1099890.6 | H14: =$M$15+SUMPRODUCT(D14:F14,$N$40:$P$40) -> 1.0760669 | I14: =B14-H14 -> -0.65884692 | J14: ='Base de Dados P1'!H14 -> 19116201 | L14: Cálculo dos coeficientes
A15: Colombia | B15: ='Base de Dados P1'!C15 -> 0.18054 | C15: 1 | D15: ='Base de Dados P1'!D15 -> 43.827462 | E15: ='Base de Dados P1'!E15 -> 16.41858 | F15: ='Base de Dados P1'!F15 -> 3.9718007 | G15: =F15*J15/100 -> 2020967 | H15: =$M$15+SUMPRODUCT(D15:F15,$N$40:$P$40) -> 0.99372106 | I15: =B15-H15 -> -0.81318106 | J15: ='Base de Dados P1'!H15 -> 50882891 | L15: α | M15: {=MMULT(Q9:T12,V9:V12)} -> 2.307678 | O15: Análise dos coeficientes
A16: Croatia | B16: ='Base de Dados P1'!C16 -> 0.75443 | C16: 1 | D16: ='Base de Dados P1'!D16 -> 22.775894 | E16: ='Base de Dados P1'!E16 -> 9.08259 | F16: ='Base de Dados P1'!F16 -> -1.7011369 | G16: =F16*J16/100 -> -69836.211 | H16: =$M$15+SUMPRODUCT(D16:F16,$N$40:$P$40) -> 1.6586437 | I16: =B16-H16 -> -0.90421366 | J16: ='Base de Dados P1'!H16 -> 4105267 | L16: β1 | M16: -0.013277651 | O16: A cada aumento de 1 p.p da razão de dependencia dos jovens, há redução de 1,3% em gastos com P&D.
A17: Cyprus | B17: ='Base de Dados P1'!C17 -> 0.49355 | C17: 1 | D17: ='Base de Dados P1'!D17 -> 25.145563 | E17: ='Base de Dados P1'!E17 -> 15.68234 | F17: ='Base de Dados P1'!F17 -> 1.3906441 | G17: =F17*J17/100 -> 16790.066 | H17: =$M$15+SUMPRODUCT(D17:F17,$N$40:$P$40) -> 1.3105541 | I17: =B17-H17 -> -0.8170041 | J17: ='Base de Dados P1'!H17 -> 1207359 | L17: β2 | M17: -0.040965978 | O17: A cada aumento de 1 p.p em gastos com eduação, há redução de 4,1% em gastos com P&D.
A18: Czech Republic | B18: ='Base de Dados P1'!C18 -> 1.3974 | C18: 1 | D18: ='Base de Dados P1'!D18 -> 20.151364 | E18: ='Base de Dados P1'!E18 -> 9.7125 | F18: ='Base de Dados P1'!F18 -> 2.2950891 | G18: =F18*J18/100 -> 245780.66 | H18: =$M$15+SUMPRODUCT(D18:F18,$N$40:$P$40) -> 1.6078929 | I18: =B18-H18 -> -0.21049291 | J18: ='Base de Dados P1'!H18 -> 10708981 | L18: β3 | M18: -0.014962479 | O18: A cada aumento de 1 p.p da taxa de crescimento, há redução de 1,5% em gastos com P&D.
A19: Denmark | B19: ='Base de Dados P1'!C19 -> 3.00138 | C19: 1 | D19: ='Base de Dados P1'!D19 -> 27.475773 | E19: ='Base de Dados P1'!E19 -> 15.10334 | F19: ='Base de Dados P1'!F19 -> 1.6251359 | G19: =F19*J19/100 -> 94131.153 | H19: =$M$15+SUMPRODUCT(D19:F19,$N$40:$P$40) -> 1.2998251 | I19: =B19-H19 -> 1.7015549 | J19: ='Base de Dados P1'!H19 -> 5792202
A20: El Salvador | B20: ='Base de Dados P1'!C20 -> 0.067230001 | C20: 1 | D20: ='Base de Dados P1'!D20 -> 52.564166 | E20: ='Base de Dados P1'!E20 -> 16.16422 | F20: ='Base de Dados P1'!F20 -> 1.3647837 | G20: =F20*J20/100 -> 88522.666 | H20: =$M$15+SUMPRODUCT(D20:F20,$N$40:$P$40) -> 0.9271457 | I20: =B20-H20 -> -0.8599157 | J20: ='Base de Dados P1'!H20 -> 6486205 | L20: yTy | M20: βTXTy | O20: n | P20: Ybarra | R20: Gastos com P&D = alfa + b1 (Dependencia de jovens) + b2 (Gastos com educação) + b3 (Taxa de crescimento)
A21: Estonia | B21: ='Base de Dados P1'!C21 -> 1.61964 | C21: 1 | D21: ='Base de Dados P1'!D21 -> 22.944788 | E21: ='Base de Dados P1'!E21 -> 13.6818 | F21: ='Base de Dados P1'!F21 -> 2.4758739 | G21: =F21*J21/100 -> 32843.333 | H21: =$M$15+SUMPRODUCT(D21:F21,$N$40:$P$40) -> 1.4054916 | I21: =B21-H21 -> 0.21414842 | J21: ='Base de Dados P1'!H21 -> 1326535 | L21: {=MMULT(TRANSPOSE(B3:B66),B3:B66)} -> 149.21456 | M21: {=MMULT(TRANSPOSE(M15:M18),MMULT(L3:BW6,B3:B66))} -> 96.224496 | O21: =COUNT(B3:B66) -> 64 | P21: =AVERAGE(B3:B66) -> 1.1430972
A22: Ethiopia | B22: ='Base de Dados P1'!C22 -> 0.24566001 | C22: 1 | D22: ='Base de Dados P1'!D22 -> 85.004237 | E22: ='Base de Dados P1'!E22 -> 22.03582 | F22: ='Base de Dados P1'!F22 -> 12.550538 | G22: =F22*J22/100 -> 14428549 | H22: =$M$15+SUMPRODUCT(D22:F22,$N$40:$P$40) -> 0.088515284 | I22: =B22-H22 -> 0.15714472 | J22: ='Base de Dados P1'!H22 -> 114963588
A23: Finland | B23: ='Base de Dados P1'!C23 -> 3.9006 | C23: 1 | D23: ='Base de Dados P1'!D23 -> 24.874029 | E23: ='Base de Dados P1'!E23 -> 11.95611 | F23: ='Base de Dados P1'!F23 -> 2.9923553 | G23: =F23*J23/100 -> 165798.03 | H23: =$M$15+SUMPRODUCT(D23:F23,$N$40:$P$40) -> 1.4428425 | I23: =B23-H23 -> 2.4577574 | J23: ='Base de Dados P1'!H23 -> 5540720 | L23: STQ | M23: =L21-$O$21*$P$21^2 -> 65.587606 | O23: TABELA ANOVA
A24: France | B24: ='Base de Dados P1'!C24 -> 2.2444601 | C24: 1 | D24: ='Base de Dados P1'!D24 -> 28.303837 | E24: ='Base de Dados P1'!E24 -> 10.06913 | F24: ='Base de Dados P1'!F24 -> 1.9656578 | G24: =F24*J24/100 -> 1283053.9 | H24: =$M$15+SUMPRODUCT(D24:F24,$N$40:$P$40) -> 1.4899666 | I24: =B24-H24 -> 0.75449347 | J24: ='Base de Dados P1'!H24 -> 65273511 | L24: SQReg | M24: =M21-$O$21*$P$21^2 -> 12.59754 | O24: Fonte | P24: GL | Q24: SQ | R24: QM | S24: F(calc) | T24: F (crit)
A25: Germany | B25: ='Base de Dados P1'!C25 -> 2.80352 | C25: 1 | D25: ='Base de Dados P1'!D25 -> 20.386593 | E25: ='Base de Dados P1'!E25 -> 10.61658 | F25: ='Base de Dados P1'!F25 -> 4.0907695 | G25: =F25*J25/100 -> 3427408 | H25: =$M$15+SUMPRODUCT(D25:F25,$N$40:$P$40) -> 1.5408653 | I25: =B25-H25 -> 1.2626547 | J25: ='Base de Dados P1'!H25 -> 83783942 | L25: SQRes | M25: =L21-M21 -> 52.990066 | O25: Regressão | P25: 3 | Q25: =M24 -> 12.59754 | R25: =Q25/P25 -> 4.19918 | S25: =R25/R26 -> 4.7546799 | T25: =FINV(5%,P25,P26) -> 2.7580783 | V25: Rejeição da hipótese nula (H0), pois F(calc) é maior que F(crit). O que configura que pelo menos um dos coeficientes beta é diferente de 0, portanto, são estatisticamente significativos.
A26: Ghana | B26: ='Base de Dados P1'!C26 -> 0.37654999 | C26: 1 | D26: ='Base de Dados P1'!D26 -> 67.75072 | E26: ='Base de Dados P1'!E26 -> 21.24422 | F26: ='Base de Dados P1'!F26 -> 7.8997403 | G26: =F26*J26/100 -> 2454681.6 | H26: =$M$15+SUMPRODUCT(D26:F26,$N$40:$P$40) -> 0.41961761 | I26: =B26-H26 -> -0.043067621 | J26: ='Base de Dados P1'!H26 -> 31072940 | L26: Resultado | M26: =M24+M25=M23 -> TRUE | O26: Resíduos | P26: =O21-(P25+1) -> 60 | Q26: =M25 -> 52.990066 | R26: =Q26/P26 -> 0.88316777
A27: Guatemala | B27: ='Base de Dados P1'!C27 -> 0.043499999 | C27: 1 | D27: ='Base de Dados P1'!D27 -> 76.8074 | E27: ='Base de Dados P1'!E27 -> 19.29692 | F27: ='Base de Dados P1'!F27 -> 2.8693724 | G27: =F27*J27/100 -> 514064.36 | H27: =$M$15+SUMPRODUCT(D27:F27,$N$40:$P$40) -> 0.45440599 | I27: =B27-H27 -> -0.41090599 | J27: ='Base de Dados P1'!H27 -> 17915568 | L27: R² | M27: =M24/M23 -> 0.19207196 | O27: Total | P27: =O21-1 -> 63 | Q27: =M23 -> 65.587606 | R27: =Q27/P27 -> 1.0410731
A28: Hong Kong | B28: ='Base de Dados P1'!C28 -> 0.74927002 | C28: 1 | D28: ='Base de Dados P1'!D28 -> 16.200772 | E28: ='Base de Dados P1'!E28 -> 19.90955 | F28: ='Base de Dados P1'!F28 -> 6.7676106 | G28: =F28*J28/100 -> 507366.48 | H28: =$M$15+SUMPRODUCT(D28:F28,$N$40:$P$40) -> 1.1756954 | I28: =B28-H28 -> -0.42642534 | J28: ='Base de Dados P1'!H28 -> 7496981 | L28: R² ajustado | M28: =1-(R26/R27) -> 0.15167556 | O28: O objetivo do R² ajustado é ponderar o resultado obtido pelo R². Por se tratar de um modelo de regressão multipla, é recomendado considerarmos este indicador. Ou seja, 15% da variabilidade do Y é explicado pelos X's do modelo.
A29: Hungary | B29: ='Base de Dados P1'!C29 -> 1.17003 | C29: 1 | D29: ='Base de Dados P1'!D29 -> 21.336267 | E29: ='Base de Dados P1'!E29 -> 9.68498 | F29: ='Base de Dados P1'!F29 -> 0.78911688 | G29: =F29*J29/100 -> 76231.46 | H29: =$M$15+SUMPRODUCT(D29:F29,$N$40:$P$40) -> 1.6158207 | I29: =B29-H29 -> -0.44579067 | J29: ='Base de Dados P1'!H29 -> 9660351
A30: India | B30: ='Base de Dados P1'!C30 -> 0.79718 | C30: 1 | D30: ='Base de Dados P1'!D30 -> 46.591042 | E30: ='Base de Dados P1'!E30 -> 11.74278 | F30: ='Base de Dados P1'!F30 -> 10.259963 | G30: =F30*J30/100 -> 1.4158794e+08 | H30: =$M$15+SUMPRODUCT(D30:F30,$N$40:$P$40) -> 1.0544894 | I30: =B30-H30 -> -0.25730944 | J30: ='Base de Dados P1'!H30 -> 1380004385 | L30: sigma^² | M30: =(M23-M24)/P26 -> 0.88316777
A31: Ireland | B31: ='Base de Dados P1'!C31 -> 1.68853 | C31: 1 | D31: ='Base de Dados P1'!D31 -> 31.700322 | E31: ='Base de Dados P1'!E31 -> 9.29551 | F31: ='Base de Dados P1'!F31 -> -0.27550501 | G31: =F31*J31/100 -> -13603.848 | H31: =$M$15+SUMPRODUCT(D31:F31,$N$40:$P$40) -> 1.5100948 | I31: =B31-H31 -> 0.17843521 | J31: ='Base de Dados P1'!H31 -> 4937786
A32: Israel | B32: ='Base de Dados P1'!C32 -> 3.9650099 | C32: 1 | D32: ='Base de Dados P1'!D32 -> 43.702014 | E32: ='Base de Dados P1'!E32 -> 13.25932 | F32: ='Base de Dados P1'!F32 -> 5.7505322 | G32: =F32*J32/100 -> 497739.33 | H32: =$M$15+SUMPRODUCT(D32:F32,$N$40:$P$40) -> 1.0981947 | I32: =B32-H32 -> 2.8668153 | J32: ='Base de Dados P1'!H32 -> 8655535 | L32: Matriz VAR-COVAR
A33: Italy | B33: ='Base de Dados P1'!C33 -> 1.26458 | C33: 1 | D33: ='Base de Dados P1'!D33 -> 21.380459 | E33: ='Base de Dados P1'!E33 -> 8.72395 | F33: ='Base de Dados P1'!F33 -> 1.7105824 | G33: =F33*J33/100 -> 1034249.4 | H33: =$M$15+SUMPRODUCT(D33:F33,$N$40:$P$40) -> 1.640816 | I33: =B33-H33 -> -0.37623601 | J33: ='Base de Dados P1'!H33 -> 60461826 | L33: {=Q9:T12*M30} -> 0.18486467 | M33: 0.00040243721 | N33: -0.013456022 | O33: 0.0014868135
A34: Japan | B34: ='Base de Dados P1'!C34 -> 3.2539401 | C34: 1 | D34: ='Base de Dados P1'!D34 -> 20.841027 | E34: ='Base de Dados P1'!E34 -> 9.45758 | F34: ='Base de Dados P1'!F34 -> 4.6520301 | G34: =F34*J34/100 -> 5883723.1 | H34: =$M$15+SUMPRODUCT(D34:F34,$N$40:$P$40) -> 1.5739132 | I34: =B34-H34 -> 1.6800269 | J34: ='Base de Dados P1'!H34 -> 126476461 | L34: 0.00040243721 | M34: 4.5037027e-05 | N34: -0.00015360915 | O34: 1.5472654e-05
A35: Kenya | B35: ='Base de Dados P1'!C35 -> 0.97617 | C35: 1 | D35: ='Base de Dados P1'!D35 -> 77.647766 | E35: ='Base de Dados P1'!E35 -> 20.55599 | F35: ='Base de Dados P1'!F35 -> 8.4022771 | G35: =F35*J35/100 -> 4518013.3 | H35: =$M$15+SUMPRODUCT(D35:F35,$N$40:$P$40) -> 0.3088829 | I35: =B35-H35 -> 0.6672871 | J35: ='Base de Dados P1'!H35 -> 53771296 | L35: -0.013456022 | M35: -0.00015360915 | N35: 0.0014734466 | O35: -0.00040423837
A36: Kyrgyz Republic | B36: ='Base de Dados P1'!C36 -> 0.15547 | C36: 1 | D36: ='Base de Dados P1'!D36 -> 45.85531 | E36: ='Base de Dados P1'!E36 -> 15.68476 | F36: ='Base de Dados P1'!F36 -> -0.47156685 | G36: =F36*J36/100 -> -30765.941 | H36: =$M$15+SUMPRODUCT(D36:F36,$N$40:$P$40) -> 1.0633414 | I36: =B36-H36 -> -0.90787145 | J36: ='Base de Dados P1'!H36 -> 6524195 | L36: 0.0014868135 | M36: 1.5472654e-05 | N36: -0.00040423837 | O36: 0.00084787137
A37: Latvia | B37: ='Base de Dados P1'!C37 -> 0.60459 | C37: 1 | D37: ='Base de Dados P1'!D37 -> 20.978531 | E37: ='Base de Dados P1'!E37 -> 8.12264 | F37: ='Base de Dados P1'!F37 -> -2.8736097 | G37: =F37*J37/100 -> -54201.969 | H37: =$M$15+SUMPRODUCT(D37:F37,$N$40:$P$40) -> 1.7393768 | I37: =B37-H37 -> -1.1347868 | J37: ='Base de Dados P1'!H37 -> 1886198
A38: Macao | B38: ='Base de Dados P1'!C38 -> 0.051720001 | C38: 1 | D38: ='Base de Dados P1'!D38 -> 15.888047 | E38: ='Base de Dados P1'!E38 -> 15.67268 | F38: ='Base de Dados P1'!F38 -> 27.498964 | G38: =F38*J38/100 -> 178560.4 | H38: =$M$15+SUMPRODUCT(D38:F38,$N$40:$P$40) -> 1.0432227 | I38: =B38-H38 -> -0.9915027 | J38: ='Base de Dados P1'!H38 -> 649335
A39: Malaysia | B39: ='Base de Dados P1'!C39 -> 1.0674 | C39: 1 | D39: ='Base de Dados P1'!D39 -> 41.026654 | E39: ='Base de Dados P1'!E39 -> 18.40623 | F39: ='Base de Dados P1'!F39 -> 7.4259705 | G39: =F39*J39/100 -> 2403489.5 | H39: =$M$15+SUMPRODUCT(D39:F39,$N$40:$P$40) -> 0.89780024 | I39: =B39-H39 -> 0.16959974 | J39: ='Base de Dados P1'!H39 -> 32365999 | M39: α | N39: β1 | O39: β2 | P39: β3
A40: Mali | B40: ='Base de Dados P1'!C40 -> 0.66141999 | C40: 1 | D40: ='Base de Dados P1'!D40 -> 93.034395 | E40: ='Base de Dados P1'!E40 -> 16.50391 | F40: ='Base de Dados P1'!F40 -> 5.8193148 | G40: =F40*J40/100 -> 1178459.7 | H40: =$M$15+SUMPRODUCT(D40:F40,$N$40:$P$40) -> 0.30922954 | I40: =B40-H40 -> 0.35219045 | J40: ='Base de Dados P1'!H40 -> 20250833 | M40: 2.307678 | N40: -0.013277651 | O40: -0.040965978 | P40: -0.014962479
...
