Workbook

Sheet Estatistica descritiva
A1: Período | B1: Inflação (%) | C1: Desocupação (%) | F1: Inflação | G1: Desocupação | H1: Passo nº 1 - Estimar medidas de estatística descritiva
A2: 40969 | B2: 5.2399927 | C2: 7.9 | E2: Média | F2: =AVERAGE(B2:B97) -> 5.7824178 | G2: =AVERAGE(C2:C97) -> 9.8083333
A3: 41000 | B3: 5.1042261 | C3: 7.7 | E3: DP | F3: =_xlfn.STDEV.P(B2:B97) -> 2.2203703 | G3: =_xlfn.STDEV.P(C2:C97) -> 2.4351876
A4: 41030 | B4: 4.9891523 | C4: 7.6 | E4: CV | F4: =F3/F2*100 -> 38.398649 | G4: =G3/G2*100 -> 24.827742 | H4: <-- A variável "desocupação" é mais consistente/precisa
A5: 41061 | B5: 4.91577 | C5: 7.5 | E5: Mediana | F5: =MEDIAN(B2:B97) -> 5.6325241 | G5: =MEDIAN(C2:C97) -> 10.55 | I5: Menor CV = Maior precisão da variável
A6: 41091 | B6: 5.19859 | C6: 7.4 | E6: Assimetria | F6: =3*(F2-F5)/F3 -> 0.20252536 | G6: =3*(G2-G5)/G3 -> -0.91368729
A7: 41122 | B7: 5.2405144 | C7: 7.3 | F7: Assimetria D | G7: Assimetria E | I7: Tecnicamente simétrica se: -0.15 < A < +0.15
A8: 41153 | B8: 5.2823886 | C8: 7.1 | G8: =_xlfn.QUARTILE.EXC(C2:C97,1) -> 7.3 | H8: =_xlfn.QUARTILE.INC(C2:C97,1) -> 7.3
A9: 41183 | B9: 5.4501192 | C9: 6.9 | E9: Passo nº 2 - Realizar análises gráficas
A10: 41214 | B10: 5.5340429 | C10: 6.8 | E10: 1º - Linhas
A11: 41244 | B11: 5.838569 | C11: 6.9 | E11: 2º - Histograma
A12: 41275 | B12: 6.1543165 | C12: 7.2 | E12: 3º - Boxplot
A13: 41306 | B13: 6.3128347 | C13: 7.7 | E13: 4º - Dispersão
A14: 41334 | B14: 6.5886688 | C14: 8
A15: 41365 | B15: 6.493349 | C15: 7.8 | K15: Limites Superiores (BLOCOS)
A16: 41395 | B16: 6.5039602 | C16: 7.6 | K16: 3
A17: 41426 | B17: 6.695514 | C17: 7.4 | K17: 4
A18: 41456 | B18: 6.2705593 | C18: 7.3 | K18: 5
A19: 41487 | B19: 6.090637 | C19: 7.1 | K19: 6
A20: 41518 | B20: 5.8585605 | C20: 6.9 | K20: 7
A21: 41548 | B21: 5.8375129 | C21: 6.7 | K21: 8
A22: 41579 | B22: 5.7743892 | C22: 6.5 | K22: 9
A23: 41609 | B23: 5.9108181 | C23: 6.2 | K23: 10
A24: 41640 | B24: 5.5852941 | C24: 6.4
A25: 41671 | B25: 5.6797541 | C25: 6.7
A26: 41699 | B26: 6.1530883 | C26: 7.2 | F26: Limites Superiores (BLOCOS) | G26: Freqüência
A27: 41730 | B27: 6.2797752 | C27: 7.1 | F27: < 3,00 | G27: 14
A28: 41760 | B28: 6.3750744 | C28: 7 | F28: (3,00 , 4,00] | G28: 8
A29: 41791 | B29: 6.5236133 | C29: 6.8 | F29: (4,00 , 5,00] | G29: 17
A30: 41821 | B30: 6.502315 | C30: 6.9 | F30: (5,00 , 6,00] | G30: 15
A31: 41852 | B31: 6.5129397 | C31: 6.9 | F31: (6,00 , 7,00] | G31: 20
A32: 41883 | B32: 6.7464509 | C32: 6.8 | F32: (7,00 , 8,00] | G32: 3
A33: 41913 | B33: 6.5872387 | C33: 6.6 | F33: (8,00 , 9,00] | G33: 8
A34: 41944 | B34: 6.5554343 | C34: 6.5 | F34: (9,00 , 10,00] | G34: 7
A35: 41974 | B35: 6.4076166 | C35: 6.5 | F35: > 10,00 | G35: 4
A36: 42005 | B36: 7.1378131 | C36: 6.8
A37: 42036 | B37: 7.7017523 | C37: 7.4
A38: 42064 | B38: 8.128632 | C38: 7.9
A39: 42095 | B39: 8.1715956 | C39: 8
A40: 42125 | B40: 8.4730892 | C40: 8.1
...

Sheet Boxplot
C2: Inserir dados aqui! | E2: Não mexer nisso
A3: Lim. Inf. | B3: Mínimo | C3: =MIN('Estatistica descritiva'!B:B) -> 2.4558042 | E3: LI | F3: =C3 -> 2.4558042
B4: 1º Quartil | C4: =_xlfn.QUARTILE.EXC('Estatistica descritiva'!B2:B97,1) -> 4.0550528 | E4: A | F4: =0 -> 0
B5: Mediana | C5: =MEDIAN('Estatistica descritiva'!B2:B97) -> 5.6325241 | E5: B-A | F5: =C4-C3 -> 1.5992486
B6: 3º Quartil | C6: =_xlfn.QUARTILE.EXC('Estatistica descritiva'!B2:B97,3) -> 6.7337167 | E6: C-B | F6: =C5-C4 -> 1.5774713
A7: Lim. Sup. | B7: Máximo | C7: =MAX('Estatistica descritiva'!B2:B97,) -> 10.706293 | E7: D-C | F7: =C6-C5 -> 1.1011926
B8: Média | C8: =AVERAGE('Estatistica descritiva'!B2:B97) -> 5.7824178 | E8: E-D | F8: =C7-C6 -> 3.9725767
E9: LS | F9: =0 -> 0
B11: PROCEDIMENTO PARA O BOXPLOT - Versão 1
B12: 1- Insira, nas células verdes, os valores solicitados
B13: 2- Analise e interprete o gráfico :-)

Sheet Modelo econométrico
A1: Período | B1: Inflação (%) Y | C1: Desocupação (%) X | D1: y = Y - Y barra | E1: x = X - X barra | F1: x * y | G1: y² | H1: x² | I1: Y chapeu | J1: ê = Y - Y^ | K1: Y - Ybarra | L1: Y^ - Ybarra
A2: 40969 | B2: 5.2399927 | C2: 7.9 | D2: =B2-$O$3 -> -0.54242512 | E2: =C2-$O$2 -> -1.9083333 | F2: =E2*D2 -> 1.0351279 | G2: =D2^2 -> 0.29422501 | H2: =E2^2 -> 3.6417361 | I2: =$O$9+$O$10*C2 -> 6.5421411 | J2: =B2-I2 -> -1.3021484 | K2: =D2 -> -0.54242512 | L2: =I2-$O$3 -> 0.75972329 | N2: Média X | O2: =AVERAGE(C2:C97) -> 9.8083333
A3: 41000 | B3: 5.1042261 | C3: 7.7 | D3: =B3-$O$3 -> -0.67819171 | E3: =C3-$O$2 -> -2.1083333 | F3: =E3*D3 -> 1.4298542 | G3: =D3^2 -> 0.45994399 | H3: =E3^2 -> 4.4450694 | I3: =$O$9+$O$10*C3 -> 6.6217628 | J3: =B3-I3 -> -1.5175367 | K3: =D3 -> -0.67819171 | L3: =I3-$O$3 -> 0.83934495 | N3: Média Y | O3: =AVERAGE(B2:B97) -> 5.7824178
A4: 41030 | B4: 4.9891523 | C4: 7.6 | D4: =B4-$O$3 -> -0.79326551 | E4: =C4-$O$2 -> -2.2083333 | F4: =E4*D4 -> 1.7517947 | G4: =D4^2 -> 0.62927017 | H4: =E4^2 -> 4.8767361 | I4: =$O$9+$O$10*C4 -> 6.6615736 | J4: =B4-I4 -> -1.6724213 | K4: =D4 -> -0.79326551 | L4: =I4-$O$3 -> 0.87915578 | N4: Desvio padrão X (pop.) | O4: =_xlfn.STDEV.P(C2:C97) -> 2.4351876
A5: 41061 | B5: 4.91577 | C5: 7.5 | D5: =B5-$O$3 -> -0.86664784 | E5: =C5-$O$2 -> -2.3083333 | F5: =E5*D5 -> 2.0005121 | G5: =D5^2 -> 0.75107848 | H5: =E5^2 -> 5.3284028 | I5: =$O$9+$O$10*C5 -> 6.7013844 | J5: =B5-I5 -> -1.7856144 | K5: =D5 -> -0.86664784 | L5: =I5-$O$3 -> 0.91896661 | N5: Desvio padrão Y (pop.) | O5: =_xlfn.STDEV.P(B2:B97) -> 2.2203703
A6: 41091 | B6: 5.19859 | C6: 7.4 | D6: =B6-$O$3 -> -0.58382777 | E6: =C6-$O$2 -> -2.4083333 | F6: =E6*D6 -> 1.4060519 | G6: =D6^2 -> 0.34085487 | H6: =E6^2 -> 5.8000694 | I6: =$O$9+$O$10*C6 -> 6.7411953 | J6: =B6-I6 -> -1.5426052 | K6: =D6 -> -0.58382777 | L6: =I6-$O$3 -> 0.95877743 | N6: Correlação
A7: 41122 | B7: 5.2405144 | C7: 7.3 | D7: =B7-$O$3 -> -0.54190346 | E7: =C7-$O$2 -> -2.5083333 | F7: =E7*D7 -> 1.3592745 | G7: =D7^2 -> 0.29365936 | H7: =E7^2 -> 6.2917361 | I7: =$O$9+$O$10*C7 -> 6.7810061 | J7: =B7-I7 -> -1.5404917 | K7: =D7 -> -0.54190346 | L7: =I7-$O$3 -> 0.99858826 | N7: P.S: Alfa depende de Beta, ou seja, calcula-se sempre primeiro o beta.
A8: 41153 | B8: 5.2823886 | C8: 7.1 | D8: =B8-$O$3 -> -0.50002919 | E8: =C8-$O$2 -> -2.7083333 | F8: =E8*D8 -> 1.3542457 | G8: =D8^2 -> 0.25002919 | H8: =E8^2 -> 7.3350694 | I8: =$O$9+$O$10*C8 -> 6.8606277 | J8: =B8-I8 -> -1.5782391 | K8: =D8 -> -0.50002919 | L8: =I8-$O$3 -> 1.0782099 | N8: Inflação = 9,687 - 0,398 * Desocupação + e
A9: 41183 | B9: 5.4501192 | C9: 6.9 | D9: =B9-$O$3 -> -0.33229861 | E9: =C9-$O$2 -> -2.9083333 | F9: =E9*D9 -> 0.96643511 | G9: =D9^2 -> 0.11042236 | H9: =E9^2 -> 8.4584028 | I9: =$O$9+$O$10*C9 -> 6.9402494 | J9: =B9-I9 -> -1.4901302 | K9: =D9 -> -0.33229861 | L9: =I9-$O$3 -> 1.1578316 | N9: Alfa (β0) | O9: =O3-O10*O2 -> 9.6871965 | P9: Coeficiente linear / intercepto
A10: 41214 | B10: 5.5340429 | C10: 6.8 | D10: =B10-$O$3 -> -0.24837491 | E10: =C10-$O$2 -> -3.0083333 | F10: =E10*D10 -> 0.74719453 | G10: =D10^2 -> 0.061690098 | H10: =E10^2 -> 9.0500694 | I10: =$O$9+$O$10*C10 -> 6.9800602 | J10: =B10-I10 -> -1.4460173 | K10: =D10 -> -0.24837491 | L10: =I10-$O$3 -> 1.1976424 | N10: Beta (β1) | O10: =SUM(F2:F97)/SUM(H2:H97) -> -0.39810828 | P10: Coeficiente angular / inclinação
A11: 41244 | B11: 5.838569 | C11: 6.9 | D11: =B11-$O$3 -> 0.05615118 | E11: =C11-$O$2 -> -2.9083333 | F11: =E11*D11 -> -0.16330635 | G11: =D11^2 -> 0.003152955 | H11: =E11^2 -> 8.4584028 | I11: =$O$9+$O$10*C11 -> 6.9402494 | J11: =B11-I11 -> -1.1016804 | K11: =D11 -> 0.05615118 | L11: =I11-$O$3 -> 1.1578316 | N11: Significância estatística dos coeficientes
A12: 41275 | B12: 6.1543165 | C12: 7.2 | D12: =B12-$O$3 -> 0.3718987 | E12: =C12-$O$2 -> -2.6083333 | F12: =E12*D12 -> -0.97003578 | G12: =D12^2 -> 0.13830864 | H12: =E12^2 -> 6.8034028 | I12: =$O$9+$O$10*C12 -> 6.8208169 | J12: =B12-I12 -> -0.66650039 | K12: =D12 -> 0.3718987 | L12: =I12-$O$3 -> 1.0383991 | N12: s²(Alfa) | O12: =O14*((1/COUNT(J2:J97))+(O2^2/SUM(H2:H97))) -> 0.73108467 | P12: t(alfa) | Q12: =O9/SQRT(O12) -> 11.329592
A13: 41306 | B13: 6.3128347 | C13: 7.7 | D13: =B13-$O$3 -> 0.53041684 | E13: =C13-$O$2 -> -2.1083333 | F13: =E13*D13 -> -1.1182955 | G13: =D13^2 -> 0.28134203 | H13: =E13^2 -> 4.4450694 | I13: =$O$9+$O$10*C13 -> 6.6217628 | J13: =B13-I13 -> -0.30892811 | K13: =D13 -> 0.53041684 | L13: =I13-$O$3 -> 0.83934495 | N13: s²(Beta) | O13: =O14/SUM(H2:H97) -> 0.0071581251 | P13: t(beta) | Q13: =O10/SQRT(O13) -> -4.7054543
A14: 41334 | B14: 6.5886688 | C14: 8 | D14: =B14-$O$3 -> 0.80625096 | E14: =C14-$O$2 -> -1.8083333 | F14: =E14*D14 -> -1.4579705 | G14: =D14^2 -> 0.65004061 | H14: =E14^2 -> 3.2700694 | I14: =$O$9+$O$10*C14 -> 6.5023303 | J14: =B14-I14 -> 0.086338496 | K14: =D14 -> 0.80625096 | L14: =I14-$O$3 -> 0.71991247 | N14: Sigma^2 | O14: =SUMSQ(J2:J97)/(COUNT(J2:J97)-2) -> 4.0750729 | P14: gl | Q14: =COUNT(J2:J97)-2 -> 94
A15: 41365 | B15: 6.493349 | C15: 7.8 | D15: =B15-$O$3 -> 0.71093121 | E15: =C15-$O$2 -> -2.0083333 | F15: =E15*D15 -> -1.4277868 | G15: =D15^2 -> 0.50542318 | H15: =E15^2 -> 4.0334028 | I15: =$O$9+$O$10*C15 -> 6.5819519 | J15: =B15-I15 -> -0.088602915 | K15: =D15 -> 0.71093121 | L15: =I15-$O$3 -> 0.79953412 | P15: t(crítico
A16: 41395 | B16: 6.5039602 | C16: 7.6 | D16: =B16-$O$3 -> 0.72154234 | E16: =C16-$O$2 -> -2.2083333 | F16: =E16*D16 -> -1.593406 | G16: =D16^2 -> 0.52062335 | H16: =E16^2 -> 4.8767361 | I16: =$O$9+$O$10*C16 -> 6.6615736 | J16: =B16-I16 -> -0.15761344 | K16: =D16 -> 0.72154234 | L16: =I16-$O$3 -> 0.87915578
A17: 41426 | B17: 6.695514 | C17: 7.4 | D17: =B17-$O$3 -> 0.91309623 | E17: =C17-$O$2 -> -2.4083333 | F17: =E17*D17 -> -2.1990401 | G17: =D17^2 -> 0.83374472 | H17: =E17^2 -> 5.8000694 | I17: =$O$9+$O$10*C17 -> 6.7411953 | J17: =B17-I17 -> -0.045681206 | K17: =D17 -> 0.91309623 | L17: =I17-$O$3 -> 0.95877743 | N17: STQ | O17: =SUMSQ(K2:K97) -> 473.28427 | P17: Coluna K
A18: 41456 | B18: 6.2705593 | C18: 7.3 | D18: =B18-$O$3 -> 0.48814148 | E18: =C18-$O$2 -> -2.5083333 | F18: =E18*D18 -> -1.2244215 | G18: =D18^2 -> 0.2382821 | H18: =E18^2 -> 6.2917361 | I18: =$O$9+$O$10*C18 -> 6.7810061 | J18: =B18-I18 -> -0.51044678 | K18: =D18 -> 0.48814148 | L18: =I18-$O$3 -> 0.99858826 | N18: SQRes | O18: =SUMSQ(J2:J97) -> 383.05685 | P18: Coluna J
A19: 41487 | B19: 6.090637 | C19: 7.1 | D19: =B19-$O$3 -> 0.30821921 | E19: =C19-$O$2 -> -2.7083333 | F19: =E19*D19 -> -0.83476035 | G19: =D19^2 -> 0.09499908 | H19: =E19^2 -> 7.3350694 | I19: =$O$9+$O$10*C19 -> 6.8606277 | J19: =B19-I19 -> -0.76999071 | K19: =D19 -> 0.30821921 | L19: =I19-$O$3 -> 1.0782099 | N19: SQReg | O19: =SUMSQ(L2:L97) -> 90.227414 | P19: Coluna L
A20: 41518 | B20: 5.8585605 | C20: 6.9 | D20: =B20-$O$3 -> 0.076142642 | E20: =C20-$O$2 -> -2.9083333 | F20: =E20*D20 -> -0.22144818 | G20: =D20^2 -> 0.0057977019 | H20: =E20^2 -> 8.4584028 | I20: =$O$9+$O$10*C20 -> 6.9402494 | J20: =B20-I20 -> -1.0816889 | K20: =D20 -> 0.076142642 | L20: =I20-$O$3 -> 1.1578316 | N20: R²
A21: 41548 | B21: 5.8375129 | C21: 6.7 | D21: =B21-$O$3 -> 0.05509511 | E21: =C21-$O$2 -> -3.1083333 | F21: =E21*D21 -> -0.17125397 | G21: =D21^2 -> 0.0030354712 | H21: =E21^2 -> 9.6617361 | I21: =$O$9+$O$10*C21 -> 7.019871 | J21: =B21-I21 -> -1.1823581 | K21: =D21 -> 0.05509511 | L21: =I21-$O$3 -> 1.2374532
A22: 41579 | B22: 5.7743892 | C22: 6.5 | D22: =B22-$O$3 -> -0.0080286548 | E22: =C22-$O$2 -> -3.3083333 | F22: =E22*D22 -> 0.026561466 | G22: =D22^2 -> 6.4459298e-05 | H22: =E22^2 -> 10.945069 | I22: =$O$9+$O$10*C22 -> 7.0994927 | J22: =B22-I22 -> -1.3251035 | K22: =D22 -> -0.0080286548 | L22: =I22-$O$3 -> 1.3170749 | N22: Significância estatística do modelos como um todo
A23: 41609 | B23: 5.9108181 | C23: 6.2 | D23: =B23-$O$3 -> 0.12840026 | E23: =C23-$O$2 -> -3.6083333 | F23: =E23*D23 -> -0.46331095 | G23: =D23^2 -> 0.016486627 | H23: =E23^2 -> 13.020069 | I23: =$O$9+$O$10*C23 -> 7.2189252 | J23: =B23-I23 -> -1.3081071 | K23: =D23 -> 0.12840026 | L23: =I23-$O$3 -> 1.4365074 | N23: FONTE | O23: GL | P23: SQ | Q23: QM | R23: F
A24: 41640 | B24: 5.5852941 | C24: 6.4 | D24: =B24-$O$3 -> -0.19712377 | E24: =C24-$O$2 -> -3.4083333 | F24: =E24*D24 -> 0.6718635 | G24: =D24^2 -> 0.038857779 | H24: =E24^2 -> 11.616736 | I24: =$O$9+$O$10*C24 -> 7.1393035 | J24: =B24-I24 -> -1.5540095 | K24: =D24 -> -0.19712377 | L24: =I24-$O$3 -> 1.3568857 | N24: Regressão | O24: 1 | P24: =O19 -> 90.227414 | Q24: =P24 -> 90.227414
A25: 41671 | B25: 5.6797541 | C25: 6.7 | D25: =B25-$O$3 -> -0.10266376 | E25: =C25-$O$2 -> -3.1083333 | F25: =E25*D25 -> 0.31911319 | G25: =D25^2 -> 0.010539848 | H25: =E25^2 -> 9.6617361 | I25: =$O$9+$O$10*C25 -> 7.019871 | J25: =B25-I25 -> -1.340117 | K25: =D25 -> -0.10266376 | L25: =I25-$O$3 -> 1.2374532 | N25: Resíduos | O25: =Q14 -> 94 | P25: =O18 -> 383.05685
A26: 41699 | B26: 6.1530883 | C26: 7.2 | D26: =B26-$O$3 -> 0.37067046 | E26: =C26-$O$2 -> -2.6083333 | F26: =E26*D26 -> -0.96683212 | G26: =D26^2 -> 0.13739659 | H26: =E26^2 -> 6.8034028 | I26: =$O$9+$O$10*C26 -> 6.8208169 | J26: =B26-I26 -> -0.66772863 | K26: =D26 -> 0.37067046 | L26: =I26-$O$3 -> 1.0383991 | N26: Total
A27: 41730 | B27: 6.2797752 | C27: 7.1 | D27: =B27-$O$3 -> 0.49735739 | E27: =C27-$O$2 -> -2.7083333 | F27: =E27*D27 -> -1.3470096 | G27: =D27^2 -> 0.24736437 | H27: =E27^2 -> 7.3350694 | I27: =$O$9+$O$10*C27 -> 6.8606277 | J27: =B27-I27 -> -0.58085253 | K27: =D27 -> 0.49735739 | L27: =I27-$O$3 -> 1.0782099 | Q27: F9crit) | R27: =FINV(5%,O55,O56) -> #NUM!
A28: 41760 | B28: 6.3750744 | C28: 7 | D28: =B28-$O$3 -> 0.59265658 | E28: =C28-$O$2 -> -2.8083333 | F28: =E28*D28 -> -1.6643772 | G28: =D28^2 -> 0.35124182 | H28: =E28^2 -> 7.8867361 | I28: =$O$9+$O$10*C28 -> 6.9004386 | J28: =B28-I28 -> -0.52536416 | K28: =D28 -> 0.59265658 | L28: =I28-$O$3 -> 1.1180207
A29: 41791 | B29: 6.5236133 | C29: 6.8 | D29: =B29-$O$3 -> 0.74119548 | E29: =C29-$O$2 -> -3.0083333 | F29: =E29*D29 -> -2.2297631 | G29: =D29^2 -> 0.54937074 | H29: =E29^2 -> 9.0500694 | I29: =$O$9+$O$10*C29 -> 6.9800602 | J29: =B29-I29 -> -0.45644692 | K29: =D29 -> 0.74119548 | L29: =I29-$O$3 -> 1.1976424
A30: 41821 | B30: 6.502315 | C30: 6.9 | D30: =B30-$O$3 -> 0.71989715 | E30: =C30-$O$2 -> -2.9083333 | F30: =E30*D30 -> -2.0937009 | G30: =D30^2 -> 0.5182519 | H30: =E30^2 -> 8.4584028 | I30: =$O$9+$O$10*C30 -> 6.9402494 | J30: =B30-I30 -> -0.43793442 | K30: =D30 -> 0.71989715 | L30: =I30-$O$3 -> 1.1578316
A31: 41852 | B31: 6.5129397 | C31: 6.9 | D31: =B31-$O$3 -> 0.73052188 | E31: =C31-$O$2 -> -2.9083333 | F31: =E31*D31 -> -2.1246011 | G31: =D31^2 -> 0.53366222 | H31: =E31^2 -> 8.4584028 | I31: =$O$9+$O$10*C31 -> 6.9402494 | J31: =B31-I31 -> -0.42730969 | K31: =D31 -> 0.73052188 | L31: =I31-$O$3 -> 1.1578316
A32: 41883 | B32: 6.7464509 | C32: 6.8 | D32: =B32-$O$3 -> 0.96403306 | E32: =C32-$O$2 -> -3.0083333 | F32: =E32*D32 -> -2.9001328 | G32: =D32^2 -> 0.92935974 | H32: =E32^2 -> 9.0500694 | I32: =$O$9+$O$10*C32 -> 6.9800602 | J32: =B32-I32 -> -0.23360934 | K32: =D32 -> 0.96403306 | L32: =I32-$O$3 -> 1.1976424
A33: 41913 | B33: 6.5872387 | C33: 6.6 | D33: =B33-$O$3 -> 0.80482089 | E33: =C33-$O$2 -> -3.2083333 | F33: =E33*D33 -> -2.5821337 | G33: =D33^2 -> 0.64773667 | H33: =E33^2 -> 10.293403 | I33: =$O$9+$O$10*C33 -> 7.0596819 | J33: =B33-I33 -> -0.47244316 | K33: =D33 -> 0.80482089 | L33: =I33-$O$3 -> 1.2772641
A34: 41944 | B34: 6.5554343 | C34: 6.5 | D34: =B34-$O$3 -> 0.77301646 | E34: =C34-$O$2 -> -3.3083333 | F34: =E34*D34 -> -2.5573961 | G34: =D34^2 -> 0.59755445 | H34: =E34^2 -> 10.945069 | I34: =$O$9+$O$10*C34 -> 7.0994927 | J34: =B34-I34 -> -0.54405842 | K34: =D34 -> 0.77301646 | L34: =I34-$O$3 -> 1.3170749
A35: 41974 | B35: 6.4076166 | C35: 6.5 | D35: =B35-$O$3 -> 0.62519878 | E35: =C35-$O$2 -> -3.3083333 | F35: =E35*D35 -> -2.068366 | G35: =D35^2 -> 0.39087351 | H35: =E35^2 -> 10.945069 | I35: =$O$9+$O$10*C35 -> 7.0994927 | J35: =B35-I35 -> -0.6918761 | K35: =D35 -> 0.62519878 | L35: =I35-$O$3 -> 1.3170749
A36: 42005 | B36: 7.1378131 | C36: 6.8 | D36: =B36-$O$3 -> 1.3553953 | E36: =C36-$O$2 -> -3.0083333 | F36: =E36*D36 -> -4.0774807 | G36: =D36^2 -> 1.8370963 | H36: =E36^2 -> 9.0500694 | I36: =$O$9+$O$10*C36 -> 6.9800602 | J36: =B36-I36 -> 0.15775285 | K36: =D36 -> 1.3553953 | L36: =I36-$O$3 -> 1.1976424
A37: 42036 | B37: 7.7017523 | C37: 7.4 | D37: =B37-$O$3 -> 1.9193345 | E37: =C37-$O$2 -> -2.4083333 | F37: =E37*D37 -> -4.6223972 | G37: =D37^2 -> 3.6838449 | H37: =E37^2 -> 5.8000694 | I37: =$O$9+$O$10*C37 -> 6.7411953 | J37: =B37-I37 -> 0.96055705 | K37: =D37 -> 1.9193345 | L37: =I37-$O$3 -> 0.95877743
A38: 42064 | B38: 8.128632 | C38: 7.9 | D38: =B38-$O$3 -> 2.3462142 | E38: =C38-$O$2 -> -1.9083333 | F38: =E38*D38 -> -4.4773588 | G38: =D38^2 -> 5.5047211 | H38: =E38^2 -> 3.6417361 | I38: =$O$9+$O$10*C38 -> 6.5421411 | J38: =B38-I38 -> 1.5864909 | K38: =D38 -> 2.3462142 | L38: =I38-$O$3 -> 0.75972329
A39: 42095 | B39: 8.1715956 | C39: 8 | D39: =B39-$O$3 -> 2.3891778 | E39: =C39-$O$2 -> -1.8083333 | F39: =E39*D39 -> -4.3204298 | G39: =D39^2 -> 5.7081705 | H39: =E39^2 -> 3.2700694 | I39: =$O$9+$O$10*C39 -> 6.5023303 | J39: =B39-I39 -> 1.6692653 | K39: =D39 -> 2.3891778 | L39: =I39-$O$3 -> 0.71991247
... A97: 43862 | B97: 4.0049273 | C97: 11.6 | D97: =B97-$O$3 -> -1.7774905 | E97: =C97-$O$2 -> 1.7916667 | F97: =E97*D97 -> -3.1846705 | G97: =D97^2 -> 3.1594725 | H97: =E97^2 -> 3.2100694 | I97: =$O$9+$O$10*C97 -> 5.0691405 | J97: =B97-I97 -> -1.0642132 | K97: =D97 -> -1.7774905 | L97: =I97-$O$3 -> -0.71327733
