Workbook

Sheet Dados
A1: UF | B1: Mortalidade (Y) | C1: Educacao (X1) | D1: Pobres (X2) | E1: Theil (X3) | F1: Y^ | G1: ê | I1: α | J1: β1 | K1: β2 | L1: β3
A2: AC | B2: 34.079 | C2: 4.593 | D2: 47.829 | E2: 0.718 | F2: =$I$2+SUMPRODUCT(C2:E2,$J$2:$L$2) -> 53.630716 | G2: =B2-F2 -> -19.551716 | I2: -5.8231536 | J2: -0.70330149 | K2: 1.1012158 | L2: 13.947192
A3: AL | B3: 62.052 | C3: 4.111 | D3: 62.24 | E3: 0.816 | F3: =$I$2+SUMPRODUCT(C3:E3,$J$2:$L$2) -> 71.206152 | G3: =B3-F3 -> -9.1541523
A4: AM | B4: 51.313 | C4: 5.548 | D4: 52.968 | E4: 0.786 | F4: =$I$2+SUMPRODUCT(C4:E4,$J$2:$L$2) -> 59.56662 | G4: =B4-F4 -> -8.2536196
A5: AP | B5: 36.351 | C5: 6.05 | D5: 42.947 | E5: 0.708 | F5: =$I$2+SUMPRODUCT(C5:E5,$J$2:$L$2) -> 47.090398 | G5: =B5-F5 -> -10.739398 | I5: Y = a + b1X1 + b2X2 + b3X3 | L5: <---- OK!
A6: BA | B6: 70.187 | C6: 4.455 | D6: 55.316 | E6: 0.775 | F6: =$I$2+SUMPRODUCT(C6:E6,$J$2:$L$2) -> 62.767564 | G6: =B6-F6 -> 7.4194363 | I6: Y = a + b1X1 + b2X2
A7: CE | B7: 64.966 | C7: 4.42 | D7: 57 | E7: 0.816 | F7: =$I$2+SUMPRODUCT(C7:E7,$J$2:$L$2) -> 65.218461 | G7: =B7-F7 -> -0.25246148 | I7: Y = a + b1X1 + b3X3
A8: DF | B8: 24 | C8: 8.249 | D8: 16.072 | E8: 0.781 | F8: =$I$2+SUMPRODUCT(C8:E8,$J$2:$L$2) -> 16.966809 | G8: =B8-F8 -> 7.033191 | I8: Y = a + b2X2 + b3X3
A9: ES | B9: 33.711 | C9: 5.902 | D9: 28.04 | E9: 0.651 | F9: =$I$2+SUMPRODUCT(C9:E9,$J$2:$L$2) -> 29.983673 | G9: =B9-F9 -> 3.7273269
A10: GO | B10: 24.545 | C10: 5.662 | D10: 26.65 | E10: 0.648 | F10: =$I$2+SUMPRODUCT(C10:E10,$J$2:$L$2) -> 28.579934 | G10: =B10-F10 -> -4.034934
A11: MA | B11: 85.7 | C11: 3.969 | D11: 66.813 | E11: 0.758 | F11: =$I$2+SUMPRODUCT(C11:E11,$J$2:$L$2) -> 75.532944 | G11: =B11-F11 -> 10.167056
A12: MG | B12: 30.369 | C12: 5.623 | D12: 29.766 | E12: 0.671 | F12: =$I$2+SUMPRODUCT(C12:E12,$J$2:$L$2) -> 32.359537 | G12: =B12-F12 -> -1.9905365
A13: MS | B13: 26.565 | C13: 5.729 | D13: 28.66 | E13: 0.692 | F13: =$I$2+SUMPRODUCT(C13:E13,$J$2:$L$2) -> 31.359933 | G13: =B13-F13 -> -4.7949329
A14: MT | B14: 30.549 | C14: 5.502 | D14: 27.784 | E14: 0.685 | F14: =$I$2+SUMPRODUCT(C14:E14,$J$2:$L$2) -> 30.457287 | G14: =B14-F14 -> 0.091713
A15: PA | B15: 35.595 | C15: 5.005 | D15: 51.887 | E15: 0.744 | F15: =$I$2+SUMPRODUCT(C15:E15,$J$2:$L$2) -> 58.172316 | G15: =B15-F15 -> -22.577316
A16: PB | B16: 77.715 | C16: 4.329 | D16: 55.262 | E16: 0.734 | F16: =$I$2+SUMPRODUCT(C16:E16,$J$2:$L$2) -> 62.224879 | G16: =B16-F16 -> 15.490121
A17: PE | B17: 54.598 | C17: 5.053 | D17: 51.306 | E17: 0.795 | F17: =$I$2+SUMPRODUCT(C17:E17,$J$2:$L$2) -> 58.210058 | G17: =B17-F17 -> -3.612058
A18: PI | B18: 73.533 | C18: 3.949 | D18: 61.811 | E18: 0.796 | F18: =$I$2+SUMPRODUCT(C18:E18,$J$2:$L$2) -> 70.568722 | G18: =B18-F18 -> 2.9642782
A19: PR | B19: 23.527 | C19: 5.981 | D19: 23.694 | E19: 0.652 | F19: =$I$2+SUMPRODUCT(C19:E19,$J$2:$L$2) -> 25.156176 | G19: =B19-F19 -> -1.6291757
A20: RJ | B20: 23.07 | C20: 7.235 | D20: 19.228 | E20: 0.664 | F20: =$I$2+SUMPRODUCT(C20:E20,$J$2:$L$2) -> 19.523572 | G20: =B20-F20 -> 3.5464277
A21: RN | B21: 67.712 | C21: 4.95 | D21: 50.634 | E21: 0.731 | F21: =$I$2+SUMPRODUCT(C21:E21,$J$2:$L$2) -> 56.649861 | G21: =B21-F21 -> 11.062139
A22: RO | B22: 36.352 | C22: 4.859 | D22: 35.203 | E22: 0.639 | F22: =$I$2+SUMPRODUCT(C22:E22,$J$2:$L$2) -> 38.437859 | G22: =B22-F22 -> -2.0858589 | I22: O método rápido do Excel só funciona se as variáveis X estiverem em colunas CONTÍGUAS
A23: RR | B23: 39.18 | C23: 5.681 | D23: 35.897 | E23: 0.643 | F23: =$I$2+SUMPRODUCT(C23:E23,$J$2:$L$2) -> 38.679778 | G23: =B23-F23 -> 0.50022241
A24: RS | B24: 17.269 | C24: 6.416 | D24: 19.687 | E24: 0.617 | F24: =$I$2+SUMPRODUCT(C24:E24,$J$2:$L$2) -> 19.949516 | G24: =B24-F24 -> -2.6805163
A25: SC | B25: 16.797 | C25: 6.199 | D25: 16.244 | E25: 0.551 | F25: =$I$2+SUMPRODUCT(C25:E25,$J$2:$L$2) -> 15.390132 | G25: =B25-F25 -> 1.4068679
A26: SE | B26: 72.664 | C26: 4.691 | D26: 53.993 | E26: 0.763 | F26: =$I$2+SUMPRODUCT(C26:E26,$J$2:$L$2) -> 60.97731 | G26: =B26-F26 -> 11.68669
A27: SP | B27: 20.008 | C27: 6.847 | D27: 14.369 | E27: 0.607 | F27: =$I$2+SUMPRODUCT(C27:E27,$J$2:$L$2) -> 13.650656 | G27: =B27-F27 -> 6.3573441
A28: TO | B28: 67.023 | C28: 4.658 | D28: 50.785 | E28: 0.738 | F28: =$I$2+SUMPRODUCT(C28:E28,$J$2:$L$2) -> 57.119139 | G28: =B28-F28 -> 9.9038613

Sheet Matrizes
A2: Matriz y | B2: 1º passo - compor a MATRIZ X | G2: 2º passo - inverter a matriz X para obter a MATRIZ XT
A3: 34.079 | B3: 1 | C3: 4.593 | D3: 47.829 | E3: 0.718 | G3: {=TRANSPOSE(B3:E29)} -> 1 | H3: 1 | I3: 1 | J3: 1 | K3: 1 | L3: 1 | M3: 1 | N3: 1 | O3: 1 | P3: 1 | Q3: 1 | R3: 1 | S3: 1 | T3: 1 | U3: 1 | V3: 1 | W3: 1 | X3: 1 | Y3: 1 | Z3: 1 | AA3: 1 | AB3: 1 | AC3: 1 | AD3: 1 | AE3: 1 | AF3: 1 | AG3: 1
A4: 62.052 | B4: 1 | C4: 4.111 | D4: 62.24 | E4: 0.816 | G4: 4.593 | H4: 4.111 | I4: 5.548 | J4: 6.05 | K4: 4.455 | L4: 4.42 | M4: 8.249 | N4: 5.902 | O4: 5.662 | P4: 3.969 | Q4: 5.623 | R4: 5.729 | S4: 5.502 | T4: 5.005 | U4: 4.329 | V4: 5.053 | W4: 3.949 | X4: 5.981 | Y4: 7.235 | Z4: 4.95 | AA4: 4.859 | AB4: 5.681 | AC4: 6.416 | AD4: 6.199 | AE4: 4.691 | AF4: 6.847 | AG4: 4.658
A5: 51.313 | B5: 1 | C5: 5.548 | D5: 52.968 | E5: 0.786 | G5: 47.829 | H5: 62.24 | I5: 52.968 | J5: 42.947 | K5: 55.316 | L5: 57 | M5: 16.072 | N5: 28.04 | O5: 26.65 | P5: 66.813 | Q5: 29.766 | R5: 28.66 | S5: 27.784 | T5: 51.887 | U5: 55.262 | V5: 51.306 | W5: 61.811 | X5: 23.694 | Y5: 19.228 | Z5: 50.634 | AA5: 35.203 | AB5: 35.897 | AC5: 19.687 | AD5: 16.244 | AE5: 53.993 | AF5: 14.369 | AG5: 50.785
A6: 36.351 | B6: 1 | C6: 6.05 | D6: 42.947 | E6: 0.708 | G6: 0.718 | H6: 0.816 | I6: 0.786 | J6: 0.708 | K6: 0.775 | L6: 0.816 | M6: 0.781 | N6: 0.651 | O6: 0.648 | P6: 0.758 | Q6: 0.671 | R6: 0.692 | S6: 0.685 | T6: 0.744 | U6: 0.734 | V6: 0.795 | W6: 0.796 | X6: 0.652 | Y6: 0.664 | Z6: 0.731 | AA6: 0.639 | AB6: 0.643 | AC6: 0.617 | AD6: 0.551 | AE6: 0.763 | AF6: 0.607 | AG6: 0.738
A7: 70.187 | B7: 1 | C7: 4.455 | D7: 55.316 | E7: 0.775
A8: 64.966 | B8: 1 | C8: 4.42 | D8: 57 | E8: 0.816
A9: 24 | B9: 1 | C9: 8.249 | D9: 16.072 | E9: 0.781
A10: 33.711 | B10: 1 | C10: 5.902 | D10: 28.04 | E10: 0.651
A11: 24.545 | B11: 1 | C11: 5.662 | D11: 26.65 | E11: 0.648
A12: 85.7 | B12: 1 | C12: 3.969 | D12: 66.813 | E12: 0.758 | G12: 3º passo - multiplicar matrizes e obter a MATRIZ XTX | N12: 4º passo - inverter a matriz XTX
A13: 30.369 | B13: 1 | C13: 5.623 | D13: 29.766 | E13: 0.671 | G13: {=MMULT(G3:AG6,B3:E29)} -> 27 | H13: 145.666 | I13: 1082.085 | J13: 19.179 | N13: {=MINVERSE(G13:J16)} -> 9.9807859 | O13: -0.87409434 | P13: -0.035753675 | Q13: -5.34266
A14: 26.565 | B14: 1 | C14: 5.729 | D14: 28.66 | E14: 0.692 | G14: 145.666 | H14: 813.7625 | I14: 5450.1379 | J14: 102.51326 | N14: -0.87409434 | O14: 0.26572018 | P14: 0.021472966 | Q14: -1.9991357
A15: 30.549 | B15: 1 | C15: 5.502 | D15: 27.784 | E15: 0.685 | G15: 1082.085 | H15: 5450.1379 | I15: 50392.554 | J15: 792.56494 | N15: -0.035753675 | O15: 0.021472966 | P15: 0.0021184156 | Q15: -0.23227684
A16: 35.595 | B16: 1 | C16: 5.005 | D16: 51.887 | E16: 0.744 | G16: 19.179 | H16: 102.51326 | I16: 792.56494 | J16: 13.753097 | N16: -5.34266 | O16: -1.9991357 | P16: -0.23227684 | Q16: 35.810063
A17: 77.715 | B17: 1 | C17: 4.329 | D17: 55.262 | E17: 0.734
A18: 54.598 | B18: 1 | C18: 5.053 | D18: 51.306 | E18: 0.795
A19: 73.533 | B19: 1 | C19: 3.949 | D19: 61.811 | E19: 0.796 | G19: 5º passo - multipliar XT pela matriz y | M19: 6º passo - calcular os coeficientes beta, conforme a fórmula acima
A20: 23.527 | B20: 1 | C20: 5.981 | D20: 23.694 | E20: 0.652 | G20: {=MMULT(G3:AG6,A3:A29)} -> 1199.43 | M20: α | N20: {=MMULT(N13:Q16,G20:G23)} -> -5.8231536
A21: 23.07 | B21: 1 | C21: 7.235 | D21: 19.228 | E21: 0.664 | G21: 6010.994 | L21: Educacao | M21: β1 | N21: -0.70330149 | O21: <--- O aumento de 1 ANO na escolaridade média reduz em 0,7 o número de óbitos a cada 1.000 crianças
A22: 67.712 | B22: 1 | C22: 4.95 | D22: 50.634 | E22: 0.731 | G22: 56412.893 | L22: Pobres | M22: β2 | N22: 1.1012158 | O22: <--- O aumento em 1 PONTO PERCENTUAL no percentual de pobres aumenta em 1,10 o número de óbitos a cada 1.000 crianças
A23: 36.352 | B23: 1 | C23: 4.859 | D23: 35.203 | E23: 0.639 | G23: 880.8221 | L23: Theil | M23: β3 | N23: 13.947192 | O23: <--- O aumento em 0,01 UNIDADES no índice de Theil aumenta em (13,95 / 100 = 0,1395) o número de óbitos a cada 1.000 crianças
A24: 39.18 | B24: 1 | C24: 5.681 | D24: 35.897 | E24: 0.643
A25: 17.269 | B25: 1 | C25: 6.416 | D25: 19.687 | E25: 0.617 | M25: Mortalidade = alfa + b1 (Educacao) + b2 (Pobres) + b3 (Theil)
A26: 16.797 | B26: 1 | C26: 6.199 | D26: 16.244 | E26: 0.551 | G26: yTy | I26: βTXTy
A27: 72.664 | B27: 1 | C27: 4.691 | D27: 53.993 | E27: 0.763 | G27: {=MMULT(TRANSPOSE(A3:A29),A3:A29)} -> 65308.325 | I27: {=MMULT(TRANSPOSE(N20:N23),MMULT(G3:AG6,A3:A29))} -> 63195.756 | M27: Mortalidade: óbitos de crianças até 5 anos em cada 1.000
A28: 20.008 | B28: 1 | C28: 6.847 | D28: 14.369 | E28: 0.607 | M28: Educacao: número médio de anos estudados
A29: 67.023 | B29: 1 | C29: 4.658 | D29: 50.785 | E29: 0.738 | M29: Pobres: percentual de pobres
M30: Theil: índice de desigualdade (0 a 1)
A31: =COUNTA(A3:A29) -> 27 | B31: n | G31: STQ | H31: =G27-A31*A32^2 -> 12025.647
A32: =AVERAGE(A3:A29) -> 44.423333 | B32: Y barra | G32: SQReg | H32: =I27-A31*A32^2 -> 9913.0778
G33: SQRes | H33: =G27-I27 -> 2112.569
H34: =H32+H33=H31 -> TRUE
G35: R² | H35: =H32/H31 -> 0.82432803
C37: TABELA ANOVA
C38: Fonte | D38: GL | E38: SQ | F38: QM | G38: F(calc) | H38: F(crit)
C39: Regressão | D39: 3 | E39: =H32 -> 9913.0778 | F39: =E39/D39 -> 3304.3593 | G39: =F39/F40 -> 35.975281 | H39: =FINV(5%,D39,D40) -> 3.0279984
C40: Resíduos | D40: =A31-(D39+1) -> 23 | E40: =H33 -> 2112.569 | F40: =E40/D40 -> 91.850826
C41: Total | D41: =A31-1 -> 26 | E41: =H31 -> 12025.647 | F41: =E41/D41 -> 462.52488
J42: R² adj. | K42: =1-(F40/F41) -> 0.8014143
...

Sheet Contribuição Marginal
A1: Y | B1: X1 | C1: X2 | E1: Y | F1: X2 | G1: X3 | I1: Y | J1: X1 | K1: X3 | M1: REGRESSÃO 3 - Y = f(X1,X3) | Y1: REGRESSÃO 2 - Y = f(X2,X3) | AJ1: REGRESSÃO 1 - Y = f(X1,X2)
A2: 34.079 | B2: 4.593 | C2: 47.829 | E2: 34.079 | F2: 47.829 | G2: 0.718 | I2: 34.079 | J2: 4.593 | K2: 0.718 | M2: RESUMO DOS RESULTADOS | Y2: RESUMO DOS RESULTADOS | AJ2: RESUMO DOS RESULTADOS
A3: 62.052 | B3: 4.111 | C3: 62.24 | E3: 62.052 | F3: 62.24 | G3: 0.816 | I3: 62.052 | J3: 4.111 | K3: 0.816
A4: 51.313 | B4: 5.548 | C4: 52.968 | E4: 51.313 | F4: 52.968 | G4: 0.786 | I4: 51.313 | J4: 5.548 | K4: 0.786 | M4: Estatística de regressão | Y4: Estatística de regressão | AJ4: Estatística de regressão
A5: 36.351 | B5: 6.05 | C5: 42.947 | E5: 36.351 | F5: 42.947 | G5: 0.708 | I5: 36.351 | J5: 6.05 | K5: 0.708 | M5: R múltiplo | N5: 0.88132062 | Y5: R múltiplo | Z5: 0.90783988 | AJ5: R múltiplo | AK5: 0.90767633
A6: 70.187 | B6: 4.455 | C6: 55.316 | E6: 70.187 | F6: 55.316 | G6: 0.775 | I6: 70.187 | J6: 4.455 | K6: 0.775 | M6: R-Quadrado | N6: 0.77672603 | Y6: R-Quadrado | Z6: 0.82417324 | AJ6: R-Quadrado | AK6: 0.82387632
A7: 64.966 | B7: 4.42 | C7: 57 | E7: 64.966 | F7: 57 | G7: 0.816 | I7: 64.966 | J7: 4.42 | K7: 0.816 | M7: R-quadrado ajustado | N7: 0.75811987 | O7: <---- | Y7: R-quadrado ajustado | Z7: 0.80952101 | AA7: <---- | AJ7: R-quadrado ajustado | AK7: 0.80919935 | AL7: <-----
A8: 24 | B8: 8.249 | C8: 16.072 | E8: 24 | F8: 16.072 | G8: 0.781 | I8: 24 | J8: 8.249 | K8: 0.781 | M8: Erro padrão | N8: 10.577125 | Y8: Erro padrão | Z8: 9.3862277 | AJ8: Erro padrão | AK8: 9.3941496
A9: 33.711 | B9: 5.902 | C9: 28.04 | E9: 33.711 | F9: 28.04 | G9: 0.651 | I9: 33.711 | J9: 5.902 | K9: 0.651 | M9: Observações | N9: 27 | Y9: Observações | Z9: 27 | AJ9: Observações | AK9: 27
A10: 24.545 | B10: 5.662 | C10: 26.65 | E10: 24.545 | F10: 26.65 | G10: 0.648 | I10: 24.545 | J10: 5.662 | K10: 0.648
A11: 85.7 | B11: 3.969 | C11: 66.813 | E11: 85.7 | F11: 66.813 | G11: 0.758 | I11: 85.7 | J11: 3.969 | K11: 0.758 | M11: ANOVA | Y11: ANOVA | AJ11: ANOVA
A12: 30.369 | B12: 5.623 | C12: 29.766 | E12: 30.369 | F12: 29.766 | G12: 0.671 | I12: 30.369 | J12: 5.623 | K12: 0.671 | N12: gl | O12: SQ | P12: MQ | Q12: F | R12: F de significação | Z12: gl | AA12: SQ | AB12: MQ | AC12: F | AD12: F de significação | AK12: gl | AL12: SQ | AM12: MQ | AN12: F | AO12: F de significação
A13: 26.565 | B13: 5.729 | C13: 28.66 | E13: 26.565 | F13: 28.66 | G13: 0.692 | I13: 26.565 | J13: 5.729 | K13: 0.692 | M13: Regressão | N13: 2 | O13: 9340.6329 | P13: 4670.3164 | Q13: 41.745629 | R13: 1.5348189e-08 | Y13: Regressão | Z13: 2 | AA13: 9911.2163 | AB13: 4955.6081 | AC13: 56.248998 | AD13: 8.7301079e-10 | AJ13: Regressão | AK13: 2 | AL13: 9907.6456 | AM13: 4953.8228 | AN13: 56.13394 | AO13: 8.9086701e-10 | AQ13: SQReg RESTRITA
A14: 30.549 | B14: 5.502 | C14: 27.784 | E14: 30.549 | F14: 27.784 | G14: 0.685 | I14: 30.549 | J14: 5.502 | K14: 0.685 | M14: Resíduo | N14: 24 | O14: 2685.0139 | P14: 111.87558 | Y14: Resíduo | Z14: 24 | AA14: 2114.4305 | AB14: 88.10127 | AJ14: Resíduo | AK14: 24 | AL14: 2118.0011 | AM14: 88.250046 | AQ14: SQReg(r)
A15: 35.595 | B15: 5.005 | C15: 51.887 | E15: 35.595 | F15: 51.887 | G15: 0.744 | I15: 35.595 | J15: 5.005 | K15: 0.744 | M15: Total | N15: 26 | O15: 12025.647 | Y15: Total | Z15: 26 | AA15: 12025.647 | AJ15: Total | AK15: 26 | AL15: 12025.647
A16: 77.715 | B16: 4.329 | C16: 55.262 | E16: 77.715 | F16: 55.262 | G16: 0.734 | I16: 77.715 | J16: 4.329 | K16: 0.734
A17: 54.598 | B17: 5.053 | C17: 51.306 | E17: 54.598 | F17: 51.306 | G17: 0.795 | I17: 54.598 | J17: 5.053 | K17: 0.795 | N17: Coeficientes | O17: Erro padrão | P17: Stat t | Q17: valor-P | R17: 95% inferiores | S17: 95% superiores | T17: Inferior 95,0% | U17: Superior 95,0% | Z17: Coeficientes | AA17: Erro padrão | AB17: Stat t | AC17: valor-P | AD17: 95% inferiores | AE17: 95% superiores | AF17: Inferior 95,0% | AG17: Superior 95,0% | AK17: Coeficientes | AL17: Erro padrão | AM17: Stat t | AN17: valor-P | AO17: 95% inferiores | AP17: 95% superiores | AQ17: Inferior 95,0% | AR17: Superior 95,0%
A18: 73.533 | B18: 3.949 | C18: 61.811 | E18: 73.533 | F18: 61.811 | G18: 0.796 | I18: 73.533 | J18: 3.949 | K18: 0.796 | M18: Interseção | N18: 12.762676 | O18: 32.389761 | P18: 0.39403429 | Q18: 0.69703502 | R18: -54.086504 | S18: 79.611857 | T18: -54.086504 | U18: 79.611857 | Y18: Interseção | Z18: -8.1366845 | AA18: 25.019935 | AB18: -0.32520806 | AC18: 0.74784169 | AD18: -59.775292 | AE18: 43.501923 | AF18: -59.775292 | AG18: 43.501923 | AJ18: Interseção | AK18: -3.7423111 | AL18: 28.468599 | AM18: -0.13145399 | AN18: 0.89651195 | AO18: -62.498613 | AP18: 55.01399 | AQ18: -62.498613 | AR18: 55.01399
A19: 23.527 | B19: 5.981 | C19: 23.694 | E19: 23.527 | F19: 23.694 | G19: 0.652 | I19: 23.527 | J19: 5.981 | K19: 0.652 | M19: X1 | N19: -11.865591 | O19: 2.3188535 | P19: -5.1170078 | Q19: 3.0911715e-05 | R19: -16.65147 | S19: -7.0797129 | T19: -16.65147 | U19: -7.0797129 | Y19: X2 | Z19: 1.1580499 | AA19: 0.18373422 | AB19: 6.3028535 | AC19: 1.6258079e-06 | AD19: 0.77884108 | AE19: 1.5372587 | AF19: 0.77884108 | AG19: 1.5372587 | AJ19: X1 | AK19: 0.075315629 | AL19: 3.6879218 | AM19: 0.020422241 | AN19: 0.98387538 | AO19: -7.5361809 | AP19: 7.6868121 | AQ19: -7.5361809 | AR19: 7.6868121
A20: 23.07 | B20: 7.235 | C20: 19.228 | E20: 23.07 | F20: 19.228 | G20: 0.664 | I20: 23.07 | J20: 7.235 | K20: 0.664 | M20: X3 | N20: 134.69164 | O20: 34.014499 | P20: 3.9598302 | Q20: 0.00058316581 | R20: 64.489164 | S20: 204.89412 | T20: 64.489164 | U20: 204.89412 | Y20: X3 | Z20: 8.6559296 | AA20: 42.776534 | AB20: 0.20235229 | AC20: 0.84134687 | AD20: -79.630497 | AE20: 96.942356 | AF20: -79.630497 | AG20: 96.942356 | AJ20: X2 | AK20: 1.1916822 | AL20: 0.23235763 | AM20: 5.1286555 | AN20: 3.0014646e-05 | AO20: 0.71211966 | AP20: 1.6712448 | AQ20: 0.71211966 | AR20: 1.6712448
A21: 67.712 | B21: 4.95 | C21: 50.634 | E21: 67.712 | F21: 50.634 | G21: 0.731 | I21: 67.712 | J21: 4.95 | K21: 0.731
A22: 36.352 | B22: 4.859 | C22: 35.203 | E22: 36.352 | F22: 35.203 | G22: 0.639 | I22: 36.352 | J22: 4.859 | K22: 0.639 | M22: Fonte | N22: GL | O22: SQ | P22: QM | Q22: F | Y22: Fonte | Z22: GL | AA22: SQ | AB22: QM | AC22: F
A23: 39.18 | B23: 5.681 | C23: 35.897 | E23: 39.18 | F23: 35.897 | G23: 0.643 | I23: 39.18 | J23: 5.681 | K23: 0.643 | M23: Reg. Restrita | N23: 2 | O23: =O13 -> 9340.6329 | P23: =O23/N23 -> 4670.3164 | Y23: Reg. Restrita | Z23: 2 | AA23: =AA13 -> 9911.2163 | AB23: =AA23/Z23 -> 4955.6081 | AJ23: Fonte | AK23: GL | AL23: SQ | AM23: QM | AN23: F
A24: 17.269 | B24: 6.416 | C24: 19.687 | E24: 17.269 | F24: 19.687 | G24: 0.617 | I24: 17.269 | J24: 6.416 | K24: 0.617 | M24: Contribuição | N24: 1 | O24: =O25-O23 -> 572.4449 | P24: =O24/N24 -> 572.4449 | Q24: =P24/P26 -> 6.2323326 | R24: <---- A variável X2, isoladamente, tem contribuição marginal significativa | Y24: Contribuição | Z24: 1 | AA24: =AA25-AA23 -> 1.8614807 | AB24: =AA24/Z24 -> 1.8614807 | AC24: =AB24/AB26 -> 0.020266347 | AJ24: Reg. Restrita | AK24: 2 | AL24: =AL13 -> 9907.6456 | AM24: =AL24/AK24 -> 4953.8228
A25: 16.797 | B25: 6.199 | C25: 16.244 | E25: 16.797 | F25: 16.244 | G25: 0.551 | I25: 16.797 | J25: 6.199 | K25: 0.551 | M25: Reg. Irrestrita | N25: =Z25 -> 3 | O25: =AA25 -> 9913.0778 | P25: =O25/N25 -> 3304.3593 | Y25: Reg. Irrestrita | Z25: 3 | AA25: =AL26 -> 9913.0778 | AB25: =AA25/Z25 -> 3304.3593 | AJ25: Contribuição | AK25: 1 | AL25: =AL26-AL24 -> 5.4321087 | AM25: =AL25/AK25 -> 5.4321087 | AN25: =AM25/AM27 -> 0.059140554
A26: 72.664 | B26: 4.691 | C26: 53.993 | E26: 72.664 | F26: 53.993 | G26: 0.763 | I26: 72.664 | J26: 4.691 | K26: 0.763 | M26: Resíduos | N26: =Z26 -> 23 | O26: =AA26 -> 2112.569 | P26: =O26/N26 -> 91.850826 | Y26: Resíduos | Z26: =AK27 -> 23 | AA26: =AL27 -> 2112.569 | AB26: =AA26/Z26 -> 91.850826 | AJ26: Reg. Irrestrita | AK26: 3 | AL26: =Matrizes!E39 -> 9913.0778 | AM26: =AL26/AK26 -> 3304.3593
A27: 20.008 | B27: 6.847 | C27: 14.369 | E27: 20.008 | F27: 14.369 | G27: 0.607 | I27: 20.008 | J27: 6.847 | K27: 0.607 | M27: Total | N27: =Z27 -> 26 | O27: =AA27 -> 12025.647 | Y27: Total | Z27: =AK28 -> 26 | AA27: =AL28 -> 12025.647 | AJ27: Resíduos | AK27: =AK9-(AK26+1) -> 23 | AL27: =Matrizes!E40 -> 2112.569 | AM27: =AL27/AK27 -> 91.850826
A28: 67.023 | B28: 4.658 | C28: 50.785 | E28: 67.023 | F28: 50.785 | G28: 0.738 | I28: 67.023 | J28: 4.658 | K28: 0.738 | M28: TESTE DE CONTRIBUIÇÃO MARGINAL | AJ28: Total | AK28: =AK27+AK26 -> 26 | AL28: =AL15 -> 12025.647
X29: F(crit) | Y29: =FINV(5%,Z24,Z26) -> 4.2793443
AI30: F(crit) | AJ30: =FINV(5%,AK25,AK27) -> 4.2793443
AO33: NÃO REJEITO H0, POIS F(calc) < F(crit)
AO34: H0: | AP34: Os coeficientes das "q" variáveis que não estão no modelo restrito são iguais a 0
AO35: H1: | AP35: Os coeficientes das "q" variáveis que não estão no modelo restrito são diferentes de 0

Sheet Dados (2)
A1: UF | B1: ln(Y) | C1: ln(X1) | D1: Pobres (X2) | E1: Theil (X3) | F1: Mortalidade (Y) | G1: Educacao (X1) | J1: Y | K1: X1 | L1: X2 | M1: X3
A2: AC | B2: =LN(F2) -> 3.5286814 | C2: =LN(G2) -> 1.5245334 | D2: 47.829 | E2: 0.718 | F2: 34.079 | G2: 4.593 | I2: Assimetria | J2: =3*(J3-J4)/J5 -> 0.48655863 | K2: =3*(K3-K4)/K5 -> -0.59067027 | L2: =3*(L3-L4)/L5 -> -0.52373875 | M2: =3*(M3-M4)/M5 -> -0.3257531
A3: AL | B3: =LN(F3) -> 4.1279727 | C3: =LN(G3) -> 1.4136663 | D3: 62.24 | E3: 0.816 | F3: 62.052 | G3: 4.111 | I3: Média | J3: =AVERAGE(B2:B28) -> 3.6750336 | K3: =AVERAGE(C2:C28) -> 1.6686061 | L3: =AVERAGE(D2:D28) -> 40.077222 | M3: =AVERAGE(E2:E28) -> 0.71033333
A4: AM | B4: =LN(F4) -> 3.9379441 | C4: =LN(G4) -> 1.7134375 | D4: 52.968 | E4: 0.786 | F4: 51.313 | G4: 5.548 | I4: Mediana | J4: =MEDIAN(B2:B28) -> 3.5932217 | K4: =MEDIAN(C2:C28) -> 1.7051117 | L4: =MEDIAN(D2:D28) -> 42.947 | M4: =MEDIAN(E2:E28) -> 0.718
A5: AP | B5: =LN(F5) -> 3.5932217 | C5: =LN(G5) -> 1.8000583 | D5: 42.947 | E5: 0.708 | F5: 36.351 | G5: 6.05 | I5: DP | J5: =_xlfn.STDEV.S(B2:B28) -> 0.50443206 | K5: =_xlfn.STDEV.S(C2:C28) -> 0.18541092 | L5: =_xlfn.STDEV.S(D2:D28) -> 16.438221 | M5: =_xlfn.STDEV.S(E2:E28) -> 0.070605622
A6: BA | B6: =LN(F6) -> 4.2511631 | C6: =LN(G6) -> 1.4940271 | D6: 55.316 | E6: 0.775 | F6: 70.187 | G6: 4.455
A7: CE | B7: =LN(F7) -> 4.1738641 | C7: =LN(G7) -> 1.4861397 | D7: 57 | E7: 0.816 | F7: 64.966 | G7: 4.42
A8: DF | B8: =LN(F8) -> 3.1780538 | C8: =LN(G8) -> 2.110092 | D8: 16.072 | E8: 0.781 | F8: 24 | G8: 8.249 | J8: Y = a + b1X1 + b2X2 + b3X3
A9: ES | B9: =LN(F9) -> 3.5178242 | C9: =LN(G9) -> 1.7752913 | D9: 28.04 | E9: 0.651 | F9: 33.711 | G9: 5.902 | J9: ln(Y) = a + b1X1 + b2X2 + b3X3
A10: GO | B10: =LN(F10) -> 3.2005082 | C10: =LN(G10) -> 1.7337772 | D10: 26.65 | E10: 0.648 | F10: 24.545 | G10: 5.662
A11: MA | B11: =LN(F11) -> 4.4508528 | C11: =LN(G11) -> 1.3785142 | D11: 66.813 | E11: 0.758 | F11: 85.7 | G11: 3.969 | J11: α | K11: β1 | L11: β2 | M11: β3
A12: MG | B12: =LN(F12) -> 3.4134224 | C12: =LN(G12) -> 1.7268653 | D12: 29.766 | E12: 0.671 | F12: 30.369 | G12: 5.623 | I12: ANTES | J12: -5.8231536 | K12: -0.70330149 | L12: 1.1012158 | M12: 13.947192
A13: MS | B13: =LN(F13) -> 3.2795946 | C13: =LN(G13) -> 1.745541 | D13: 28.66 | E13: 0.692 | F13: 26.565 | G13: 5.729 | I13: DEPOIS (Y vira Log) | J13: 2.2317547 | K13: -0.02529569 | L13: 0.024389152 | M13: 0.84791271
A14: MT | B14: =LN(F14) -> 3.419332 | C14: =LN(G14) -> 1.7051117 | D14: 27.784 | E14: 0.685 | F14: 30.549 | G14: 5.502 | I14: DEPOIS (X2 vira Log) | J14: 2.4935443 | K14: -0.23787594 | L14: 0.023148931 | M14: 0.91600052
A15: PA | B15: =LN(F15) -> 3.5722052 | C15: =LN(G15) -> 1.6104374 | D15: 51.887 | E15: 0.744 | F15: 35.595 | G15: 5.005
A16: PB | B16: =LN(F16) -> 4.3530483 | C16: =LN(G16) -> 1.4653366 | D16: 55.262 | E16: 0.734 | F16: 77.715 | G16: 4.329 | I16: PROCESSO DE ALTERAÇÃO DE FORMA FUNCIONAL DA VARIÁVEL Y (ANAMORFOSE)
A17: PE | B17: =LN(F17) -> 3.9999973 | C17: =LN(G17) -> 1.6199821 | D17: 51.306 | E17: 0.795 | F17: 54.598 | G17: 5.053 | H17: ANTES
A18: PI | B18: =LN(F18) -> 4.2977343 | C18: =LN(G18) -> 1.3734624 | D18: 61.811 | E18: 0.796 | F18: 73.533 | G18: 3.949 | H18: β1 | I18: -0.70330149 | J18: <--- O aumento de 1 ANO na escolaridade média reduz em 0,7 o número de óbitos a cada 1.000 crianças
A19: PR | B19: =LN(F19) -> 3.1581487 | C19: =LN(G19) -> 1.7885878 | D19: 23.694 | E19: 0.652 | F19: 23.527 | G19: 5.981 | H19: β2 | I19: 1.1012158 | J19: <--- O aumento em 1 PONTO PERCENTUAL no percentual de pobres aumenta em 1,10 o número de óbitos a cada 1.000 crianças
A20: RJ | B20: =LN(F20) -> 3.1385331 | C20: =LN(G20) -> 1.9789304 | D20: 19.228 | E20: 0.664 | F20: 23.07 | G20: 7.235 | H20: β3 | I20: 13.947192 | J20: <--- O aumento em 0,01 UNIDADES no índice de Theil aumenta em (13,95 / 100 = 0,1395) o número de óbitos a cada 1.000 crianças
A21: RN | B21: =LN(F21) -> 4.2152634 | C21: =LN(G21) -> 1.5993876 | D21: 50.634 | E21: 0.731 | F21: 67.712 | G21: 4.95
A22: RO | B22: =LN(F22) -> 3.5932492 | C22: =LN(G22) -> 1.5808327 | D22: 35.203 | E22: 0.639 | F22: 36.352 | G22: 4.859
A23: RR | B23: =LN(F23) -> 3.6681664 | C23: =LN(G23) -> 1.7371273 | D23: 35.897 | E23: 0.643 | F23: 39.18 | G23: 5.681 | H23: DEPOIS (Y vira Log)
A24: RS | B24: =LN(F24) -> 2.848913 | C24: =LN(G24) -> 1.8587949 | D24: 19.687 | E24: 0.617 | F24: 17.269 | G24: 6.416 | H24: β1 | I24: -0.02529569 | J24: -0.02529569 | K24: <--- O aumento de 1 ANO na escolaridade média reduz em 2,5% o número de óbitos a cada 1.000 crianças
A25: SC | B25: =LN(F25) -> 2.8212003 | C25: =LN(G25) -> 1.824388 | D25: 16.244 | E25: 0.551 | F25: 16.797 | G25: 6.199 | H25: β2 | I25: 0.024389152 | J25: 0.024389152 | K25: <--- O aumento em 1 PONTO PERCENTUAL no percentual de pobres aumenta em 2,4% o número de óbitos a cada 1.000 crianças
A26: SE | B26: =LN(F26) -> 4.2858461 | C26: =LN(G26) -> 1.5456458 | D26: 53.993 | E26: 0.763 | F26: 72.664 | G26: 4.691 | H26: β3 | I26: 0.84791271 | J26: 0.84791271 | K26: <--- O aumento em 0,01 UNIDADES no índice de Theil aumenta em (84,8 / 100 = 0,848%) o número de óbitos a cada 1.000 crianças
A27: SP | B27: =LN(F27) -> 2.9961322 | C27: =LN(G27) -> 1.9238106 | D27: 14.369 | E27: 0.607 | F27: 20.008 | G27: 6.847 | H27: α | I27: =EXP(J13) -> 9.3161988 | J27: <--- É esperado que, se X1=X2=X3 = 0, então o número de óbitos a cada 1.000 crianças seria 9.32
A28: TO | B28: =LN(F28) -> 4.2050358 | C28: =LN(G28) -> 1.5385862 | D28: 50.785 | E28: 0.738 | F28: 67.023 | G28: 4.658
H29: DEPOIS (X2 também vira Log)
H30: β1 | I30: -0.23787594 | J30: -0.23787594 | K30: <--- O aumento em UM PORCENTO na escolaridade média reduz em 23,8% o número de óbitos a cada 1.000 crianças
H31: β2 | I31: 0.023148931 | J31: 0.023148931 | K31: <--- O aumento em 1 PONTO PERCENTUAL no percentual de pobres aumenta em 2,3% o número de óbitos a cada 1.000 crianças
H32: β3 | I32: 0.91600052 | J32: 0.91600052 | K32: <--- O aumento em 0,01 UNIDADES no índice de Theil aumenta em (176,4 / 100 = 1,764%) o número de óbitos a cada 1.000 crianças
H33: α | I33: =EXP(J14) -> 12.104101 | J33: <--- É esperado que, se X1=X2=X3 = 0, então o número de óbitos a cada 1.000 crianças seria 12.1
H34: NÃO FAÇA TRANSFORMAÇÃO LOGARITMICA EM VARIÁVEIS PERCENTUAIS!!!

Sheet Matrizes (2)
A2: Matriz y | B2: 1º passo - compor a MATRIZ X | G2: 2º passo - inverter a matriz X para obter a MATRIZ XT
A3: ='Dados (2)'!B2 -> 3.5286814 | B3: 1 | C3: ='Dados (2)'!C2 -> 1.5245334 | D3: ='Dados (2)'!D2 -> 47.829 | E3: ='Dados (2)'!E2 -> 0.718 | G3: {=TRANSPOSE(B3:E29)} -> 1 | H3: 1 | I3: 1 | J3: 1 | K3: 1 | L3: 1 | M3: 1 | N3: 1 | O3: 1 | P3: 1 | Q3: 1 | R3: 1 | S3: 1 | T3: 1 | U3: 1 | V3: 1 | W3: 1 | X3: 1 | Y3: 1 | Z3: 1 | AA3: 1 | AB3: 1 | AC3: 1 | AD3: 1 | AE3: 1 | AF3: 1 | AG3: 1
A4: ='Dados (2)'!B3 -> 4.1279727 | B4: 1 | C4: ='Dados (2)'!C3 -> 1.4136663 | D4: ='Dados (2)'!D3 -> 62.24 | E4: ='Dados (2)'!E3 -> 0.816 | G4: 1.5245334 | H4: 1.4136663 | I4: 1.7134375 | J4: 1.8000583 | K4: 1.4940271 | L4: 1.4861397 | M4: 2.110092 | N4: 1.7752913 | O4: 1.7337772 | P4: 1.3785142 | Q4: 1.7268653 | R4: 1.745541 | S4: 1.7051117 | T4: 1.6104374 | U4: 1.4653366 | V4: 1.6199821 | W4: 1.3734624 | X4: 1.7885878 | Y4: 1.9789304 | Z4: 1.5993876 | AA4: 1.5808327 | AB4: 1.7371273 | AC4: 1.8587949 | AD4: 1.824388 | AE4: 1.5456458 | AF4: 1.9238106 | AG4: 1.5385862
A5: ='Dados (2)'!B4 -> 3.9379441 | B5: 1 | C5: ='Dados (2)'!C4 -> 1.7134375 | D5: ='Dados (2)'!D4 -> 52.968 | E5: ='Dados (2)'!E4 -> 0.786 | G5: 47.829 | H5: 62.24 | I5: 52.968 | J5: 42.947 | K5: 55.316 | L5: 57 | M5: 16.072 | N5: 28.04 | O5: 26.65 | P5: 66.813 | Q5: 29.766 | R5: 28.66 | S5: 27.784 | T5: 51.887 | U5: 55.262 | V5: 51.306 | W5: 61.811 | X5: 23.694 | Y5: 19.228 | Z5: 50.634 | AA5: 35.203 | AB5: 35.897 | AC5: 19.687 | AD5: 16.244 | AE5: 53.993 | AF5: 14.369 | AG5: 50.785
A6: ='Dados (2)'!B5 -> 3.5932217 | B6: 1 | C6: ='Dados (2)'!C5 -> 1.8000583 | D6: ='Dados (2)'!D5 -> 42.947 | E6: ='Dados (2)'!E5 -> 0.708 | G6: 0.718 | H6: 0.816 | I6: 0.786 | J6: 0.708 | K6: 0.775 | L6: 0.816 | M6: 0.781 | N6: 0.651 | O6: 0.648 | P6: 0.758 | Q6: 0.671 | R6: 0.692 | S6: 0.685 | T6: 0.744 | U6: 0.734 | V6: 0.795 | W6: 0.796 | X6: 0.652 | Y6: 0.664 | Z6: 0.731 | AA6: 0.639 | AB6: 0.643 | AC6: 0.617 | AD6: 0.551 | AE6: 0.763 | AF6: 0.607 | AG6: 0.738
A7: ='Dados (2)'!B6 -> 4.2511631 | B7: 1 | C7: ='Dados (2)'!C6 -> 1.4940271 | D7: ='Dados (2)'!D6 -> 55.316 | E7: ='Dados (2)'!E6 -> 0.775
A8: ='Dados (2)'!B7 -> 4.1738641 | B8: 1 | C8: ='Dados (2)'!C7 -> 1.4861397 | D8: ='Dados (2)'!D7 -> 57 | E8: ='Dados (2)'!E7 -> 0.816
A9: ='Dados (2)'!B8 -> 3.1780538 | B9: 1 | C9: ='Dados (2)'!C8 -> 2.110092 | D9: ='Dados (2)'!D8 -> 16.072 | E9: ='Dados (2)'!E8 -> 0.781
A10: ='Dados (2)'!B9 -> 3.5178242 | B10: 1 | C10: ='Dados (2)'!C9 -> 1.7752913 | D10: ='Dados (2)'!D9 -> 28.04 | E10: ='Dados (2)'!E9 -> 0.651
A11: ='Dados (2)'!B10 -> 3.2005082 | B11: 1 | C11: ='Dados (2)'!C10 -> 1.7337772 | D11: ='Dados (2)'!D10 -> 26.65 | E11: ='Dados (2)'!E10 -> 0.648
A12: ='Dados (2)'!B11 -> 4.4508528 | B12: 1 | C12: ='Dados (2)'!C11 -> 1.3785142 | D12: ='Dados (2)'!D11 -> 66.813 | E12: ='Dados (2)'!E11 -> 0.758 | G12: 3º passo - multiplicar matrizes e obter a MATRIZ XTX | N12: 4º passo - inverter a matriz XTX
A13: ='Dados (2)'!B12 -> 3.4134224 | B13: 1 | C13: ='Dados (2)'!C12 -> 1.7268653 | D13: ='Dados (2)'!D12 -> 29.766 | E13: ='Dados (2)'!E12 -> 0.671 | G13: {=MMULT(G3:AG6,B3:E29)} -> 27 | H13: 45.052364 | I13: 1082.085 | J13: 19.179 | N13: {=MINVERSE(G13:J16)} -> 24.756654 | O13: -12.170422 | P13: -0.13315596 | Q13: 1.3015645
A14: ='Dados (2)'!B13 -> 3.2795946 | B14: 1 | C14: ='Dados (2)'!C13 -> 1.745541 | D14: ='Dados (2)'!D13 -> 28.66 | E14: ='Dados (2)'!E13 -> 0.692 | G14: 45.052364 | H14: 76.068457 | I14: 1734.5585 | J14: 31.812673 | N14: -12.170422 | O14: 8.3914379 | P14: 0.11586142 | Q14: -9.1154193
A15: ='Dados (2)'!B14 -> 3.419332 | B15: 1 | C15: ='Dados (2)'!C14 -> 1.7051117 | D15: ='Dados (2)'!D14 -> 27.784 | E15: ='Dados (2)'!E14 -> 0.685 | G15: 1082.085 | H15: 1734.5585 | I15: 50392.554 | J15: 792.56494 | N15: -0.13315596 | O15: 0.11586142 | P15: 0.0019828859 | Q15: -0.1965833
A16: ='Dados (2)'!B15 -> 3.5722052 | B16: 1 | C16: ='Dados (2)'!C15 -> 1.6104374 | D16: ='Dados (2)'!D15 -> 51.887 | E16: ='Dados (2)'!E15 -> 0.744 | G16: 19.179 | H16: 31.812673 | I16: 792.56494 | J16: 13.753097 | N16: 1.3015645 | O16: -9.1154193 | P16: -0.1965833 | Q16: 30.671505
A17: ='Dados (2)'!B16 -> 4.3530483 | B17: 1 | C17: ='Dados (2)'!C16 -> 1.4653366 | D17: ='Dados (2)'!D16 -> 55.262 | E17: ='Dados (2)'!E16 -> 0.734
A18: ='Dados (2)'!B17 -> 3.9999973 | B18: 1 | C18: ='Dados (2)'!C17 -> 1.6199821 | D18: ='Dados (2)'!D17 -> 51.306 | E18: ='Dados (2)'!E17 -> 0.795
A19: ='Dados (2)'!B18 -> 4.2977343 | B19: 1 | C19: ='Dados (2)'!C18 -> 1.3734624 | D19: ='Dados (2)'!D18 -> 61.811 | E19: ='Dados (2)'!E18 -> 0.796 | G19: 5º passo - multipliar XT pela matriz y | M19: 6º passo - calcular os coeficientes beta, conforme a fórmula acima
A20: ='Dados (2)'!B19 -> 3.1581487 | B20: 1 | C20: ='Dados (2)'!C19 -> 1.7885878 | D20: ='Dados (2)'!D19 -> 23.694 | E20: ='Dados (2)'!E19 -> 0.652 | G20: {=MMULT(G3:AG6,A3:A29)} -> 99.225908 | M20: α | N20: {=MMULT(N13:Q16,G20:G23)} -> 2.4935443
A21: ='Dados (2)'!B20 -> 3.1385331 | B21: 1 | C21: ='Dados (2)'!C20 -> 1.9789304 | D21: ='Dados (2)'!D20 -> 19.228 | E21: ='Dados (2)'!E20 -> 0.664 | G21: 163.53881 | L21: Educacao | M21: β1 | N21: -0.23787594 | O21: <--- O aumento de 1 ANO na escolaridade média reduz em 0,7 o número de óbitos a cada 1.000 crianças
A22: ='Dados (2)'!B21 -> 4.2152634 | B22: 1 | C22: ='Dados (2)'!C21 -> 1.5993876 | D22: ='Dados (2)'!D21 -> 50.634 | E22: ='Dados (2)'!E21 -> 0.731 | G22: 4178.1408 | L22: Pobres | M22: β2 | N22: 0.023148931 | O22: <--- O aumento em 1 PONTO PERCENTUAL no percentual de pobres aumenta em 1,10 o número de óbitos a cada 1.000 crianças
A23: ='Dados (2)'!B22 -> 3.5932492 | B23: 1 | C23: ='Dados (2)'!C22 -> 1.5808327 | D23: ='Dados (2)'!D22 -> 35.203 | E23: ='Dados (2)'!E22 -> 0.639 | G23: 71.201092 | L23: Theil | M23: β3 | N23: 0.91600052 | O23: <--- O aumento em 0,01 UNIDADES no índice de Theil aumenta em (13,95 / 100 = 0,1395) o número de óbitos a cada 1.000 crianças
A24: ='Dados (2)'!B23 -> 3.6681664 | B24: 1 | C24: ='Dados (2)'!C23 -> 1.7371273 | D24: ='Dados (2)'!D23 -> 35.897 | E24: ='Dados (2)'!E23 -> 0.643
A25: ='Dados (2)'!B24 -> 2.848913 | B25: 1 | C25: ='Dados (2)'!C24 -> 1.8587949 | D25: ='Dados (2)'!D24 -> 19.687 | E25: ='Dados (2)'!E24 -> 0.617 | M25: Mortalidade = alfa + b1 (Educacao) + b2 (Pobres) + b3 (Theil)
A26: ='Dados (2)'!B25 -> 2.8212003 | B26: 1 | C26: ='Dados (2)'!C25 -> 1.824388 | D26: ='Dados (2)'!D25 -> 16.244 | E26: ='Dados (2)'!E25 -> 0.551 | G26: yTy | I26: βTXTy
A27: ='Dados (2)'!B26 -> 4.2858461 | B27: 1 | C27: ='Dados (2)'!C26 -> 1.5456458 | D27: ='Dados (2)'!D26 -> 53.993 | E27: ='Dados (2)'!E26 -> 0.763 | G27: {=MMULT(TRANSPOSE(A3:A29),A3:A29)} -> 371.27429 | I27: {=MMULT(TRANSPOSE(N20:N23),MMULT(G3:AG6,A3:A29))} -> 370.46198 | M27: Mortalidade: óbitos de crianças até 5 anos em cada 1.000
A28: ='Dados (2)'!B27 -> 2.9961322 | B28: 1 | C28: ='Dados (2)'!C27 -> 1.9238106 | D28: ='Dados (2)'!D27 -> 14.369 | E28: ='Dados (2)'!E27 -> 0.607 | M28: Educacao: número médio de anos estudados
A29: ='Dados (2)'!B28 -> 4.2050358 | B29: 1 | C29: ='Dados (2)'!C28 -> 1.5385862 | D29: ='Dados (2)'!D28 -> 50.785 | E29: ='Dados (2)'!E28 -> 0.738 | M29: Pobres: percentual de pobres
M30: Theil: índice de desigualdade (0 a 1)
A31: =COUNTA(A3:A29) -> 27 | B31: n | G31: STQ | H31: =G27-A31*A32^2 -> 6.6157444
A32: =AVERAGE(A3:A29) -> 3.6750336 | B32: Y barra | G32: SQReg | H32: =I27-A31*A32^2 -> 5.8034323
G33: SQRes | H33: =G27-I27 -> 0.81231203
H34: =H32+H33=H31 -> TRUE
G35: R² | H35: =H32/H31 -> 0.87721532
C37: TABELA ANOVA
C38: Fonte | D38: GL | E38: SQ | F38: QM | G38: F(calc) | H38: F(crit)
C39: Regressão | D39: 3 | E39: =H32 -> 5.8034323 | F39: =E39/D39 -> 1.9344774 | G39: =F39/F40 -> 54.773264 | H39: =FINV(5%,D39,D40) -> 3.0279984
C40: Resíduos | D40: =A31-(D39+1) -> 23 | E40: =H33 -> 0.81231203 | F40: =E40/D40 -> 0.035317915
C41: Total | D41: =A31-1 -> 26 | E41: =H31 -> 6.6157444 | F41: =E41/D41 -> 0.25445171
J42: R² adj. | K42: =1-(F40/F41) -> 0.86119993
...
