Workbook

Sheet Questão 1 - Multicolinearidade
B2: Insira seu nome e RA abaixo | D2: Escola Superior de Administração, Marketing e Comunicação (ESAMC) 10175/A - Econometria - 1º Sem. de 2021 - Prof. Pier Francesco De Maria | P2: Você recebeu os dados abaixo, relativos ao número de viagens de ônibus (Y, em milhares de passageiros por hora), à tarifa do ônibus (X1, em R$) e ao preço do litro da gasolina (X2, em R$). Faça o que é pedido abaixo, na ordem.
B4: 101190648 | P4: 1) (2.00 pontos) Estime o modelo de regressão Y = α + β1X1 + β2X2 + e, por meio do método de MQO. Interprete os resultados.
D5: Prova 2 / Parte 1 (Multicolinearidade) | P5: 2) (1.50 pontos) Avalie se o modelo como um todo é significativo (teste-F), construindo a tabela ANOVA.
B6: Este exercício vale 17,5% (dezessete porcento e cinco décimos) da nota da P2. A nota desta prova será ponderada junto às demais notas da Prova 2, compondo a nota da P2. Faça o que é pedido, sempre utilizando (a não ser que seja solicitado o contrário) álgebra matricial. Deixe todas as fórmulas indicadas, sob pena de perder nota! Você recebeu essa prova em 07/05, durante a aula. Faça a QUESTÃO 1 e devolva-a até 14/05, antes do horário da aula (19h30). Ao terminar a sua prova, SALVE O ARQUIVO E ENVIE PARA O E-MAIL pier.francesco@esamc.br! | P6: 3) (2.00 pontos) Avalie se, isoladamente, os coeficientes do modelo são significativos, por meio do teste-T.
P7: 4) (2.00 pontos) Calcule os FIV para X1 e X2. Avalie se, a partir dos mesmos, é possível concluir pela multicolinearidade (SE SIM, INDIQUE QUAL(IS) VARIÁVEL(IS).
P8: 5) (1.50 pontos) Escolha sabiamente uma variável para converter em logaritmo. Depois, re-faça e re-interprete o modelo por MQO.
P9: 6) (1.00 pontos) O que você sugere fazer, diante das evidências encontradas?
P12: Y | Q12: X1 | R12: X2
P13: 2073 | Q13: 0.85 | R13: 0.88
P14: 2136 | Q14: 0.75 | R14: 1.03
P15: 1879 | Q15: 0.6 | R15: 0.91
P16: 938 | Q16: 1 | R16: 0.91
P17: 7343 | Q17: 0.5 | R17: 0.97
P18: 838 | Q18: 0.85 | R18: 0.88
P19: 1648 | Q19: 1 | R19: 0.91
P20: 739 | Q20: 0.75 | R20: 0.89
P21: 1071 | Q21: 1.5 | R21: 0.89
P22: 275 | Q22: 1.5 | R22: 0.89

Sheet Questão 2 - Heterocedasticidade
B2: Insira seu nome e RA abaixo | D2: Escola Superior de Administração, Marketing e Comunicação (ESAMC) 10175/A - Econometria - 1º Sem. de 2021 - Prof. Pier Francesco De Maria | P2: Você recebeu os dados abaixo, relativos ao investimento de empresas (I, em US$ mi), seus valores em ações (V, em US$ mi) e o valor de capital da firma (K, em US$ mi). Faça o que é pedido abaixo, na ordem.
B4: 101190648 | P4: 1) (1.00 pontos) Estime o modelo de regressão I = α + β1V + β2K + e, por meio do método de MQO. Interprete os resultados.
D5: Prova 2 / Parte 2 (Heterocedasticidade) | P5: 2) (1.00 pontos) Construa a tabela ANOVA (e interprete o teste-F), calcule o R² ajustado e avalie a significância dos coeficientes (teste-T).
B6: Este exercício vale 17,5% (dezessete porcento e cinco décimos) da nota da P2. A nota desta prova será ponderada junto às demais notas da Prova 2, compondo a nota da P2. Faça o que é pedido, sempre utilizando (a não ser que seja solicitado o contrário) álgebra matricial. Deixe todas as fórmulas indicadas, sob pena de perder nota! Você recebeu essa prova em 07/05, durante a aula. Faça a QUESTÃO 2 e devolva-a até 21/05, antes do horário da aula (19h30). Ao terminar a sua prova, SALVE O ARQUIVO E ENVIE PARA O E-MAIL pier.francesco@esamc.br! | P6: 3) (1.50 pontos) Realize a avaliação gráfica e conclua se há ou não suspeita de heterocedasticidade.
P7: 4) (2.00 pontos) Realize o teste de Breusch-Pagan e o teste de White. O que você conclui, a partir dos resultados?
P8: 5) (2.00 pontos) Aplique o método dos MQGF e obtenha os novos estimadores da regressão. Compare resultados com o item (1).
P9: 6) (1.50 pontos) Escolha sabiamente uma variável para converter em logaritmo. Avalie se, após fazer MQO, ainda persiste a heterocedasticidade.
P10: 7) (1.00 pontos) O que você consegue concluir, diante das evidências encontradas?
P12: I | Q12: V | R12: K
P13: 33.1 | Q13: 1170.6 | R13: 97.8
P14: 80 | Q14: 1588 | R14: 287.8
P15: 67 | Q15: 1687.2 | R15: 321.3
P16: 82 | Q16: 1749.4 | R16: 319.9
P17: 72 | Q17: 1834.1 | R17: 220.9
P18: 45 | Q18: 2015.8 | R18: 104.4
P19: 44.6 | Q19: 2039.7 | R19: 156.2
P20: 98 | Q20: 2132.2 | R20: 186.6

Sheet RESOLUÇÃO QUESTÃO 1
A1: Y | C1: X1 | D1: X2 | F1: 1 | G1: 1 | H1: 1 | I1: 1 | J1: 1 | K1: 1 | L1: 1 | M1: 1 | N1: 1 | O1: 1
A2: 2073 | B2: 1 | C2: 0.85 | D2: 0.88 | F2: 0.85 | G2: 0.75 | H2: 0.6 | I2: 1 | J2: 0.5 | K2: 0.85 | L2: 1 | M2: 0.75 | N2: 1.5 | O2: 1.5 | V2: RESUMO DOS RESULTADOS
A3: 2136 | B3: 1 | C3: 0.75 | D3: 1.03 | F3: 0.88 | G3: 1.03 | H3: 0.91 | I3: 0.91 | J3: 0.97 | K3: 0.88 | L3: 0.91 | M3: 0.89 | N3: 0.89 | O3: 0.89
A4: 1879 | B4: 1 | C4: 0.6 | D4: 0.91 | V4: Estatística de regressão
A5: 938 | B5: 1 | C5: 1 | D5: 0.91 | F5: {=MMULT(F1:O3,B2:D11)} -> 10 | G5: 9.3 | H5: 9.16 | J5: {=MINVERSE(F5:H7)} -> 56.696603 | K5: -4.3414316 | L5: -57.378899 | N5: {=MMULT(F1:O3,A2:A11)} -> 18940 | O5: 18940 | P5: 18940 | V5: R múltiplo | W5: 0.65831616
A6: 7343 | B6: 1 | C6: 0.5 | D6: 0.97 | F6: 9.3 | G6: 9.68 | H6: 8.457 | J6: -4.3414316 | K6: 1.18209 | L6: 3.5393973 | N6: 14034.5 | O6: 14034.5 | P6: 14034.5 | V6: R-Quadrado | W6: 0.43338017
A7: 838 | B7: 1 | C7: 0.85 | D7: 0.88 | F7: 9.16 | G7: 8.457 | H7: 8.4112 | J7: -57.378899 | K7: 3.5393973 | L7: 59.047226 | N7: 17803.27 | O7: 17803.27 | P7: 17803.27 | V7: R-quadrado ajustado | W7: 0.27148879
A8: 1648 | B8: 1 | C8: 1 | D8: 0.91 | V8: Erro padrão | W8: 1718.9778
A9: 739 | B9: 1 | C9: 0.75 | D9: 0.89 | F9: α | G9: {=MMULT(J5:L7,N5:P7)} -> -8628.1946 | I9: n | J9: ybarra | L9: yTy | M9: βTXTy | V9: Observações | W9: 10
A10: 1071 | B10: 1 | C10: 1.5 | D10: 0.89 | F10: β1 | G10: -2623.827 | I10: =COUNT(A2:A11) -> 10 | J10: =AVERAGE(A2:A11) -> 1894 | L10: {=MMULT(TRANSPOSE(A2:A11),A2:A11)} -> 72376894 | M10: {=MMULT(TRANSPOSE(G9:G11),MMULT(F1:O3,A2:A11))} -> 51692701
A11: 275 | B11: 1 | C11: 1.5 | D11: 0.89 | F11: β2 | G11: 14151.041 | V11: ANOVA
W12: gl | X12: SQ | Y12: MQ | Z12: F | AA12: F de significação
F13: STQ | G13: =L10-I10*J10^2 -> 36504534 | J13: TABELA ANOVA | V13: Regressão | W13: 2 | X13: 15820341 | Y13: 7910170.5 | Z13: 2.6769811 | AA13: 0.13693712
A14: Interpretação do modelo | F14: SQReg | G14: =M10-I10*J10^2 -> 15820341 | J14: Fonte | K14: GL | L14: SQ | M14: QM | N14: F(calc) | O14: F(crit) | Q14: O modelo como um todo é significante. Ou seja, rejeitamos H0, pois F(calc) é maior do que F(crit). | V14: Resíduo | W14: 7 | X14: 20684193 | Y14: 2954884.7
A15: Y = -8628,1947 -2623,8271*X1 +14151,05*X2 + e | F15: SQRes | G15: =L10-M10 -> 20684193 | J15: Regressão | K15: 2 | L15: =G14 -> 15820341 | M15: =L15/K15 -> 7910170.5 | N15: =M15/M16 -> 2.6769811 | O15: =_xlfn.F.INV(5%,K15,K16) -> 0.051670995 | V15: Total | W15: 9 | X15: 36504534
A16: A cada 1 p.p de aumento em X1 há dimunuição de 2623,83 em Y | F16: Resultado | G16: =G14+G15=G13 -> TRUE | J16: Resíduos | K16: =I10-(K15+1) -> 7 | L16: =G15 -> 20684193 | M16: =L16/K16 -> 2954884.7
A17: A cada 1 p.p de aumento em X2 há aumento de 14151,05 em Y | F17: R² | G17: =G14/G13 -> 0.43338017 | J17: Total | K17: =I10-1 -> 9 | L17: =G13 -> 36504534 | M17: =L17/K17 -> 4056059.3 | W17: Coeficientes | X17: Erro padrão | Y17: Stat t | Z17: valor-P | AA17: 95% inferiores | AB17: 95% superiores | AC17: Inferior 95,0% | AD17: Superior 95,0%
F18: R² ajustado | G18: =1-(M16/M17) -> 0.27148879 | V18: Interseção | W18: -8628.1946 | X18: 12943.412 | Y18: -0.66660896 | Z18: 0.52637542 | AA18: -39234.501 | AB18: 21978.112 | AC18: -39234.501 | AD18: 21978.112
J19: Matriz VAR-COVAR | V19: X1 | W19: -2623.827 | X19: 1868.9408 | Y19: -1.4039113 | Z19: 0.20312186 | AA19: -7043.1697 | AB19: 1795.5156 | AC19: -7043.1697 | AD19: 1795.5156
F20: Sigma^² | G20: =(G13-G14)/K16 -> 2954884.7 | J20: {=J5:L7*G20} -> 1.6753192e+08 | K20: -12828430 | L20: -1.6954803e+08 | V20: X2 | W20: 14151.041 | X20: 13209.002 | Y20: 1.0713179 | Z20: 0.31956746 | AA20: -17083.286 | AB20: 45385.369 | AC20: -17083.286 | AD20: 45385.369
J21: -12828430 | K21: 3492939.6 | L21: 10458511
J22: -1.6954803e+08 | K22: 10458511 | L22: 1.7447775e+08
K24: α | L24: β1 | M24: β2
K25: -8628.1946 | L25: -2623.827 | M25: 14151.041
J26: t(calc) | K26: =K25/SQRT(J20) -> -0.66660896 | L26: =L25/SQRT(K21) -> -1.4039113 | M26: =M25/SQRT(L22) -> 1.0713179 | O26: β2 é significativo. Apenas β1 não é siginficativo isoladamente, portanto não rejeitamos H0 para ele.
J27: t(crit) | K27: =_xlfn.T.INV(5%,K16) -> -1.8945786
A30: Y (X1) | C30: X2 | E30: 1 | F30: 1 | G30: 1 | H30: 1 | I30: 1 | J30: 1 | K30: 1 | L30: 1 | M30: 1 | N30: 1 | V30: RESUMO DOS RESULTADOS
A31: 0.85 | B31: 1 | C31: 0.88 | E31: 0.88 | F31: 1.03 | G31: 0.91 | H31: 0.91 | I31: 0.97 | J31: 0.88 | K31: 0.91 | L31: 0.89 | M31: 0.89 | N31: 0.89
A32: 0.75 | B32: 1 | C32: 1.03 | V32: Estatística de regressão
A33: 0.6 | B33: 1 | C33: 0.91 | E33: {=MMULT(E30:N31,B31:C40)} -> 10 | F33: 9.16 | H33: {=MINVERSE(E33:F34)} -> 40.751938 | I33: -44.379845 | K33: {=MMULT(E30:N31,A31:A40)} -> 9.3 | L33: 9.3 | V33: R múltiplo | W33: 0.42364716
A34: 1 | B34: 1 | C34: 0.91 | E34: 9.16 | F34: 8.4112 | H34: -44.379845 | I34: 48.449612 | K34: 8.457 | L34: 8.457 | V34: R-Quadrado | W34: 0.17947691
A35: 0.5 | B35: 1 | C35: 0.97 | V35: R-quadrado ajustado | W35: 0.076911528
A36: 0.85 | B36: 1 | C36: 0.88 | E36: α | F36: {=MMULT(H33:I34,K33:L34)} -> 3.6726744 | H36: n | I36: ybarra | K36: yTy | L36: βTXTy | V36: Erro padrão | W36: 0.32518443
A37: 1 | B37: 1 | C37: 0.91 | E37: β1 | F37: -2.994186 | H37: =COUNT(A31:A40) -> 10 | I37: =AVERAGE(A31:A40) -> 0.93 | K37: {=MMULT(TRANSPOSE(A31:A40),A31:A40)} -> 9.68 | L37: {=MMULT(TRANSPOSE(F36:F37),MMULT(E30:N31,A31:A40))} -> 8.8340407 | V37: Observações | W37: 10
A38: 0.75 | B38: 1 | C38: 0.89
A39: 1.5 | B39: 1 | C39: 0.89 | E39: STQ | F39: =K37-H37*I37^2 -> 1.031 | V39: ANOVA
A40: 1.5 | B40: 1 | C40: 0.89 | E40: SQReg | F40: =L37-H37*I37^2 -> 0.1850407 | W40: gl | X40: SQ | Y40: MQ | Z40: F | AA40: F de significação
E41: SQRes | F41: =K37-L37 -> 0.8459593 | V41: Regressão | W41: 1 | X41: 0.1850407 | Y41: 0.1850407 | Z41: 1.749878 | AA41: 0.2224525
E42: Resultado | F42: =F40+F41=F39 -> TRUE | V42: Resíduo | W42: 8 | X42: 0.8459593 | Y42: 0.10574491
E43: R² | F43: =F40/F39 -> 0.17947691 | V43: Total | W43: 9 | X43: 1.031
...

Sheet RESOLUÇÃO QUESTÃO 2
A1: I(y) | C1: V(X1) | D1: K(X2) | E1: ê | F1: ê^2 | H1: 1 | I1: 1 | J1: 1 | K1: 1 | L1: 1 | M1: 1 | N1: 1 | O1: 1 | X1: RESUMO DOS RESULTADOS
A2: 33.1 | B2: 1 | C2: 1170.6 | D2: 97.8 | E2: {=A2-($M$9+SUMPRODUCT(TRANSPOSE($M$10:$M$11),C2:D2))} -> 3.9343507 | F2: =E2^2 -> 15.479116 | H2: 1170.6 | I2: 1588 | J2: 1687.2 | K2: 1749.4 | L2: 1834.1 | M2: 2015.8 | N2: 2039.7 | O2: 2132.2
A3: 80 | B3: 1 | C3: 1588 | D3: 287.8 | E3: {=A3-($M$9+SUMPRODUCT(TRANSPOSE($M$10:$M$11),C3:D3))} -> 7.6233093 | F3: =E3^2 -> 58.114844 | H3: 97.8 | I3: 287.8 | J3: 321.3 | K3: 319.9 | L3: 220.9 | M3: 104.4 | N3: 156.2 | O3: 186.6 | X3: Estatística de regressão
A4: 67 | B4: 1 | C4: 1687.2 | D4: 321.3 | E4: {=A4-($M$9+SUMPRODUCT(TRANSPOSE($M$10:$M$11),C4:D4))} -> -13.722475 | F4: =E4^2 -> 188.30633 | X4: R múltiplo | Y4: 0.76639439
A5: 82 | B5: 1 | C5: 1749.4 | D5: 319.9 | E5: {=A5-($M$9+SUMPRODUCT(TRANSPOSE($M$10:$M$11),C5:D5))} -> -0.25737217 | F5: =E5^2 -> 0.066240431 | H5: {=MMULT(H1:O3,B2:D9)} -> 8 | I5: 14217 | J5: 1694.9 | L5: {=MINVERSE(H5:J7)} -> 5.7694577 | M5: -0.0027015923 | N5: -0.0039808393 | X5: R-Quadrado | Y5: 0.58736036
A6: 72 | B6: 1 | C6: 1834.1 | D6: 220.9 | E6: {=A6-($M$9+SUMPRODUCT(TRANSPOSE($M$10:$M$11),C6:D6))} -> 3.6781979 | F6: =E6^2 -> 13.52914 | H6: 14217 | I6: 25933118 | J6: 3005313.4 | L6: -0.0027015923 | M6: 1.4993701e-06 | N6: 1.7475569e-07 | X6: R-quadrado ajustado | Y6: 0.42230451
A7: 45 | B7: 1 | C7: 2015.8 | D7: 104.4 | E7: {=A7-($M$9+SUMPRODUCT(TRANSPOSE($M$10:$M$11),C7:D7))} -> -9.2517936 | F7: =E7^2 -> 85.595684 | H7: 1694.9 | I7: 3005313.4 | J7: 416877.55 | L7: -0.0039808393 | M7: 1.7475569e-07 | N7: 1.7323862e-05 | X7: Erro padrão | Y7: 16.969787
A8: 44.6 | B8: 1 | C8: 2039.7 | D8: 156.2 | E8: {=A8-($M$9+SUMPRODUCT(TRANSPOSE($M$10:$M$11),C8:D8))} -> -18.880163 | F8: =E8^2 -> 356.46055 | X8: Observações | Y8: 8
A9: 98 | B9: 1 | C9: 2132.2 | D9: 186.6 | E9: {=A9-($M$9+SUMPRODUCT(TRANSPOSE($M$10:$M$11),C9:D9))} -> 26.875946 | F9: =E9^2 -> 722.31647 | H9: {=MMULT(H1:O3,A2:A9)} -> 521.7 | I9: 521.7 | J9: 521.7 | L9: α | M9: {=MMULT(L5:N7,H9:J11)} -> -20.212138 | O9: Y = -20,2121 +0,0283 *X1 + 0,16505*X2 + e
H10: 944972.48 | I10: 944972.48 | J10: 944972.48 | L10: β1 | M10: 0.028391845 | O10: A cada 1 p.p de aumento em X1 há aumento de 0,028392 em Y | X10: ANOVA
H11: 119876.2 | I11: 119876.2 | J11: 119876.2 | L11: β2 | M11: 0.16505413 | O11: A cada 1 p.p de aumento em X2 há aumento de 0,16505 em Y | Y11: gl | Z11: SQ | AA11: MQ | AB11: F | AC11: F de significação
X12: Regressão | Y12: 2 | Z12: 2049.5404 | AA12: 1024.7702 | AB12: 3.5585551 | AC12: 0.10937734
H13: n | I13: ybarra | K13: yTy | L13: βTXTy | X13: Resíduo | Y13: 5 | Z13: 1439.8684 | AA13: 287.97367
H14: =COUNT(A2:A9) -> 8 | I14: =AVERAGE(A2:A9) -> 65.2125 | K14: {=MMULT(TRANSPOSE(A2:A9),A2:A9)} -> 37510.77 | L14: {=MMULT(TRANSPOSE(M9:M11),MMULT(H1:O3,A2:A9))} -> 36070.902 | X14: Total | Y14: 7 | Z14: 3489.4088
H16: STQ | I16: =K14-H14*I14^2 -> 3489.4087 | K16: TABELA ANOVA | Y16: Coeficientes | Z16: Erro padrão | AA16: Stat t | AB16: valor-P | AC16: 95% inferiores | AD16: 95% superiores | AE16: Inferior 95,0% | AF16: Superior 95,0%
H17: SQReg | I17: =L14-H14*I14^2 -> 2049.5404 | K17: Fonte | L17: GL | M17: SQ | N17: QM | O17: F(calc) | P17: F(crit) | X17: Interseção | Y17: -20.212138 | Z17: 40.760912 | AA17: -0.49587061 | AB17: 0.64101027 | AC17: -124.9914 | AD17: 84.567121 | AE17: -124.9914 | AF17: 84.567121
H18: SQRes | I18: =K14-L14 -> 1439.8684 | K18: Regressão | L18: 2 | M18: =I17 -> 2049.5404 | N18: =M18/L18 -> 1024.7702 | O18: =N18/N19 -> 3.5585551 | P18: =_xlfn.F.INV(5%,L18,L19) -> 0.051823112 | R18: O modelo como um todo é significante. Ou seja, rejeitamos H0, pois F(calc) é maior do que F(crit). | X18: VX1) | Y18: 0.028391845 | Z18: 0.020779295 | AA18: 1.3663526 | AB18: 0.23006915 | AC18: -0.025023035 | AD18: 0.081806724 | AE18: -0.025023035 | AF18: 0.081806724
H19: Resultado | I19: =I17+I18=I16 -> TRUE | K19: Resíduos | L19: =H14-(L18+1) -> 5 | M19: =I18 -> 1439.8684 | N19: =M19/L19 -> 287.97367 | X19: K(X2) | Y19: 0.16505413 | Z19: 0.070631551 | AA19: 2.3368329 | AB19: 0.066642187 | AC19: -0.016510048 | AD19: 0.34661832 | AE19: -0.016510048 | AF19: 0.34661832
H20: R² | I20: =I17/I16 -> 0.58736036 | K20: Total | L20: =H14-1 -> 7 | M20: =I16 -> 3489.4087 | N20: =M20/L20 -> 498.48696
H21: R² ajustado | I21: =1-(N19/N20) -> 0.42230451
A24: De acordo com a análise gráfica, há heterocedasticidade em ambas variáveis X, pois a disperssão dos pontos não tem padrão horizontal.
A39: Para o teste Breusch-Pagan (BP) | X39: RESUMO DOS RESULTADOS
A40: ê^2(y) | C40: V(X1) | D40: K(X2) | F40: 1 | G40: 1 | H40: 1 | I40: 1 | J40: 1 | K40: 1 | L40: 1 | M40: 1
A41: =F2 -> 15.479116 | B41: 1 | C41: 1170.6 | D41: 97.8 | F41: 1170.6 | G41: 1588 | H41: 1687.2 | I41: 1749.4 | J41: 1834.1 | K41: 2015.8 | L41: 2039.7 | M41: 2132.2 | X41: Estatística de regressão
A42: =F3 -> 58.114844 | B42: 1 | C42: 1588 | D42: 287.8 | F42: 97.8 | G42: 287.8 | H42: 321.3 | I42: 319.9 | J42: 220.9 | K42: 104.4 | L42: 156.2 | M42: 186.6 | X42: R múltiplo | Y42: 0.63215796
A43: =F4 -> 188.30633 | B43: 1 | C43: 1687.2 | D43: 321.3 | X43: R-Quadrado | Y43: 0.39962369
A44: =F5 -> 0.066240431 | B44: 1 | C44: 1749.4 | D44: 319.9 | F44: {=MMULT(F40:M42,B41:D48)} -> 8 | G44: 14217 | H44: 1694.9 | J44: {=MINVERSE(F44:H46)} -> 5.7694577 | K44: -0.0027015923 | L44: -0.0039808393 | X44: R-quadrado ajustado | Y44: 0.15947316
A45: =F6 -> 13.52914 | B45: 1 | C45: 1834.1 | D45: 220.9 | F45: 14217 | G45: 25933118 | H45: 3005313.4 | J45: -0.0027015923 | K45: 1.4993701e-06 | L45: 1.7475569e-07 | X45: Erro padrão | Y45: 228.86994
A46: =F7 -> 85.595684 | B46: 1 | C46: 2015.8 | D46: 104.4 | F46: 1694.9 | G46: 3005313.4 | H46: 416877.55 | J46: -0.0039808393 | K46: 1.7475569e-07 | L46: 1.7323862e-05 | X46: Observações | Y46: 8
A47: =F8 -> 356.46055 | B47: 1 | C47: 2039.7 | D47: 156.2
A48: =F9 -> 722.31647 | B48: 1 | C48: 2132.2 | D48: 186.6 | F48: {=MMULT(F40:M42,A41:A48)} -> 1439.8684 | G48: 1439.8684 | H48: 1439.8684 | J48: γ | K48: {=MMULT(J44:L46,F48:H50)} -> -627.08716 | X48: ANOVA
F49: 2892785.9 | G49: 2892785.9 | H49: 2892785.9 | J49: δ1 | K49: 0.49655221 | Y49: gl | Z49: SQ | AA49: MQ | AB49: F | AC49: F de significação
F50: 281151.49 | G50: 281151.49 | H50: 281151.49 | J50: δ2 | K50: -0.35572434 | X50: Regressão | Y50: 2 | Z50: 174331.22 | AA50: 87165.611 | AB50: 1.664055 | AC50: 0.27929224
X51: Resíduo | Y51: 5 | Z51: 261907.24 | AA51: 52381.448
F52: n | G52: ybarra | H52: nYmédio² | I52: yTy | J52: βTXTy | X52: Total | Y52: 7 | Z52: 436238.46
F53: =COUNT(A41:A48) -> 8 | G53: =AVERAGE(A41:A48) -> 179.98355 | H53: =COUNTA(A41:A48)*AVERAGE(A41:A48)^2 -> 259152.61 | I53: {=MMULT(TRANSPOSE(A41:A48),A41:A48)} -> 695391.07 | J53: {=MMULT(TRANSPOSE(K48:K50),MMULT(F40:M42,A41:A48))} -> 433483.83
Y54: Coeficientes | Z54: Erro padrão | AA54: Stat t | AB54: valor-P | AC54: 95% inferiores | AD54: 95% superiores | AE54: Inferior 95,0% | AF54: Superior 95,0%
F55: STQ | G55: =I53-F53*G53^2 -> 436238.46 | I55: TABELA ANOVA | X55: Interseção | Y55: -627.08716 | Z55: 549.73862 | AA55: -1.1407006 | AB55: 0.30566848 | AC55: -2040.2353 | AD55: 786.06095 | AE55: -2040.2353 | AF55: 786.06095
F56: SQReg | G56: =J53-F53*G53^2 -> 174331.22 | I56: Fonte | J56: GL | K56: SQ | L56: QM | M56: F(calc) | N56: F(crit) | X56: V(X1) | Y56: 0.49655221 | Z56: 0.28024842 | AA56: 1.7718288 | AB56: 0.13662537 | AC56: -0.22384928 | AD56: 1.2169537 | AE56: -0.22384928 | AF56: 1.2169537
F57: SQRes | G57: =I53-J53 -> 261907.24 | I57: Regressão | J57: 2 | K57: =G56 -> 174331.22 | L57: =K57/J57 -> 87165.611 | M57: =L57/L58 -> 1.664055 | N57: =_xlfn.F.INV(5%,J57,J58) -> 0.051823112 | X57: K(X2) | Y57: -0.35572434 | Z57: 0.95260115 | AA57: -0.37342422 | AB57: 0.72414204 | AC57: -2.8044635 | AD57: 2.0930149 | AE57: -2.8044635 | AF57: 2.0930149
...

Sheet Questão 3 - Autocorrelação
B2: Insira seu nome e RA abaixo | D2: Escola Superior de Administração, Marketing e Comunicação (ESAMC) 10175/A - Econometria - 1º Sem. de 2021 - Prof. Pier Francesco De Maria | P2: Você recebeu os dados abaixo, necessários para construir uma função Cobb-Douglas para Taiwan, entre os anos de 1958 e 1972. Y é o produto real, L são os dias trabalhados e K é o volume de capital. Faça o que é pedido, na ordem.
B4: 101190648 | P4: 1) (1.00 pontos) Estime o modelo de regressão ln(Y) = α + β1ln(L) + β2ln(K) + e, por meio do método de MQO. Interprete os resultados.
D5: Prova 2 / Parte 3 (Autocorrelação serial) | P5: 2) (1.00 pontos) Construa a tabela ANOVA (e interprete o teste-F), calcule o R² ajustado e avalie a significância dos coeficientes (teste-T).
B6: Este exercício vale 17,5% (dezessete porcento e cinco décimos) da nota da P2. A nota desta prova será ponderada junto às demais notas da Prova 2, compondo a nota da P2. Faça o que é pedido, sempre utilizando (a não ser que seja solicitado o contrário) álgebra matricial. Deixe todas as fórmulas indicadas, sob pena de perder nota! Você recebeu essa prova em 07/05, durante a aula. Faça a QUESTÃO 3 e devolva-a até 28/05, antes do horário da aula (19h30). Ao terminar a sua prova, SALVE O ARQUIVO E ENVIE PARA O E-MAIL pier.francesco@esamc.br! | P6: 3) (1.50 pontos) Realize a avaliação gráfica e monte o correlograma; conclua se há ou não suspeita de autocorrelação serial.
P7: 4) (2.00 pontos) Realize o teste de regressores exógenos, bem como o teste Durbin-Watson. O que você conclui, a partir dos resultados?
P8: 5) (1.50 pontos) Realize o teste de Breusch-Godfrey para autocorrelação de 1ª e 2ª ordem. Analise os resultados.
P9: 6) (2.00 pontos) Aplique o método dos MQGF e obtenha os novos estimadores da regressão. Compare resultados com o item (1).
P10: 7) (1.00 pontos) O que você consegue concluir, diante das evidências encontradas?
P12: Ano | Q12: Y | R12: L | S12: K
P13: 1958 | Q13: 16607.7 | R13: 275.5 | S13: 17803.7
P14: 1959 | Q14: 17511.3 | R14: 274.4 | S14: 18096.8
P15: 1960 | Q15: 20171.2 | R15: 269.7 | S15: 18271.8
P16: 1961 | Q16: 20932.9 | R16: 267 | S16: 19167.3
P17: 1962 | Q17: 20406 | R17: 267.8 | S17: 19647.6
P18: 1963 | Q18: 20831.6 | R18: 275 | S18: 20803.5
P19: 1964 | Q19: 24806.3 | R19: 283 | S19: 22076.6
P20: 1965 | Q20: 26465.8 | R20: 300.7 | S20: 23445.2
P21: 1966 | Q21: 27403 | R21: 307.5 | S21: 24939
P22: 1967 | Q22: 28628.7 | R22: 303.7 | S22: 26713.7
P23: 1968 | Q23: 29904.5 | R23: 304.7 | S23: 29957.8
P24: 1969 | Q24: 27508.2 | R24: 298.6 | S24: 31585.9
... P27: 1972 | Q27: 31531.8 | R27: 288.1 | S27: 41794.3

Sheet RESOLUÇÃO QUESTÃO 3
A1: Ano | B1: Y | D1: L | E1: K | F1: ê | H1: 1 | I1: 1 | J1: 1 | K1: 1 | L1: 1 | M1: 1 | N1: 1 | O1: 1 | P1: 1 | Q1: 1 | R1: 1 | S1: 1 | T1: 1 | U1: 1 | V1: 1 | AA1: RESUMO DOS RESULTADOS
A2: 1958 | B2: 16607.7 | C2: 1 | D2: =LN('Questão 3 - Autocorrelação'!R13) -> 5.6185876 | E2: =LN('Questão 3 - Autocorrelação'!S13) -> 9.7871616 | F2: {=B2-($I$9+SUMPRODUCT(TRANSPOSE($I$10:$I$11),D2:E2))} -> -2853.5787 | H2: 5.6185876 | I2: 5.6145869 | J2: 5.5973102 | K2: 5.5872487 | L2: 5.5902404 | M2: 5.6167711 | N2: 5.6454469 | O2: 5.7061131 | P2: 5.7284751 | Q2: 5.7160404 | R2: 5.7193277 | S2: 5.6991049 | T2: 5.6886688 | U2: 5.7004436 | V2: 5.6633076
A3: 1959 | B3: 17511.3 | C3: 1 | D3: =LN('Questão 3 - Autocorrelação'!R14) -> 5.6145869 | E3: =LN('Questão 3 - Autocorrelação'!S14) -> 9.8034904 | F3: {=B3-($I$9+SUMPRODUCT(TRANSPOSE($I$10:$I$11),D3:E3))} -> -2012.3195 | H3: 9.7871616 | I3: 9.8034904 | J3: 9.8131142 | K3: 9.860961 | L3: 9.8857105 | M3: 9.9428765 | N3: 10.002274 | O3: 10.062421 | P3: 10.124188 | Q3: 10.192932 | R3: 10.307545 | S3: 10.360466 | T3: 10.418539 | U3: 10.457999 | V3: 10.640515 | AA3: Estatística de regressão
A4: 1960 | B4: 20171.2 | C4: 1 | D4: =LN('Questão 3 - Autocorrelação'!R15) -> 5.5973102 | E4: =LN('Questão 3 - Autocorrelação'!S15) -> 9.8131142 | F4: {=B4-($I$9+SUMPRODUCT(TRANSPOSE($I$10:$I$11),D4:E4))} -> 1112.423 | AA4: R múltiplo | AB4: 0.95370161
A5: 1961 | B5: 20932.9 | C5: 1 | D5: =LN('Questão 3 - Autocorrelação'!R16) -> 5.5872487 | E5: =LN('Questão 3 - Autocorrelação'!S16) -> 9.860961 | F5: {=B5-($I$9+SUMPRODUCT(TRANSPOSE($I$10:$I$11),D5:E5))} -> 1635.5937 | H5: {=MMULT(H1:V3,C2:E16)} -> 15 | I5: 84.891673 | J5: 151.66019 | L5: {=MINVERSE(H5:J7)} -> 1072.109 | M5: -225.24006 | N5: 20.047259 | P5: {=MMULT(H1:V3,B2:B16)} -> 371026 | Q5: 371026 | R5: 371026 | AA5: R-Quadrado | AB5: 0.90954676
A6: 1962 | B6: 20406 | C6: 1 | D6: =LN('Questão 3 - Autocorrelação'!R17) -> 5.5902404 | E6: =LN('Questão 3 - Autocorrelação'!S17) -> 9.8857105 | F6: {=B6-($I$9+SUMPRODUCT(TRANSPOSE($I$10:$I$11),D6:E6))} -> 709.7431 | H6: 84.891673 | I6: 480.47716 | J6: 858.45058 | L6: -225.24006 | M6: 52.065613 | N6: -6.8662453 | P6: 2102723.7 | Q6: 2102723.7 | R6: 2102723.7 | AA6: R-quadrado ajustado | AB6: 0.89447122
A7: 1963 | B7: 20831.6 | C7: 1 | D7: =LN('Questão 3 - Autocorrelação'!R18) -> 5.6167711 | E7: =LN('Questão 3 - Autocorrelação'!S18) -> 9.9428765 | F7: {=B7-($I$9+SUMPRODUCT(TRANSPOSE($I$10:$I$11),D7:E7))} -> -445.80354 | H7: 151.66019 | I7: 858.45058 | J7: 1534.4346 | L7: 20.047259 | M7: -6.8662453 | N7: 1.8605947 | P7: 3768589.4 | Q7: 3768589.4 | R7: 3768589.4 | AA7: Erro padrão | AB7: 1583.2552
A8: 1964 | B8: 24806.3 | C8: 1 | D8: =LN('Questão 3 - Autocorrelação'!R19) -> 5.6454469 | E8: =LN('Questão 3 - Autocorrelação'!S19) -> 10.002274 | F8: {=B8-($I$9+SUMPRODUCT(TRANSPOSE($I$10:$I$11),D8:E8))} -> 1848.7333 | AA8: Observações | AB8: 15
A9: 1965 | B9: 26465.8 | C9: 1 | D9: =LN('Questão 3 - Autocorrelação'!R20) -> 5.7061131 | E9: =LN('Questão 3 - Autocorrelação'!S20) -> 10.062421 | F9: {=B9-($I$9+SUMPRODUCT(TRANSPOSE($I$10:$I$11),D9:E9))} -> 743.47005 | H9: α | I9: {=MMULT(L5:N7,P5:R7)} -> -287429.42 | K9: ln(Y) = α + β1ln(L) + β2ln(K)
A10: 1966 | B10: 27403 | C10: 1 | D10: =LN('Questão 3 - Autocorrelação'!R21) -> 5.7284751 | E10: =LN('Questão 3 - Autocorrelação'!S21) -> 10.124188 | F10: {=B10-($I$9+SUMPRODUCT(TRANSPOSE($I$10:$I$11),D10:E10))} -> 184.21171 | H10: β1 | I10: 33621.085 | K10: A cada aumento de 1 dia em β1(dias trabalhados) aumenta 34.928,44 em Y (produto real) | AA10: ANOVA
A11: 1967 | B11: 28628.7 | C11: 1 | D11: =LN('Questão 3 - Autocorrelação'!R22) -> 5.7160404 | E11: =LN('Questão 3 - Autocorrelação'!S22) -> 10.192932 | F11: {=B11-($I$9+SUMPRODUCT(TRANSPOSE($I$10:$I$11),D11:E11))} -> 999.25077 | H11: β2 | I11: 12055.353 | K11: A cada aumento de 1 unidade em β1(volume de capital) aumenta 11.737,92 em Y (produto real) | AB11: gl | AC11: SQ | AD11: MQ | AE11: F | AF11: F de significação
A12: 1968 | B12: 29904.5 | C12: 1 | D12: =LN('Questão 3 - Autocorrelação'!R23) -> 5.7193277 | E12: =LN('Questão 3 - Autocorrelação'!S23) -> 10.307545 | F12: {=B12-($I$9+SUMPRODUCT(TRANSPOSE($I$10:$I$11),D12:E12))} -> 782.82532 | AA12: Regressão | AB12: 2 | AC12: 3.0247119e+08 | AD12: 1.5123559e+08 | AE12: 60.332615 | AF12: 5.4770259e-07
A13: 1969 | B13: 27508.2 | C13: 1 | D13: =LN('Questão 3 - Autocorrelação'!R24) -> 5.6991049 | E13: =LN('Questão 3 - Autocorrelação'!S24) -> 10.360466 | F13: {=B13-($I$9+SUMPRODUCT(TRANSPOSE($I$10:$I$11),D13:E13))} -> -1571.5446 | H13: n | I13: Ybarra | K13: yTy | L13: βTXTy | AA13: Resíduo | AB13: 12 | AC13: 30080366 | AD13: 2506697.1
A14: 1970 | B14: 29035.5 | C14: 1 | D14: =LN('Questão 3 - Autocorrelação'!R25) -> 5.6886688 | E14: =LN('Questão 3 - Autocorrelação'!S25) -> 10.418539 | F14: {=B14-($I$9+SUMPRODUCT(TRANSPOSE($I$10:$I$11),D14:E14))} -> -393.46553 | H14: =COUNT(B2:B16) -> 15 | I14: =AVERAGE(B2:B16) -> 24735.067 | K14: {=MMULT(TRANSPOSE(A2:A16),A2:A16)} -> 57918655 | L14: {=MMULT(TRANSPOSE(I9:I11),MMULT(H1:V3,A2:A16))} -> 7.2934951e+08 | AA14: Total | AB14: 14 | AC14: 3.3255155e+08
A15: 1971 | B15: 29281.5 | C15: 1 | D15: =LN('Questão 3 - Autocorrelação'!R26) -> 5.7004436 | E15: =LN('Questão 3 - Autocorrelação'!S26) -> 10.457999 | F15: {=B15-($I$9+SUMPRODUCT(TRANSPOSE($I$10:$I$11),D15:E15))} -> -1019.0452
A16: 1972 | B16: 31531.8 | C16: 1 | D16: =LN('Questão 3 - Autocorrelação'!R27) -> 5.6633076 | E16: =LN('Questão 3 - Autocorrelação'!S27) -> 10.640515 | F16: {=B16-($I$9+SUMPRODUCT(TRANSPOSE($I$10:$I$11),D16:E16))} -> 279.50617 | K16: STQ | L16: =K14-H14*I14^2 -> -9.1194342e+09 | N16: TABELA ANOVA | AB16: Coeficientes | AC16: Erro padrão | AD16: Stat t | AE16: valor-P | AF16: 95% inferiores | AG16: 95% superiores | AH16: Inferior 95,0% | AI16: Superior 95,0%
K17: SQReg | L17: =L14-H14*I14^2 -> -8.4480033e+09 | N17: Fonte | O17: GL | P17: SQ | Q17: QM | R17: F(calc) | S17: F(crit) | AA17: Interseção | AB17: -28075.862 | AC17: 9431.9216 | AD17: -2.9766852 | AE17: 0.011556722 | AF17: -48626.253 | AG17: -7525.4698 | AH17: -48626.253 | AI17: -7525.4698
K18: SQRes | L18: =K14-L14 -> -6.7143086e+08 | N18: Regressão | O18: 2 | P18: =L17 -> -8.4480033e+09 | Q18: =P18/O18 -> -4.2240017e+09 | R18: =Q18/Q19 -> 75.492539 | S18: =_xlfn.F.INV(5%,O18,O19) -> 0.051513171 | U18: O modelo é altamente significativo, segundo teste estatístico. | AA18: L | AB18: 147.97785 | AC18: 36.442878 | AD18: 4.0605424 | AE18: 0.001580168 | AF18: 68.57564 | AG18: 227.38006 | AH18: 68.57564 | AI18: 227.38006
K19: Resultado | L19: =L17+L18=L16 -> TRUE | N19: Resíduos | O19: =H14-(O18+1) -> 12 | P19: =L18 -> -6.7143086e+08 | Q19: =P19/O19 -> -55952571 | AA19: K | AB19: 0.40342393 | AC19: 0.073559385 | AD19: 5.4843299 | AE19: 0.00013972792 | AF19: 0.2431518 | AG19: 0.56369607 | AH19: 0.2431518 | AI19: 0.56369607
K20: R² | L20: =L17/L16 -> 0.92637363 | N20: Total | O20: =H14-1 -> 14 | P20: =L16 -> -9.1194342e+09 | Q20: =P20/O20 -> -6.5138816e+08
K21: R² ajustado | L21: =1-(Q19/Q20) -> 0.91410257
A34: Ano | B34: ê(t) | D34: ê(t-1) | E34: û(t)
A35: =A2 -> 1958 | B35: =F2 -> -2853.5787 | G35: 1 | H35: 1 | I35: 1 | J35: 1 | K35: 1 | L35: 1 | M35: 1 | N35: 1 | O35: 1 | P35: 1 | Q35: 1 | R35: 1 | S35: 1 | T35: 1 | AA35: RESUMO DOS RESULTADOS
A36: =A3 -> 1959 | B36: =F3 -> -2012.3195 | C36: 1 | D36: =B35 -> -2853.5787 | E36: =B36-$H$42*D36 -> -1204.5802 | G36: -2853.5787 | H36: -2012.3195 | I36: 1112.423 | J36: 1635.5937 | K36: 709.7431 | L36: -445.80354 | M36: 1848.7333 | N36: 743.47005 | O36: 184.21171 | P36: 999.25077 | Q36: 782.82532 | R36: -1571.5446 | S36: -393.46553 | T36: -1019.0452
A37: =A4 -> 1960 | B37: =F4 -> 1112.423 | C37: 1 | D37: =B36 -> -2012.3195 | E37: =B37-$H$42*D37 -> 1682.0338 | AA37: Estatística de regressão
A38: =A5 -> 1961 | B38: =F5 -> 1635.5937 | C38: 1 | D38: =B37 -> 1112.423 | E38: =B38-$H$42*D38 -> 1320.7092 | G38: {=MMULT(G35:T36,C36:D49)} -> 14 | H38: -279.50617 | J38: {=MINVERSE(G38:H39)} -> 0.071443854 | K38: 7.6549742e-07 | M38: {=MMULT(G35:T36,B36:B49)} -> 2853.5787 | N38: 2853.5787 | AA38: R múltiplo | AB38: 0.37718624
A39: =A6 -> 1962 | B39: =F6 -> 709.7431 | C39: 1 | D39: =B38 -> 1635.5937 | E39: =B39-$H$42*D39 -> 246.76894 | G39: -279.50617 | H39: 26086304 | J39: 7.6549742e-07 | K39: 3.8342495e-08 | M39: 7325486.7 | N39: 7325486.7 | AA39: R-Quadrado | AB39: 0.14226946
A40: =A7 -> 1963 | B40: =F7 -> -445.80354 | C40: 1 | D40: =B39 -> 709.7431 | E40: =B40-$H$42*D40 -> -646.70472 | AA40: R-quadrado ajustado | AB40: 0.065346382
A41: =A8 -> 1964 | B41: =F8 -> 1848.7333 | C41: 1 | D41: =B40 -> -445.80354 | E41: =B41-$H$42*D41 -> 1974.9233 | G41: α | H41: {=MMULT(J38:K39,M38:N39)} -> 209.4783 | J41: rho ^ | K41: {=SUMPRODUCT(B36:B49,D36:D49)/SUMPRODUCT(D36:D49,D36:D49)} -> 0.28081735 | AA41: Erro padrão | AB41: 1131.6192
A42: =A9 -> 1965 | B42: =F9 -> 743.47005 | C42: 1 | D42: =B41 -> 1848.7333 | E42: =B42-$H$42*D42 -> 220.16418 | G42: β1 | H42: 0.28306184 | J42: sigma² ^ | K42: {=SUMPRODUCT(E36:E49,E36:E49)/(H44-1)} -> 1228040.3 | AA42: Observações | AB42: 14
A43: =A10 -> 1966 | B43: =F10 -> 184.21171 | C43: 1 | D43: =B42 -> 743.47005 | E43: =B43-$H$42*D43 -> -26.236293 | J43: S(rho) | K43: {=SQRT(K42/SUMPRODUCT(D36:D49,D36:D49))} -> 0.21697017
A44: =A11 -> 1967 | B44: =F11 -> 999.25077 | C44: 1 | D44: =B43 -> 184.21171 | E44: =B44-$H$42*D44 -> 947.10746 | G44: n | H44: =COUNT(B36:B49) -> 14 | J44: t(calc) | K44: =K41/K43 -> 1.2942671 | M44: Não rejeita H0, pois o valor absoluto de t(calc) é menor do que o valor de t(crit). | AA44: ANOVA
A45: =A12 -> 1968 | B45: =F12 -> 782.82532 | C45: 1 | D45: =B44 -> 999.25077 | E45: =B45-$H$42*D45 -> 499.97556 | J45: t(crit) | K45: =TINV(5%,H44-1) -> 2.1603687 | AB45: gl | AC45: SQ | AD45: MQ | AE45: F | AF45: F de significação
A46: =A13 -> 1969 | B46: =F13 -> -1571.5446 | C46: 1 | D46: =B45 -> 782.82532 | E46: =B46-$H$42*D46 -> -1793.1326 | AA46: Regressão | AB46: 1 | AC46: 2761243.7 | AD46: 2761243.7 | AE46: 2.156275 | AF46: 0.16770806
A47: =A14 -> 1970 | B47: =F14 -> -393.46553 | C47: 1 | D47: =B46 -> -1571.5446 | E47: =B47-$H$42*D47 -> 51.378793 | AA47: Resíduo | AB47: 13 | AC47: 16647305 | AD47: 1280561.9
A48: =A15 -> 1971 | B48: =F15 -> -1019.0452 | C48: 1 | D48: =B47 -> -393.46553 | E48: =B48-$H$42*D48 -> -907.67016 | AA48: Total | AB48: 14 | AC48: 19408548
A49: =A16 -> 1972 | B49: =F16 -> 279.50617 | C49: 1 | D49: =B48 -> -1019.0452 | E49: =B49-$H$42*D49 -> 567.95899
AB50: Coeficientes | AC50: Erro padrão | AD50: Stat t | AE50: valor-P | AF50: 95% inferiores | AG50: 95% superiores | AH50: Inferior 95,0% | AI50: Superior 95,0%
AA51: Interseção | AB51: 0 | AC51: #N/A | AD51: #N/A | AE51: #N/A | AF51: #N/A | AG51: #N/A | AH51: #N/A | AI51: #N/A
AA52: Variável X 1 | AB52: 0.30304376 | AC52: 0.20637319 | AD52: 1.468426 | AE52: 0.16576597 | AF52: -0.1427984 | AG52: 0.74888592 | AH52: -0.1427984 | AI52: 0.74888592
...

Sheet Questão 4 - Variáveis Binárias
B2: Insira seu nome e RA abaixo | D2: Escola Superior de Administração, Marketing e Comunicação (ESAMC) 10175/A - Econometria - 1º Sem. de 2021 - Prof. Pier Francesco De Maria | P2: Você recebeu os dados abaixo, referentes ao salário de 15 professores (Y, em R$ mil por ano), anos de docência após concluir o doutorado (X) e universidade em que trabalha (D). Cuidado: você também sabe os nomes deles(as). Faça o que é pedido, na ordem.
B4: 101190648 | P4: USE APENAS O MÉTODO DIRETO! Cuidado, porém, para não esquecer de interpretar tudo (ANOVA, testes-T, coeficientes, R²...) nos itens (1) a (4)!
D5: Prova 2 / Parte 4 (Variáveis Binárias) | P5: 1) (1.50 pontos) Estime um modelo de regressão no qual você use as variáveis Y, X e D, sendo que D será "é ou não da Universidade A".
B6: Este exercício vale 17,5% (dezessete porcento e cinco décimos) da nota da P2. A nota desta prova será ponderada junto às demais notas da Prova 2, compondo a nota da P2. Faça o que é pedido, sempre utilizando (a não ser que seja solicitado o contrário) álgebra matricial. Deixe todas as fórmulas indicadas, sob pena de perder nota! Você recebeu essa prova em 01/06. Faça a QUESTÃO 4 e devolva-a até 11/06, antes do horário da aula (19h30). Ao terminar a sua prova, SALVE O ARQUIVO E ENVIE PARA O E-MAIL pier.francesco@esamc.br! | P6: 2) (2.00 pontos) Estime outro modelo de regressão, no qual você consiga observar o impacto de cada uma das universidades.
P7: 3) (2.00 pontos) Refaça o modelo do item (2), adicionando a variável sexo. O que aconteceu? Explique com suas palavras.
P8: 4) (1.50 pontos) Faça um modelo de regressão no qual haja uma quebra estrutural após os 20 anos de docência (X > 20).
P9: 5) (1.50 pontos) Existe quebra estrutural entre a universidade B e as demais? Teste isso e avalie os resultados.
P10: 6) (1.50 pontos) O que você consegue concluir, diante das evidências encontradas?
P12: Prof. | Q12: Y | R12: X | S12: D | T12: Z
P13: André | Q13: 105 | R13: 16 | S13: A | T13: Homem
P14: Paula | Q14: 98 | R14: 31 | S14: B | T14: Mulher
P15: Beto | Q15: 114 | R15: 15 | S15: A | T15: Homem
P16: Karol | Q16: 99 | R16: 21 | S16: C | T16: Mulher
P17: Caio | Q17: 93 | R17: 7 | S17: B | T17: Homem
P18: Julia | Q18: 46 | R18: 25 | S18: A | T18: Mulher
P19: Dênis | Q19: 73 | R19: 33 | S19: C | T19: Homem
P20: Pietra | Q20: 52 | R20: 10 | S20: B | T20: Mulher
P21: Rafael | Q21: 108 | R21: 16 | S21: A | T21: Homem
P22: Ticiana | Q22: 75 | R22: 40 | S22: C | T22: Mulher
P23: Flávio | Q23: 68 | R23: 18 | S23: C | T23: Homem
P24: Elisa | Q24: 121 | R24: 5 | S24: C | T24: Mulher
... P27: Bárbara | Q27: 72 | R27: 28 | S27: B | T27: Mulher

Sheet RESOLUÇÃO QUESTÃO 4
A1: Prof. | B1: Y | C1: X | D1: D(A=1) | E1: D(B=1) | F1: D(C=1) | H1: RESUMO DOS RESULTADOS | J1: Item 1
A2: André | B2: 105 | C2: 16 | D2: =IF('Questão 4 - Variáveis Binárias'!S13="A",1,0) -> 1 | E2: =IF('Questão 4 - Variáveis Binárias'!S13="B",1,0) -> 0 | F2: =IF('Questão 4 - Variáveis Binárias'!S13="C",1,0) -> 0
A3: Paula | B3: 98 | C3: 31 | D3: =IF('Questão 4 - Variáveis Binárias'!S14="A",1,0) -> 0 | E3: =IF('Questão 4 - Variáveis Binárias'!S14="B",1,0) -> 1 | F3: =IF('Questão 4 - Variáveis Binárias'!S14="C",1,0) -> 0 | H3: Estatística de regressão | M3: α | N3: β1 | O3: β2
A4: Beto | B4: 114 | C4: 15 | D4: =IF('Questão 4 - Variáveis Binárias'!S15="A",1,0) -> 1 | E4: =IF('Questão 4 - Variáveis Binárias'!S15="B",1,0) -> 0 | F4: =IF('Questão 4 - Variáveis Binárias'!S15="C",1,0) -> 0 | H4: R múltiplo | I4: 0.48614423 | L4: t(calc) | M4: =K17 -> 6.1987375 | N4: =K18 -> -1.5051583 | O4: =K19 -> 0.80804835 | P4: Rejeitamos H0 para todas as variáveis.
A5: Karol | B5: 99 | C5: 21 | D5: =IF('Questão 4 - Variáveis Binárias'!S16="A",1,0) -> 0 | E5: =IF('Questão 4 - Variáveis Binárias'!S16="B",1,0) -> 0 | F5: =IF('Questão 4 - Variáveis Binárias'!S16="C",1,0) -> 1 | H5: R-Quadrado | I5: 0.23633622 | L5: t(crit) | M5: =_xlfn.T.INV(5%,I13) -> -1.7822876
A6: Caio | B6: 93 | C6: 7 | D6: =IF('Questão 4 - Variáveis Binárias'!S17="A",1,0) -> 0 | E6: =IF('Questão 4 - Variáveis Binárias'!S17="B",1,0) -> 1 | F6: =IF('Questão 4 - Variáveis Binárias'!S17="C",1,0) -> 0 | H6: R-quadrado ajustado | I6: 0.10905892
A7: Julia | B7: 46 | C7: 25 | D7: =IF('Questão 4 - Variáveis Binárias'!S18="A",1,0) -> 1 | E7: =IF('Questão 4 - Variáveis Binárias'!S18="B",1,0) -> 0 | F7: =IF('Questão 4 - Variáveis Binárias'!S18="C",1,0) -> 0 | H7: Erro padrão | I7: 27.308298
A8: Dênis | B8: 73 | C8: 33 | D8: =IF('Questão 4 - Variáveis Binárias'!S19="A",1,0) -> 0 | E8: =IF('Questão 4 - Variáveis Binárias'!S19="B",1,0) -> 0 | F8: =IF('Questão 4 - Variáveis Binárias'!S19="C",1,0) -> 1 | H8: Observações | I8: 15
A9: Pietra | B9: 52 | C9: 10 | D9: =IF('Questão 4 - Variáveis Binárias'!S20="A",1,0) -> 0 | E9: =IF('Questão 4 - Variáveis Binárias'!S20="B",1,0) -> 1 | F9: =IF('Questão 4 - Variáveis Binárias'!S20="C",1,0) -> 0
A10: Rafael | B10: 108 | C10: 16 | D10: =IF('Questão 4 - Variáveis Binárias'!S21="A",1,0) -> 1 | E10: =IF('Questão 4 - Variáveis Binárias'!S21="B",1,0) -> 0 | F10: =IF('Questão 4 - Variáveis Binárias'!S21="C",1,0) -> 0 | H10: ANOVA
A11: Ticiana | B11: 75 | C11: 40 | D11: =IF('Questão 4 - Variáveis Binárias'!S22="A",1,0) -> 0 | E11: =IF('Questão 4 - Variáveis Binárias'!S22="B",1,0) -> 0 | F11: =IF('Questão 4 - Variáveis Binárias'!S22="C",1,0) -> 1 | I11: gl | J11: SQ | K11: MQ | L11: F | M11: F de significação
A12: Flávio | B12: 68 | C12: 18 | D12: =IF('Questão 4 - Variáveis Binárias'!S23="A",1,0) -> 0 | E12: =IF('Questão 4 - Variáveis Binárias'!S23="B",1,0) -> 0 | F12: =IF('Questão 4 - Variáveis Binárias'!S23="C",1,0) -> 1 | H12: Regressão | I12: 2 | J12: 2769.4823 | K12: 1384.7412 | L12: 1.8568607 | M12: 0.19834131 | N12: Rejeitamos H0. O modelo é significativo.
A13: Elisa | B13: 121 | C13: 5 | D13: =IF('Questão 4 - Variáveis Binárias'!S24="A",1,0) -> 0 | E13: =IF('Questão 4 - Variáveis Binárias'!S24="B",1,0) -> 0 | F13: =IF('Questão 4 - Variáveis Binárias'!S24="C",1,0) -> 1 | H13: Resíduo | I13: 12 | J13: 8948.9177 | K13: 745.74314
A14: Marco | B14: 153 | C14: 9 | D14: =IF('Questão 4 - Variáveis Binárias'!S25="A",1,0) -> 1 | E14: =IF('Questão 4 - Variáveis Binárias'!S25="B",1,0) -> 0 | F14: =IF('Questão 4 - Variáveis Binárias'!S25="C",1,0) -> 0 | H14: Total | I14: 14 | J14: 11718.4
A15: Sara | B15: 121 | C15: 19 | D15: =IF('Questão 4 - Variáveis Binárias'!S26="A",1,0) -> 0 | E15: =IF('Questão 4 - Variáveis Binárias'!S26="B",1,0) -> 1 | F15: =IF('Questão 4 - Variáveis Binárias'!S26="C",1,0) -> 0
A16: Bárbara | B16: 72 | C16: 28 | D16: =IF('Questão 4 - Variáveis Binárias'!S27="A",1,0) -> 0 | E16: =IF('Questão 4 - Variáveis Binárias'!S27="B",1,0) -> 1 | F16: =IF('Questão 4 - Variáveis Binárias'!S27="C",1,0) -> 0 | I16: Coeficientes | J16: Erro padrão | K16: Stat t | L16: valor-P | M16: 95% inferiores | N16: 95% superiores | O16: Inferior 95,0% | P16: Superior 95,0%
H17: Interseção | I17: 110.73905 | J17: 17.864775 | K17: 6.1987375 | L17: 4.5952752e-05 | M17: 71.815052 | N17: 149.66306 | O17: 71.815052 | P17: 149.66306
H18: X | I18: -1.1103327 | J18: 0.73768501 | K18: -1.5051583 | L18: 0.158143 | M18: -2.7176103 | N18: 0.49694482 | O18: -2.7176103 | P18: 0.49694482
H19: D(A=1) | I19: 12.448336 | J19: 15.405435 | K19: 0.80804835 | L19: 0.43478935 | M19: -21.117223 | N19: 46.013895 | O19: -21.117223 | P19: 46.013895
H21: RESUMO DOS RESULTADOS | J21: Item 2
H23: Estatística de regressão | M23: α | N23: β1 | O23: β2 | P23: β3 | Q23: β4
H24: R múltiplo | I24: 0.49154306 | L24: t(calc) | M24: =K36 -> 6.9020054 | N24: =K37 -> -1.4723192 | O24: =K38 -> 65535 | P24: =K39 -> -0.81599016 | Q24: =K40 -> -0.5156194 | R24: Rejeitamos H0 para todas as variáveis.
H25: R-Quadrado | I25: 0.24161458 | L25: t(crit) | M25: =_xlfn.T.INV(5%,I32) -> -1.7958848
H26: R-quadrado ajustado | I26: -0.0561269
H27: Erro padrão | I27: 28.423844
H28: Observações | I28: 15
H29: ANOVA
I30: gl | J30: SQ | K30: MQ | L30: F | M30: F de significação
H31: Regressão | I31: 4 | J31: 2831.3363 | K31: 707.83407 | L31: 1.1681661 | M31: 0.38118938 | N31: Rejeitamos H0. O modelo é significativo.
H32: Resíduo | I32: 11 | J32: 8887.0637 | K32: 807.91488
H33: Total | I33: 15 | J33: 11718.4
I35: Coeficientes | J35: Erro padrão | K35: Stat t | L35: valor-P | M35: 95% inferiores | N35: 95% superiores | O35: Inferior 95,0% | P35: Superior 95,0%
H36: Interseção | I36: 123.84593 | J36: 17.943471 | K36: 6.9020054 | L36: 2.5807382e-05 | M36: 84.352618 | N36: 163.33924 | O36: 84.352618 | P36: 163.33924
H37: X | I37: -1.1509834 | J37: 0.78174854 | K37: -1.4723192 | L37: 0.16896047 | M37: -2.8716003 | N37: 0.56963357 | O37: -2.8716003 | P37: 0.56963357
H38: D(A=1) | I38: 0 | J38: 0 | K38: 65535 | L38: #NUM! | M38: 0 | N38: 0 | O38: 0 | P38: 0
H39: D(B=1) | I39: -14.777247 | J39: 18.109589 | K39: -0.81599016 | L39: #NUM! | M39: -54.636184 | N39: 25.08169 | O39: -54.636184 | P39: 25.08169
H40: D(C=1) | I40: -9.7129198 | J40: 18.837382 | K40: -0.5156194 | L40: 0.61632482 | M40: -51.173719 | N40: 31.747879 | O40: -51.173719 | P40: 31.747879
A43: Prof. | B43: Y | C43: X | D43: D(A=1) | E43: D(B=1) | F43: D(C=1) | G43: Z(Mulher = 1) | I43: RESUMO DOS RESULTADOS | K43: Item 3
A44: André | B44: 105 | C44: 16 | D44: 1 | E44: 0 | F44: 0 | G44: =IF('Questão 4 - Variáveis Binárias'!T13="Mulher",1,0) -> 0
A45: Paula | B45: 98 | C45: 31 | D45: 0 | E45: 1 | F45: 0 | G45: =IF('Questão 4 - Variáveis Binárias'!T14="Mulher",1,0) -> 1 | I45: Estatística de regressão | N45: α | O45: β1 | P45: β2 | Q45: β3 | R45: β4 | S45: β5
...
